Workbook

Sheet Info_studio
A1: MATERIALE INFORMATIVO SULLO STUDIO
A3: Scheda informativa dello studio:
A4: "Usare le Forma Mentis Networks per mappare le attitudini nei confronti delle discipline STEM"
A6: Gentile partecipante,
A7: La invitiamo a partecipare al nostro studio che mira ad esplorare l’esperienza da Lei vissuta in quanto
A8: studente o studentessa di discipline STEM.
A10: Scopo dello studio: Lo scopo di questo studio è quello di comprendere le sue esperienze e i suoi processi
A11: cognitivi come studenti e studentesse di discipline STEM.
A13: Sponsorizzazione: Questo studio non è sponsorizzato da enti esterni.
A15: Durata e frequenza: La sua partecipazione comporterà la compilazione di alcuni questionari e l’esecuzione
A16: di tre task. Il tutto non durerà più di 60 minuti.
A18: Descrizione del processo e del compito: Le verrà chiesto di effettuare alcuni compiti, tra cui la
... A44: Assegnista di ricerca dell'Università di Trento

Sheet Consenso_Informato
B1: CONSENSO INFORMATO alla RICERCA
B3: Progetto: “Usare le Forma Mentis Networks per mappare le attitudini nei confronti delle discipline STEM”
A5: Con la presente dichiaro
A6: • di aver letto il foglio informativo sullo studio dal titolo: "Usare le Forma Mentis Networks per mappare le attitudini nei confronti delle discipline STEM";
A7: • che gli obiettivi, i metodi e i rischi dello studio mi sono stati spiegati chiaramente e dettagliatamente dalla dr. Ciringione
A8: • di aver avuto l'opportunità di esprimere le mie considerazioni e chiedere ulteriori chiarimenti, e che ho avuto il tempo di prendere una decisione ponderata e non richiesta;
A9: • di aver compreso che i dati raccolti qui non hanno alcuna rilevanza clinica, ma saranno raccolti ed analizzati puramente a scopo di ricerca;
A10: • di sapere che posso ritirarmi dallo studio in qualsiasi momento senza dover fornire alcuna spiegazione;
A11: • che il mio consenso a partecipare allo studio sopra menzionato è una decisione libera che non è influenzata da promesse di vantaggi finanziari o di altro tipo o da eventuali obblighi verso il ricercatore responsabile dello studio.
A12: Pertanto, sono informato/a sulle attività pianificate e so come posso partecipare allo studio.
A14: Poiché questo è il caso:
A15: X | B15: DO IL MIO CONSENSO A PARTECIPARE ALLO STUDIO
A16: FALSE | B16: RIFIUTO DI DARE IL MIO CONSENSO A PARTECIPARE ALLO STUDIO
C18: DATA | D18: ______
C19: FIRMA | D19: x | E19: X

Sheet Dati_Demografici
A2: Risponda per cortesia alle seguenti domande. In caso di cella di risposta di colore grigio, la selezioni e poi scelga la risposta per lei adatta dal menù a discesa.
A5: Dati demografici
A7: Età | B7: 19 | C7: Inserire un numero intero (es. 24)
A9: In quale genere si identifica? | B9: Donna
A11: Sesso Biologico | B11: Femminile
A13: Anno di enrollment/inizio studi universitari | B13: 2024 | C13: Inserire solo l'anno (es. 2021)
A15: Ha già conseguito una laurea? | B15: No
A17: Livello di istruzione più alto di almeno uno dei suoi due genitori | B17: Laurea Magistrale o vecchio ordinamento completa

Sheet Questionari
A4: Come quantificherebbe il suo livello accademico in:
A5: Selezioni la risposta dalla freccetta accanto ciascuna cella di risposta grigia
A7: Materie scientifiche, come chimica, biologia e scienze della vita | B7: 3 - Abilità e competenze moderate
A9: Scienze umanistiche e sociali | B9: 3 - Abilità e competenze moderate
A11: Matematica e fisica | B11: 3 - Abilità e competenze moderate
A13: Coding, programmazione e simulazioni al computer | B13: 2 - Abilità e competenze limitate
A18: Descriva in che misura ciascuna di queste affermazioni la descrive
A19: Selezioni la risposta dalla freccetta accanto ciascuna cella di risposta grigia
A20: Self-regulated learning
A22: 1. Preferisco problemi complessi a problemi semplici | B22: 5 - Mi descrive molto bene
A24: 2. Preferisco essere responsabile della gestione di situazioni che richiedono sforzo di pensiero | B24: 5 - Mi descrive molto bene
A26: 3. "Pensare" non è la mia idea di divertimento | B26: 2
A28: 4. Preferirei fare qualcosa che richiede scarsa attività cognitiva piuttosto che qualcosa che sfida la mia capacità di pensiero | B28: 1 - Non mi descrive per nulla
A30: 5. Io cerco di anticipare o evitare situazioni in cui probabilmente dovrò pensare a fondo riguardo a qualcosa | B30: 1 - Non mi descrive per nulla
A32: 6. Provo soddisfazione nel riflettere molto e a lungo | B32: 5 - Mi descrive molto bene
A34: 7. Io penso solo se sono costretto a farlo | B34: 1 - Non mi descrive per nulla
A36: 8. Preferisco pensare a piccoli progetti quotidiani, piuttosto che a progetti a lungo termine | B36: 2
A38: 9. Preferisco compiti che richiedono piccoli sforzi cognitivi dopo essere stati appresi | B38: 1 - Non mi descrive per nulla
A40: 10. L'idea di contare sul pensiero per trovare la mia strada mi intriga | B40: 5 - Mi descrive molto bene
A42: 11. Mi piace un compito che prevede l'arrivo a nuove soluzioni per risolvere problemi | B42: 4
A44: 12. Imparare nuovi modi di pensare non mi eccita molto | B44: 1 - Non mi descrive per nulla
A46: 13. Preferisco riempire la mia vita con puzzles da risolvere | B46: 5 - Mi descrive molto bene
A48: 14. La nozione di pensiero astrattamente mi affascina | B48: 5 - Mi descrive molto bene
A50: 15. Preferirei un compito intellettuale, difficile e importante rispetto ad uno piuttosto importante ma che non richiede pensiero | B50: 4
A52: 16. Provo sollievo piuttosto che soddisfazione dopo aver completato un compito che ha richiesto una gran quantità di sforzo mentale | B52: 1 - Non mi descrive per nulla
A54: 17. E' sufficiente per me ottenere un risultato dal lavoro fatto; non mi curo del come o perchè esso funziona | B54: 1 - Non mi descrive per nulla
A56: 18. Io normalmente finisco per riflettere riguardo a un tema anche se esso non mi riguarda personalmente | B56: 5 - Mi descrive molto bene
A62: Mi vedo come una persona che ...
A63: Motivational Learning | E63: questo corso... cioè??
A64: Selezioni la risposta dalla freccetta accanto ciascuna cella di risposta grigia
A66: 1) ...è riservata | B66: 1 - Per niente d'accordo
A68: 2) ...generalmente si fida | B68: 1 - Per niente d'accordo
A70: 3) ...tende a essere pigra | B70: 1 - Per niente d'accordo
A72: 4) ...è rilassata, sopporta bene lo stress | B72: 1 - Per niente d'accordo
A74: 5) ...ha pochi interessi artistici | B74: 1 - Per niente d'accordo
A76: 6) ...è spigliata, socievole | B76: 5 - Completamente d'accordo
A78: 7) ...tende a trovare i difetti negli altri | B78: 5 - Completamente d'accordo
A80: 8) ...è coscienziosa nel lavoro | B80: 5 - Completamente d'accordo
A82: 9) ...si agita facilmente | B82: 5 - Completamente d'accordo
A84: 10) ...ha una fervida immaginazione | B84: 4
...

Sheet Task_1parte_Associazioni
A1: cue word | C1: association_1 | E1: association_2 | G1: association_3
A2: Consideriamo ora questo gioco di associazione:
J3: ESEMPIO DI COMPILAZIONE - ASSOCIAZIONI
A4: Legga la parola in grassetto e scriva negli spazi grigi le prime 3 parole che le vengono in mente dopo averla letta
A5: Per favore, provi a utilizzare una sola parola come associazione
A6: Non ci sono risposte giuste o sbagliate, cerchi solo di farlo il più velocemente possibile.
A7: Se non ha associazioni, lasci gli spazi vuoti.
A8: Pronto/a?
A10: Quali parole le vengono in mente quando legge:
A11: parola_cue | C11: associazione_1 | E11: associazione_2 | G11: associazione_3
A13: noia | C13: indecisione | E13: vita pratica | G13: lavoro
A15: laurea | C15: soddisfazione | E15: master | G15: felicità
A17: biologia | C17: anatomia | E17: animali | G17: psicobiologia
A19: ansia | C19: futuro | E19: lavoro | G19: figli
A21: fisica | C21: filosofia | E21: nostalgia | G21: entp
A23: relazione | C23: amore | E23: variabili | G23: correlazione
A25: esame | C25: orale | E25: primo | G25: maturità
A27: statistica | C27: novità | E27: curiosità | G27: logica
A29: scienza | C29: neuroscienza | E29: conoscenza | G29: mondo
A31: tecnologia | C31: incapacità | E31: progresso | G31: tecnica
A33: conoscenza | C33: amore | E33: desiderio | G33: vuoto
... A75: personalità | C75: tenacia | E75: mbti | G75: forte
A77: creatività
A79: matematica
A81: mente
A83: lavoro
A85: insegnante
A87: futuro
A89: terapia
A91: professore

Sheet Task_2parte_Valenza
A2: Consideriamo ora la valenza emotiva ispirata dai concetti. | J2: ESEMPIO DI COMPILAZIONE - VALENZA
A3: Esprima quanto positivamente o negativamente percepisce ogni concetto, isolatamente, in una scala da 1 a 5
A4: dove 1 sta per "Molto negativo", 3 sta per "Neutrale" e 5 sta per "Molto Positivo".
A5: Scriva il numero negli spazi bianchi successivi alla parola/associazione.
A6: Ricordi di valutare i concetti in base alla sua personale percezione.
A7: ATTENZIONE! NON MODIFICHI LE PAROLE "ASSOCIAZIONE" IN QUESTO FOGLIO!
A9: parola_cue | B9: valenza_cue | C9: associazione_1 | D9: valenza_1 | E9: associazione_2 | F9: valenza_2 | G9: associazione_3 | H9: valenza_3
A11: =Task_1parte_Associazioni!A13 -> noia | B11: 1 | C11: =Task_1parte_Associazioni!C13 -> indecisione | D11: 1 | E11: =Task_1parte_Associazioni!E13 -> vita pratica | F11: 3 | G11: =Task_1parte_Associazioni!G13 -> lavoro | H11: 3
A13: =Task_1parte_Associazioni!A15 -> laurea | B13: 5 | C13: =Task_1parte_Associazioni!C15 -> soddisfazione | D13: 5 | E13: =Task_1parte_Associazioni!E15 -> master | F13: 5 | G13: =Task_1parte_Associazioni!G15 -> felicità | H13: 5
A15: =Task_1parte_Associazioni!A17 -> biologia | B15: 3 | C15: =Task_1parte_Associazioni!C17 -> anatomia | D15: 3 | E15: =Task_1parte_Associazioni!E17 -> animali | F15: 1 | G15: =Task_1parte_Associazioni!G17 -> psicobiologia | H15: 5
A17: =Task_1parte_Associazioni!A19 -> ansia | B17: 1 | C17: =Task_1parte_Associazioni!C19 -> futuro | D17: 1 | E17: =Task_1parte_Associazioni!E19 -> lavoro | F17: 3 | G17: =Task_1parte_Associazioni!G19 -> figli | H17: 2
A19: =Task_1parte_Associazioni!A21 -> fisica | B19: 5 | C19: =Task_1parte_Associazioni!C21 -> filosofia | D19: 5 | E19: =Task_1parte_Associazioni!E21 -> nostalgia | F19: 1 | G19: =Task_1parte_Associazioni!G21 -> entp | H19: 5
A21: =Task_1parte_Associazioni!A23 -> relazione | B21: 5 | C21: =Task_1parte_Associazioni!C23 -> amore | D21: 5 | E21: =Task_1parte_Associazioni!E23 -> variabili | F21: 4 | G21: =Task_1parte_Associazioni!G23 -> correlazione | H21: 3
A23: =Task_1parte_Associazioni!A25 -> esame | B23: 3 | C23: =Task_1parte_Associazioni!C25 -> orale | D23: 3 | E23: =Task_1parte_Associazioni!E25 -> primo | F23: 3 | G23: =Task_1parte_Associazioni!G25 -> maturità | H23: 3
A25: =Task_1parte_Associazioni!A27 -> statistica | B25: 4 | C25: =Task_1parte_Associazioni!C27 -> novità | D25: 5 | E25: =Task_1parte_Associazioni!E27 -> curiosità | F25: 5 | G25: =Task_1parte_Associazioni!G27 -> logica | H25: 5
A27: =Task_1parte_Associazioni!A29 -> scienza | B27: 5 | C27: =Task_1parte_Associazioni!C29 -> neuroscienza | D27: 5 | E27: =Task_1parte_Associazioni!E29 -> conoscenza | F27: 5 | G27: =Task_1parte_Associazioni!G29 -> mondo | H27: 5
A29: =Task_1parte_Associazioni!A31 -> tecnologia | B29: 3 | C29: =Task_1parte_Associazioni!C31 -> incapacità | D29: 1 | E29: =Task_1parte_Associazioni!E31 -> progresso | F29: 5 | G29: =Task_1parte_Associazioni!G31 -> tecnica | H29: 5
A31: =Task_1parte_Associazioni!A33 -> conoscenza | B31: 5 | C31: =Task_1parte_Associazioni!C33 -> amore | D31: 5 | E31: =Task_1parte_Associazioni!E33 -> desiderio | F31: 5 | G31: =Task_1parte_Associazioni!G33 -> vuoto | H31: 1
A33: =Task_1parte_Associazioni!A35 -> scuola | B33: 4 | C33: =Task_1parte_Associazioni!C35 -> interesse | D33: 5 | E33: =Task_1parte_Associazioni!E35 -> persone | F33: 5 | G33: =Task_1parte_Associazioni!G35 -> domande | H33: 5
... A61: =Task_1parte_Associazioni!A63 -> neuroscienze | B61: 4 | C61: =Task_1parte_Associazioni!C63 -> interesse | D61: 4 | E61: =Task_1parte_Associazioni!E63 -> professoressa | F61: 5 | G61: =Task_1parte_Associazioni!G63 -> biologia | H61: 3
A63: =Task_1parte_Associazioni!A65 -> grafico | B63: =Task_1parte_Associazioni!B65 | C63: =Task_1parte_Associazioni!C65 -> torta | D63: =Task_1parte_Associazioni!D65 | E63: =Task_1parte_Associazioni!E65 -> diagramma | F63: =Task_1parte_Associazioni!F65 | G63: =Task_1parte_Associazioni!G65 -> dati | H63: 3
A65: =Task_1parte_Associazioni!A67 -> voto | B65: 4 | C65: =Task_1parte_Associazioni!C67 -> massimo | D65: 5 | E65: =Task_1parte_Associazioni!E67 -> aspettativa | F65: 5 | G65: =Task_1parte_Associazioni!G67 -> sfida | H65: 5
A67: =Task_1parte_Associazioni!A69 -> cognizione | B67: 1 | C67: =Task_1parte_Associazioni!C69 -> causa | D67: 2 | E67: =Task_1parte_Associazioni!E69 -> incapacità | F67: 1 | G67: =Task_1parte_Associazioni!G69 -> senno di poi | H67: 1
A69: =Task_1parte_Associazioni!A71 -> compito | B69: 3 | C69: =Task_1parte_Associazioni!C71 -> matematica | D69: 3 | E69: =Task_1parte_Associazioni!E71 -> presentazione | F69: 4 | G69: =Task_1parte_Associazioni!G71 -> gruppo | H69: 4
A71: =Task_1parte_Associazioni!A73 -> scoperta | B71: 5 | C71: =Task_1parte_Associazioni!C73 -> ricerca | D71: 5 | E71: =Task_1parte_Associazioni!E73 -> neuriscienxe | F71: 5 | G71: =Task_1parte_Associazioni!G73 -> invenzione | H71: 5
A73: =Task_1parte_Associazioni!A75 -> personalità | B73: 5 | C73: =Task_1parte_Associazioni!C75 -> tenacia | D73: 5 | E73: =Task_1parte_Associazioni!E75 -> mbti | F73: 5 | G73: =Task_1parte_Associazioni!G75 -> forte | H73: 5
A75: =Task_1parte_Associazioni!A77 -> creatività | B75: 5 | C75: =Task_1parte_Associazioni!C77 | D75: =Task_1parte_Associazioni!D77 | E75: =Task_1parte_Associazioni!E77 | F75: =Task_1parte_Associazioni!F77 | G75: =Task_1parte_Associazioni!G77 | H75: =Task_1parte_Associazioni!H77
A77: =Task_1parte_Associazioni!A79 -> matematica | B77: =Task_1parte_Associazioni!B79 | C77: =Task_1parte_Associazioni!C79 | D77: =Task_1parte_Associazioni!D79 | E77: =Task_1parte_Associazioni!E79 | F77: =Task_1parte_Associazioni!F79 | G77: =Task_1parte_Associazioni!G79 | H77: =Task_1parte_Associazioni!H79
A79: =Task_1parte_Associazioni!A81 -> mente | B79: =Task_1parte_Associazioni!B81 | C79: =Task_1parte_Associazioni!C81 | D79: =Task_1parte_Associazioni!D81 | E79: =Task_1parte_Associazioni!E81 | F79: =Task_1parte_Associazioni!F81 | G79: =Task_1parte_Associazioni!G81 | H79: =Task_1parte_Associazioni!H81
A81: =Task_1parte_Associazioni!A83 -> lavoro | B81: =Task_1parte_Associazioni!B83 | C81: =Task_1parte_Associazioni!C83 | D81: =Task_1parte_Associazioni!D83 | E81: =Task_1parte_Associazioni!E83 | F81: =Task_1parte_Associazioni!F83 | G81: =Task_1parte_Associazioni!G83 | H81: =Task_1parte_Associazioni!H83
A83: =Task_1parte_Associazioni!A85 -> insegnante | B83: =Task_1parte_Associazioni!B85 | C83: =Task_1parte_Associazioni!C85 | D83: =Task_1parte_Associazioni!D85 | E83: =Task_1parte_Associazioni!E85 | F83: =Task_1parte_Associazioni!F85 | G83: =Task_1parte_Associazioni!G85 | H83: =Task_1parte_Associazioni!H85
A85: =Task_1parte_Associazioni!A87 -> futuro | B85: =Task_1parte_Associazioni!B87 | C85: =Task_1parte_Associazioni!C87 | D85: =Task_1parte_Associazioni!D87 | E85: =Task_1parte_Associazioni!E87 | F85: =Task_1parte_Associazioni!F87 | G85: =Task_1parte_Associazioni!G87 | H85: =Task_1parte_Associazioni!H87
A87: =Task_1parte_Associazioni!A89 -> terapia | B87: =Task_1parte_Associazioni!B89 | C87: =Task_1parte_Associazioni!C89 | D87: =Task_1parte_Associazioni!D89 | E87: =Task_1parte_Associazioni!E89 | F87: =Task_1parte_Associazioni!F89 | G87: =Task_1parte_Associazioni!G89 | H87: =Task_1parte_Associazioni!H89
A89: =Task_1parte_Associazioni!A91 -> professore | B89: =Task_1parte_Associazioni!B91 | C89: =Task_1parte_Associazioni!C91 | D89: =Task_1parte_Associazioni!D91 | E89: =Task_1parte_Associazioni!E91 | F89: =Task_1parte_Associazioni!F91 | G89: =Task_1parte_Associazioni!G91 | H89: =Task_1parte_Associazioni!H91

Sheet breve_testo
A1: Scriva adesso un breve testo di circa 250 parole relativamente a come si sente quando si trova ad affrontare le discipline STEM.
A2: "Quando affronto le discipline STEM…"
A3: …
