Workbook

Sheet Info_studio
A1: MATERIALE INFORMATIVO SULLO STUDIO
A3: Scheda informativa dello studio:
A4: "Usare le Forma Mentis Networks per mappare le attitudini nei confronti delle discipline STEM"
A6: Gentile partecipante,
A7: La invitiamo a partecipare al nostro studio che mira ad esplorare l’esperienza da Lei vissuta in quanto
A8: studente o studentessa di discipline STEM.
A10: Scopo dello studio: Lo scopo di questo studio è quello di comprendere le sue esperienze e i suoi processi
A11: cognitivi come studenti e studentesse di discipline STEM.
A13: Sponsorizzazione: Questo studio non è sponsorizzato da enti esterni.
A15: Durata e frequenza: La sua partecipazione comporterà la compilazione di alcuni questionari e l’esecuzione
A16: di tre task. Il tutto non durerà più di 60 minuti.
A18: Descrizione del processo e del compito: Le verrà chiesto di effettuare alcuni compiti, tra cui la
... A44: Assegnista di ricerca dell'Università di Trento

Sheet Consenso_Informato
B1: CONSENSO INFORMATO alla RICERCA
B3: Progetto: “Usare le Forma Mentis Networks per mappare le attitudini nei confronti delle discipline STEM”
A5: Con la presente dichiaro
A6: • di aver letto il foglio informativo sullo studio dal titolo: "Usare le Forma Mentis Networks per mappare le attitudini nei confronti delle discipline STEM";
A7: • che gli obiettivi, i metodi e i rischi dello studio mi sono stati spiegati chiaramente e dettagliatamente dalla dr. Ciringione
A8: • di aver avuto l'opportunità di esprimere le mie considerazioni e chiedere ulteriori chiarimenti, e che ho avuto il tempo di prendere una decisione ponderata e non richiesta;
A9: • di aver compreso che i dati raccolti qui non hanno alcuna rilevanza clinica, ma saranno raccolti ed analizzati puramente a scopo di ricerca;
A10: • di sapere che posso ritirarmi dallo studio in qualsiasi momento senza dover fornire alcuna spiegazione;
A11: • che il mio consenso a partecipare allo studio sopra menzionato è una decisione libera che non è influenzata da promesse di vantaggi finanziari o di altro tipo o da eventuali obblighi verso il ricercatore responsabile dello studio.
A12: Pertanto, sono informato/a sulle attività pianificate e so come posso partecipare allo studio.
A14: Poiché questo è il caso:
A15: X | B15: DO IL MIO CONSENSO A PARTECIPARE ALLO STUDIO
A16: FALSE | B16: RIFIUTO DI DARE IL MIO CONSENSO A PARTECIPARE ALLO STUDIO
C18: DATA | D18: 45554
C19: FIRMA | D19: X | E19: (INSERIRE UNA X)

Sheet Dati_Demografici
A2: Risponda per cortesia alle seguenti domande. In caso di cella di risposta di colore grigio, la selezioni e poi scelga la risposta per lei adatta dal menù a discesa.
A5: Dati demografici
A7: Età | B7: 18 | C7: Inserire un numero intero (es. 24)
A9: In quale genere si identifica? | B9: Uomo
A11: Sesso Biologico | B11: Maschile
A13: Anno di enrollment/inizio studi universitari | B13: 2024 | C13: Inserire solo l'anno (es. 2021)
A15: Ha già conseguito una laurea? | B15: No
A17: Livello di istruzione più alto di almeno uno dei suoi due genitori | B17: Laurea non completata

Sheet Questionari
A4: Come quantificherebbe il suo livello accademico in:
A5: Selezioni la risposta dalla freccetta accanto ciascuna cella di risposta grigia
A7: Materie scientifiche, come chimica, biologia e scienze della vita | B7: 3 - Abilità e competenze moderate
A9: Scienze umanistiche e sociali | B9: 1 - Abilità scarse o inesistenti
A11: Matematica e fisica | B11: 4 - Abilità e competenze superiori alla media
A13: Coding, programmazione e simulazioni al computer | B13: 2 - Abilità e competenze limitate
A18: Descriva in che misura ciascuna di queste affermazioni la descrive
A19: Selezioni la risposta dalla freccetta accanto ciascuna cella di risposta grigia
A20: Self-regulated learning
A22: 1. Preferisco problemi complessi a problemi semplici | B22: 3
A24: 2. Preferisco essere responsabile della gestione di situazioni che richiedono sforzo di pensiero | B24: 4
A26: 3. "Pensare" non è la mia idea di divertimento | B26: 1 - Non mi descrive per nulla
A28: 4. Preferirei fare qualcosa che richiede scarsa attività cognitiva piuttosto che qualcosa che sfida la mia capacità di pensiero | B28: 2
A30: 5. Io cerco di anticipare o evitare situazioni in cui probabilmente dovrò pensare a fondo riguardo a qualcosa | B30: 2
A32: 6. Provo soddisfazione nel riflettere molto e a lungo | B32: 3
A34: 7. Io penso solo se sono costretto a farlo | B34: 2
A36: 8. Preferisco pensare a piccoli progetti quotidiani, piuttosto che a progetti a lungo termine | B36: 4
A38: 9. Preferisco compiti che richiedono piccoli sforzi cognitivi dopo essere stati appresi | B38: 3
A40: 10. L'idea di contare sul pensiero per trovare la mia strada mi intriga | B40: 4
A42: 11. Mi piace un compito che prevede l'arrivo a nuove soluzioni per risolvere problemi | B42: 3
A44: 12. Imparare nuovi modi di pensare non mi eccita molto | B44: 1 - Non mi descrive per nulla
A46: 13. Preferisco riempire la mia vita con puzzles da risolvere | B46: 2
A48: 14. La nozione di pensiero astrattamente mi affascina | B48: 5 - Mi descrive molto bene
A50: 15. Preferirei un compito intellettuale, difficile e importante rispetto ad uno piuttosto importante ma che non richiede pensiero | B50: 3
A52: 16. Provo sollievo piuttosto che soddisfazione dopo aver completato un compito che ha richiesto una gran quantità di sforzo mentale | B52: 2
A54: 17. E' sufficiente per me ottenere un risultato dal lavoro fatto; non mi curo del come o perchè esso funziona | B54: 1 - Non mi descrive per nulla
A56: 18. Io normalmente finisco per riflettere riguardo a un tema anche se esso non mi riguarda personalmente | B56: 2
A62: Mi vedo come una persona che ...
A63: Motivational Learning | E63: questo corso... cioè??
A64: Selezioni la risposta dalla freccetta accanto ciascuna cella di risposta grigia
A66: 1) ...è riservata | B66: 3
A68: 2) ...generalmente si fida | B68: 2
A70: 3) ...tende a essere pigra | B70: 3
A72: 4) ...è rilassata, sopporta bene lo stress | B72: 3
A74: 5) ...ha pochi interessi artistici | B74: 2
A76: 6) ...è spigliata, socievole | B76: 3
A78: 7) ...tende a trovare i difetti negli altri | B78: 3
A80: 8) ...è coscienziosa nel lavoro | B80: 4
A82: 9) ...si agita facilmente | B82: 3
A84: 10) ...ha una fervida immaginazione | B84: 3
...

Sheet Task_1parte_Associazioni
A1: cue word | C1: association_1 | E1: association_2 | G1: association_3
A2: Consideriamo ora questo gioco di associazione:
J3: ESEMPIO DI COMPILAZIONE - ASSOCIAZIONI
A4: Legga la parola in grassetto e scriva negli spazi grigi le prime 3 parole che le vengono in mente dopo averla letta
A5: Per favore, provi a utilizzare una sola parola come associazione
A6: Non ci sono risposte giuste o sbagliate, cerchi solo di farlo il più velocemente possibile.
A7: Se non ha associazioni, lasci gli spazi vuoti.
A8: Pronto/a?
A10: Quali parole le vengono in mente quando legge:
A11: parola_cue | C11: associazione_1 | E11: associazione_2 | G11: associazione_3
A13: noia | C13: chimica
A15: laurea | C15: lavoro | E15: conoscenza
A17: biologia | C17: lontana | E17: spenta
A19: ansia
A21: fisica | C21: noiosa | E21: scientifica
A23: relazione | C23: persone | E23: mente
A25: esame | C25: prova
A27: statistica | C27: difficile | E27: interessante
A29: scienza | C29: certa | E29: studio
A31: tecnologia | C31: utile
A33: conoscenza | C33: affascinante | E33: ricerca
A35: scuola | C35: percorso | E35: formazione | G35: contesto
A37: sfida | C37: difficile | E37: pensiero
A39: psicologia | C39: affascinante | E39: filosofia | G39: sottovalutata
A41: equazione | C41: matematica | E41: risoluzione
A43: frustrazione | C43: impossibilità
A45: esercitazione | C45: difficoltà | E45: pensiero
A47: modello | C47: società | E47: irrealtà
A49: benessere | C49: fitness | E49: mentale
A51: stress | C51: soffocante | E51: aberrante
A53: emozione | C53: felicità | E53: istantanea
A55: curiosità | C55: studio | E55: università
A57: università | C57: studio | E57: affascinante
A59: numeri | C59: affascinati | E59: matematica | G59: filosofia
A61: comportamento | C61: psicologia | E61: infanzia | G61: società
A63: neuroscienze | C63: curiosità | E63: certa
A65: grafico | C65: matematica | E65: rappresentazione | G65: funzione
A67: voto | C67: conclusione | E67: positivo
A69: cognizione
A71: compito | C71: svolgere | E71: scuola
...

Sheet Task_2parte_Valenza
A2: Consideriamo ora la valenza emotiva ispirata dai concetti. | J2: ESEMPIO DI COMPILAZIONE - VALENZA
A3: Esprima quanto positivamente o negativamente percepisce ogni concetto, isolatamente, in una scala da 1 a 5
A4: dove 1 sta per "Molto negativo", 3 sta per "Neutrale" e 5 sta per "Molto Positivo".
A5: Scriva il numero negli spazi bianchi successivi alla parola/associazione.
A6: Ricordi di valutare i concetti in base alla sua personale percezione.
A7: ATTENZIONE! NON MODIFICHI LE PAROLE "ASSOCIAZIONE" IN QUESTO FOGLIO!
A9: parola_cue | B9: valenza_cue | C9: associazione_1 | D9: valenza_1 | E9: associazione_2 | F9: valenza_2 | G9: associazione_3 | H9: valenza_3
A11: =Task_1parte_Associazioni!A13 -> noia | B11: 3 | C11: =Task_1parte_Associazioni!C13 -> chimica | D11: 1 | E11: =Task_1parte_Associazioni!E13 | F11: =Task_1parte_Associazioni!F13 | G11: =Task_1parte_Associazioni!G13 | H11: =Task_1parte_Associazioni!H13
A13: =Task_1parte_Associazioni!A15 -> laurea | B13: 5 | C13: =Task_1parte_Associazioni!C15 -> lavoro | D13: 5 | E13: =Task_1parte_Associazioni!E15 -> conoscenza | F13: 5 | G13: =Task_1parte_Associazioni!G15 | H13: =Task_1parte_Associazioni!H15
A15: =Task_1parte_Associazioni!A17 -> biologia | B15: 2 | C15: =Task_1parte_Associazioni!C17 -> lontana | D15: 2 | E15: =Task_1parte_Associazioni!E17 -> spenta | F15: 1 | G15: =Task_1parte_Associazioni!G17 | H15: =Task_1parte_Associazioni!H17
A17: =Task_1parte_Associazioni!A19 -> ansia | B17: 3 | C17: =Task_1parte_Associazioni!C19 | D17: =Task_1parte_Associazioni!D19 | E17: =Task_1parte_Associazioni!E19 | F17: =Task_1parte_Associazioni!F19 | G17: =Task_1parte_Associazioni!G19 | H17: =Task_1parte_Associazioni!H19
A19: =Task_1parte_Associazioni!A21 -> fisica | B19: 1 | C19: =Task_1parte_Associazioni!C21 -> noiosa | D19: 3 | E19: =Task_1parte_Associazioni!E21 -> scientifica | F19: 5 | G19: =Task_1parte_Associazioni!G21 | H19: =Task_1parte_Associazioni!H21
A21: =Task_1parte_Associazioni!A23 -> relazione | B21: 5 | C21: =Task_1parte_Associazioni!C23 -> persone | D21: 3 | E21: =Task_1parte_Associazioni!E23 -> mente | F21: 5 | G21: =Task_1parte_Associazioni!G23 | H21: =Task_1parte_Associazioni!H23
A23: =Task_1parte_Associazioni!A25 -> esame | B23: 3 | C23: =Task_1parte_Associazioni!C25 -> prova | D23: 3 | E23: =Task_1parte_Associazioni!E25 | F23: =Task_1parte_Associazioni!F25 | G23: =Task_1parte_Associazioni!G25 | H23: =Task_1parte_Associazioni!H25
A25: =Task_1parte_Associazioni!A27 -> statistica | B25: 3 | C25: =Task_1parte_Associazioni!C27 -> difficile | D25: 3 | E25: =Task_1parte_Associazioni!E27 -> interessante | F25: 5 | G25: =Task_1parte_Associazioni!G27 | H25: =Task_1parte_Associazioni!H27
A27: =Task_1parte_Associazioni!A29 -> scienza | B27: 5 | C27: =Task_1parte_Associazioni!C29 -> certa | D27: 4 | E27: =Task_1parte_Associazioni!E29 -> studio | F27: 4 | G27: =Task_1parte_Associazioni!G29 | H27: =Task_1parte_Associazioni!H29
A29: =Task_1parte_Associazioni!A31 -> tecnologia | B29: 4 | C29: =Task_1parte_Associazioni!C31 -> utile | D29: 5 | E29: =Task_1parte_Associazioni!E31 | F29: =Task_1parte_Associazioni!F31 | G29: =Task_1parte_Associazioni!G31 | H29: =Task_1parte_Associazioni!H31
A31: =Task_1parte_Associazioni!A33 -> conoscenza | B31: 5 | C31: =Task_1parte_Associazioni!C33 -> affascinante | D31: 5 | E31: =Task_1parte_Associazioni!E33 -> ricerca | F31: 5 | G31: =Task_1parte_Associazioni!G33 | H31: =Task_1parte_Associazioni!H33
A33: =Task_1parte_Associazioni!A35 -> scuola | B33: 4 | C33: =Task_1parte_Associazioni!C35 -> percorso | D33: 4 | E33: =Task_1parte_Associazioni!E35 -> formazione | F33: 5 | G33: =Task_1parte_Associazioni!G35 -> contesto | H33: 3
A35: =Task_1parte_Associazioni!A37 -> sfida | B35: 4 | C35: =Task_1parte_Associazioni!C37 -> difficile | D35: 3 | E35: =Task_1parte_Associazioni!E37 -> pensiero | F35: 5 | G35: =Task_1parte_Associazioni!G37 | H35: =Task_1parte_Associazioni!H37
A37: =Task_1parte_Associazioni!A39 -> psicologia | B37: 5 | C37: =Task_1parte_Associazioni!C39 -> affascinante | D37: 5 | E37: =Task_1parte_Associazioni!E39 -> filosofia | F37: 5 | G37: =Task_1parte_Associazioni!G39 -> sottovalutata | H37: 3
A39: =Task_1parte_Associazioni!A41 -> equazione | B39: 3 | C39: =Task_1parte_Associazioni!C41 -> matematica | D39: 5 | E39: =Task_1parte_Associazioni!E41 -> risoluzione | F39: 5 | G39: =Task_1parte_Associazioni!G41 | H39: =Task_1parte_Associazioni!H41
A41: =Task_1parte_Associazioni!A43 -> frustrazione | B41: 1 | C41: =Task_1parte_Associazioni!C43 -> impossibilità | D41: 1 | E41: =Task_1parte_Associazioni!E43 | F41: =Task_1parte_Associazioni!F43 | G41: =Task_1parte_Associazioni!G43 | H41: =Task_1parte_Associazioni!H43
A43: =Task_1parte_Associazioni!A45 -> esercitazione | B43: 3 | C43: =Task_1parte_Associazioni!C45 -> difficoltà | D43: 3 | E43: =Task_1parte_Associazioni!E45 -> pensiero | F43: 5 | G43: =Task_1parte_Associazioni!G45 | H43: =Task_1parte_Associazioni!H45
A45: =Task_1parte_Associazioni!A47 -> modello | B45: 3 | C45: =Task_1parte_Associazioni!C47 -> società | D45: 3 | E45: =Task_1parte_Associazioni!E47 -> irrealtà | F45: 2 | G45: =Task_1parte_Associazioni!G47 | H45: =Task_1parte_Associazioni!H47
A47: =Task_1parte_Associazioni!A49 -> benessere | B47: 5 | C47: =Task_1parte_Associazioni!C49 -> fitness | D47: 5 | E47: =Task_1parte_Associazioni!E49 -> mentale | F47: 5 | G47: =Task_1parte_Associazioni!G49 | H47: =Task_1parte_Associazioni!H49
A49: =Task_1parte_Associazioni!A51 -> stress | B49: 2 | C49: =Task_1parte_Associazioni!C51 -> soffocante | D49: 1 | E49: =Task_1parte_Associazioni!E51 -> aberrante | F49: 1 | G49: =Task_1parte_Associazioni!G51 | H49: =Task_1parte_Associazioni!H51
A51: =Task_1parte_Associazioni!A53 -> emozione | B51: 5 | C51: =Task_1parte_Associazioni!C53 -> felicità | D51: 5 | E51: =Task_1parte_Associazioni!E53 -> istantanea | F51: 3 | G51: =Task_1parte_Associazioni!G53 | H51: =Task_1parte_Associazioni!H53
A53: =Task_1parte_Associazioni!A55 -> curiosità | B53: 5 | C53: =Task_1parte_Associazioni!C55 -> studio | D53: 5 | E53: =Task_1parte_Associazioni!E55 -> università | F53: 5 | G53: =Task_1parte_Associazioni!G55 | H53: =Task_1parte_Associazioni!H55
A55: =Task_1parte_Associazioni!A57 -> università | B55: 5 | C55: =Task_1parte_Associazioni!C57 -> studio | D55: 5 | E55: =Task_1parte_Associazioni!E57 -> affascinante | F55: 5 | G55: =Task_1parte_Associazioni!G57 | H55: =Task_1parte_Associazioni!H57
A57: =Task_1parte_Associazioni!A59 -> numeri | B57: 3 | C57: =Task_1parte_Associazioni!C59 -> affascinati | D57: 4 | E57: =Task_1parte_Associazioni!E59 -> matematica | F57: 5 | G57: =Task_1parte_Associazioni!G59 -> filosofia | H57: 5
A59: =Task_1parte_Associazioni!A61 -> comportamento | B59: 3 | C59: =Task_1parte_Associazioni!C61 -> psicologia | D59: 5 | E59: =Task_1parte_Associazioni!E61 -> infanzia | F59: 4 | G59: =Task_1parte_Associazioni!G61 -> società | H59: 3
A61: =Task_1parte_Associazioni!A63 -> neuroscienze | B61: 4 | C61: =Task_1parte_Associazioni!C63 -> curiosità | D61: 5 | E61: =Task_1parte_Associazioni!E63 -> certa | F61: 4 | G61: =Task_1parte_Associazioni!G63 | H61: =Task_1parte_Associazioni!H63
A63: =Task_1parte_Associazioni!A65 -> grafico | B63: 5 | C63: =Task_1parte_Associazioni!C65 -> matematica | D63: 5 | E63: =Task_1parte_Associazioni!E65 -> rappresentazione | F63: 4 | G63: =Task_1parte_Associazioni!G65 -> funzione | H63: 4
A65: =Task_1parte_Associazioni!A67 -> voto | B65: 3 | C65: =Task_1parte_Associazioni!C67 -> conclusione | D65: 3 | E65: =Task_1parte_Associazioni!E67 -> positivo | F65: 5 | G65: =Task_1parte_Associazioni!G67 | H65: =Task_1parte_Associazioni!H67
A67: =Task_1parte_Associazioni!A69 -> cognizione | B67: 3 | C67: =Task_1parte_Associazioni!C69 | D67: =Task_1parte_Associazioni!D69 | E67: =Task_1parte_Associazioni!E69 | F67: =Task_1parte_Associazioni!F69 | G67: =Task_1parte_Associazioni!G69 | H67: =Task_1parte_Associazioni!H69
A69: =Task_1parte_Associazioni!A71 -> compito | B69: 3 | C69: =Task_1parte_Associazioni!C71 -> svolgere | D69: 3 | E69: =Task_1parte_Associazioni!E71 -> scuola | F69: 4 | G69: =Task_1parte_Associazioni!G71 | H69: =Task_1parte_Associazioni!H71
A71: =Task_1parte_Associazioni!A73 -> scoperta | B71: 5 | C71: =Task_1parte_Associazioni!C73 -> curiosità | D71: 5 | E71: =Task_1parte_Associazioni!E73 -> spazio | F71: 5 | G71: =Task_1parte_Associazioni!G73 -> oceano | H71: 1
A73: =Task_1parte_Associazioni!A75 -> personalità | B73: 3 | C73: =Task_1parte_Associazioni!C75 -> influenza | D73: 2 | E73: =Task_1parte_Associazioni!E75 -> genetica | F73: 4 | G73: =Task_1parte_Associazioni!G75 -> complicata | H73: 3
A75: =Task_1parte_Associazioni!A77 -> creatività | B75: 5 | C75: =Task_1parte_Associazioni!C77 -> lavoro | D75: 3 | E75: =Task_1parte_Associazioni!E77 -> compiti | F75: 3 | G75: =Task_1parte_Associazioni!G77 | H75: =Task_1parte_Associazioni!H77
...

Sheet breve_testo
A1: Scriva adesso un breve testo di circa 250 parole relativamente a come si sente quando si trova ad affrontare le discipline STEM.
A2: "Quando affronto le discipline STEM…"
A3: …
