Workbook

Sheet Consenso_Informato
A1: CONSENSO INFORMATO alla RICERCA
A3: Progetto: “Using Forma Mentis Networks to Map Students’ Attitudes Toward Data Science”
A5: Nel partecipare alla ricerca, riconosco, comprendo e accetto i seguenti punti:
A7: 1. La ricerca del progetto include la raccolta di dati cognitivi che sono: (i) associazioni libere tra le parole e (ii) punteggi di valenza, entrambi raccolti in modo anonimo;
A8: 2. Partecipo come volontaria/o nella raccolta dei dati, con la possibilità di interrompere l'attività in qualsiasi momento senza penalizzazioni. Comprendo che posso chiedere informazioni e ulteriori spiegazioni in qualsiasi momento durante l'esperimento.
A9: 3. I dati saranno raccolti in forma aggregata, in modo completamente anonimo e utilizzati per scopi di ricerca.
A10: 4. La ricerca viene condotta in conformità con le Indicazioni Etiche e l’approvazione del Comitato Etico dell'Università di Melbourne
B12: DATA | C12: 0.62875
B13: FIRMA | C13: X | D13: (INSERIRE UNA X)

Sheet Dati_Demografici
A2: Risponda per cortesia alle seguenti domande. In caso di cella di risposta di colore grigio, la selezioni e poi scelga la risposta per lei adatta dal menù a discesa.
A5: Dati demografici
A7: Età | B7: 23 | C7: Inserire un numero intero (es. 24)
A9: In quale genere si identifica? | B9: Donna
A11: Sesso Biologico | B11: Femminile
A13: Anno di enrollment/inizio studi universitari | B13: 2021 | C13: Inserire solo l'anno (es. 2021)
A15: Ha già conseguito una laurea? | B15: No
A17: Livello di istruzione più alto di almeno uno dei suoi due genitori | B17: Laurea Magistrale o vecchio ordinamento completa

Sheet Questionari
A4: Come quantificherebbe il suo livello accademico in:
A5: Selezioni la risposta dalla freccetta accanto ciascuna cella di risposta grigia
A7: Materie scientifiche, come chimica, biologia e scienze della vita | B7: 3 - Abilità e competenze moderate
A9: Scienze umanistiche e sociali | B9: 4 - Abilità e competenze superiori alla media
A11: Matematica e fisica | B11: 2 - Abilità e competenze limitate
A13: Coding, programmazione e simulazioni al computer | B13: 3 - Abilità e competenze moderate
A18: In questa parte, vedrà una serie di domande rispetto alla sua esperienza con materie STEM (Scienza, Tecnologia, Ingegneria e Matematica).
A19: Selezioni la risposta dalla freccetta accanto ciascuna cella di risposta grigia
A20: Self-regulated learning
A22: Mi assicuro che nessuno mi disturbi quando studio. | B22: 7 - Sempre
A24: Cerco di studiare in un posto tranquillo. | B24: 7 - Sempre
A26: Penso ai tipi di domande che potrebbero esserci in un test/esame. | B26: 7 - Sempre
A28: Chiedo al/alla mio/a insegnante di materie STEM gli argomenti che saranno nei prossimi esami. | B28: 5 - Spesso
A30: Mi affido ai miei appunti di classe per studiare. | B30: 7 - Sempre
A32: Studio molto anche quando ci sono cose più divertenti da fare a casa. | B32: 4 - Qualche volta
A34: Mi interrogo per vedere quanto sto imparando durante lo studio. | B34: 6 - Molto spesso
A36: Faccio un programma per aiutarmi a organizzare il mio tempo di studio. | B36: 6 - Molto spesso
A38: Uso raccoglitori o cartelle per organizzare i miei materiali di studio della scienza. | B38: 5 - Spesso
A40: Tendo a smarrire gli appunti delle lezioni di scienze. | B40: 2 - Quasi mai
A42: Evito di andare a sessioni extra di aiuto nella classe STEM. | B42: 4 - Qualche volta
A44: Aspetto fino all'ultimo minuto per studiare per i test di scienze. | B44: 3 - Raramente
... A76: Finisco tutto il mio studio prima di giocare ai videogiochi o uscire con i miei amici. | B76: 4 - Qualche volta
A81: Consideri adesso i tuoi corsi STEM... quanto questi elementi riflettono il suo comportamento?
A82: Motivational Learning | E82: questo corso... cioè??
A83: Nb. per "corso", si intende l'intero corso di laurea a cui si è iscritti
A85: Rispetto agli altri studenti del corso, di solito mi aspetto di fare bene. | B85: 6 - Mi riconosco molto
A87: Sono certo di poter comprendere le idee insegnate in questo corso. | B87: 6 - Mi riconosco molto
A89: Mi aspetto di fare molto bene in questo corso. | B89: 7 - Mi riconosco completamente
A91: Rispetto ad altri in questo corso, penso di essere un/a bravo/a studente/essa. | B91: 6 - Mi riconosco molto
A93: Sono sicuro/a di poter svolgere un ottimo lavoro sui problemi e sui compiti assegnati per questo corso. | B93: 6 - Mi riconosco molto
A95: Penso che riceverò un buon voto in questo corso. | B95: 6 - Mi riconosco molto
A97: Le mie capacità di studio sono eccellenti rispetto ad altre in questo corso. | B97: 6 - Mi riconosco molto
A99: Rispetto ad altri/e studenti/esse di questo corso, penso di sapere molto sull'argomento. | B99: 5 - Mi riconosco in parte
A101: So che sarò in grado di apprendere il materiale per questo corso. | B101: 7 - Mi riconosco completamente
A103: Preferisco il lavoro di un corso impegnativo per imparare cose nuove. | B103: 4 - Neutrale
A105: È importante per me imparare ciò che viene insegnato in questo corso. | B105: 7 - Mi riconosco completamente
A107: Mi piace quello che sto imparando in questo corso. | B107: 6 - Mi riconosco molto
... A119: Comprendere l'argomento è importante per me. | B119: 7 - Mi riconosco completamente
A124: Consideriamo ora la seguente serie di situazioni. Quanto si sentirebbe ansiosa/o in questi scenari?
A125: Math anxiety UK
...

Sheet Task_1parte_Associazioni
A1: cue word | C1: association_1 | E1: association_2 | G1: association_3
A2: Consideriamo ora questo gioco di associazione:
J3: ESEMPIO DI COMPILAZIONE - ASSOCIAZIONI
A4: Legga la parola in grassetto e scriva negli spazi grigi le prime 3 parole che le vengono in mente dopo averla letta
A5: Per favore, provi a utilizzare una sola parola come associazione
A6: Non ci sono risposte giuste o sbagliate, cerchi solo di farlo il più velocemente possibile.
A7: Se non ha associazioni, lasci gli spazi vuoti.
A8: Pronto/a?
A10: Quali parole le vengono in mente quando legge:
A11: parola_cue | C11: associazione_1 | E11: associazione_2 | G11: associazione_3
A13: neuroscienze | C13: scienze cognitive | E13: Neuroni | G13: ricerca
A15: cognizione | C15: sociale | E15: cervello | G15: mente
A17: scienziato | C17: esperimento | E17: ricerca | G17: laboratorio
A19: università | C19: studio | E19: laurea | G19: lezione
A21: divertimento | C21: amici | E21: viaggiare | G21: hobby
A23: informatica | C23: programmazione | E23: computer | G23: linguaggio
A25: ansia | C25: matematica | E25: aspettative | G25: esame
A27: attaccamento | C27: materno | E27: città | G27: casa
A29: statistica | C29: ansia | E29: probabilità | G29: variabili
A31: benessere | C31: felicità | E31: fisico | G31: mentale
A33: creatività | C33: design | E33: arte | G33: scrittura
... A91: sfida | C91: sport | E91: partita | G91: competizione

Sheet Task_2parte_Valenza
A2: Consideriamo ora la valenza emotiva ispirata dai concetti. | J2: ESEMPIO DI COMPILAZIONE - VALENZA
A3: Esprima quanto positivamente o negativamente percepisce ogni concetto, isolatamente, in una scala da 1 a 5
A4: dove 1 sta per "Molto negativo", 3 sta per "Neutrale" e 5 sta per "Molto Positivo".
A5: Scriva il numero negli spazi bianchi successivi alla parola/associazione.
A6: Ricordi di valutare i concetti in base alla sua personale percezione.
A7: ATTENZIONE! NON MODIFICHI LE PAROLE "ASSOCIAZIONE" IN QUESTO FOGLIO!
A9: parola_cue | B9: valenza_cue | C9: associazione_1 | D9: valenza_1 | E9: associazione_2 | F9: valenza_2 | G9: associazione_3 | H9: valenza_3
A11: =Task_1parte_Associazioni!A13 -> neuroscienze | B11: 4 | C11: =Task_1parte_Associazioni!C13 -> scienze cognitive | D11: 4 | E11: =Task_1parte_Associazioni!E13 -> Neuroni | F11: 3 | G11: =Task_1parte_Associazioni!G13 -> ricerca | H11: 4
A13: =Task_1parte_Associazioni!A15 -> cognizione | B13: 5 | C13: =Task_1parte_Associazioni!C15 -> sociale | D13: 4 | E13: =Task_1parte_Associazioni!E15 -> cervello | F13: 4 | G13: =Task_1parte_Associazioni!G15 -> mente | H13: 4
A15: =Task_1parte_Associazioni!A17 -> scienziato | B15: 3 | C15: =Task_1parte_Associazioni!C17 -> esperimento | D15: 4 | E15: =Task_1parte_Associazioni!E17 -> ricerca | F15: 4 | G15: =Task_1parte_Associazioni!G17 -> laboratorio | H15: 4
A17: =Task_1parte_Associazioni!A19 -> università | B17: 5 | C17: =Task_1parte_Associazioni!C19 -> studio | D17: 4 | E17: =Task_1parte_Associazioni!E19 -> laurea | F17: 5 | G17: =Task_1parte_Associazioni!G19 -> lezione | H17: 4
A19: =Task_1parte_Associazioni!A21 -> divertimento | B19: 5 | C19: =Task_1parte_Associazioni!C21 -> amici | D19: 5 | E19: =Task_1parte_Associazioni!E21 -> viaggiare | F19: 5 | G19: =Task_1parte_Associazioni!G21 -> hobby | H19: 5
A21: =Task_1parte_Associazioni!A23 -> informatica | B21: 2 | C21: =Task_1parte_Associazioni!C23 -> programmazione | D21: 2 | E21: =Task_1parte_Associazioni!E23 -> computer | F21: 4 | G21: =Task_1parte_Associazioni!G23 -> linguaggio | H21: 2
A23: =Task_1parte_Associazioni!A25 -> ansia | B23: 4 | C23: =Task_1parte_Associazioni!C25 -> matematica | D23: 2 | E23: =Task_1parte_Associazioni!E25 -> aspettative | F23: 4 | G23: =Task_1parte_Associazioni!G25 -> esame | H23: 4
A25: =Task_1parte_Associazioni!A27 -> attaccamento | B25: 2 | C25: =Task_1parte_Associazioni!C27 -> materno | D25: 3 | E25: =Task_1parte_Associazioni!E27 -> città | F25: 4 | G25: =Task_1parte_Associazioni!G27 -> casa | H25: 4
A27: =Task_1parte_Associazioni!A29 -> statistica | B27: 2 | C27: =Task_1parte_Associazioni!C29 -> ansia | D27: 2 | E27: =Task_1parte_Associazioni!E29 -> probabilità | F27: 3 | G27: =Task_1parte_Associazioni!G29 -> variabili | H27: 3
A29: =Task_1parte_Associazioni!A31 -> benessere | B29: 5 | C29: =Task_1parte_Associazioni!C31 -> felicità | D29: 5 | E29: =Task_1parte_Associazioni!E31 -> fisico | F29: 5 | G29: =Task_1parte_Associazioni!G31 -> mentale | H29: 5
A31: =Task_1parte_Associazioni!A33 -> creatività | B31: 5 | C31: =Task_1parte_Associazioni!C33 -> design | D31: 5 | E31: =Task_1parte_Associazioni!E33 -> arte | F31: 3 | G31: =Task_1parte_Associazioni!G33 -> scrittura | H31: 4
A33: =Task_1parte_Associazioni!A35 -> prova | B33: 3 | C33: =Task_1parte_Associazioni!C35 -> esame | D33: 4 | E33: =Task_1parte_Associazioni!E35 -> scritta | F33: 3 | G33: =Task_1parte_Associazioni!G35 -> orale | H33: 3
... A89: =Task_1parte_Associazioni!A91 -> sfida | B89: 2 | C89: =Task_1parte_Associazioni!C91 -> sport | D89: 4 | E89: =Task_1parte_Associazioni!E91 -> partita | F89: 4 | G89: =Task_1parte_Associazioni!G91 -> competizione | H89: 3
