Workbook

Sheet Consenso_Informato
A1: CONSENSO INFORMATO alla RICERCA
A3: Progetto: “Using Forma Mentis Networks to Map Students’ Attitudes Toward Data Science”
A5: Nel partecipare alla ricerca, riconosco, comprendo e accetto i seguenti punti:
A7: 1. La ricerca del progetto include la raccolta di dati cognitivi che sono: (i) associazioni libere tra le parole e (ii) punteggi di valenza, entrambi raccolti in modo anonimo;
A8: 2. Partecipo come volontaria/o nella raccolta dei dati, con la possibilità di interrompere l'attività in qualsiasi momento senza penalizzazioni. Comprendo che posso chiedere informazioni e ulteriori spiegazioni in qualsiasi momento durante l'esperimento.
A9: 3. I dati saranno raccolti in forma aggregata, in modo completamente anonimo e utilizzati per scopi di ricerca.
A10: 4. La ricerca viene condotta in conformità con le Indicazioni Etiche e l’approvazione del Comitato Etico dell'Università di Melbourne
B12: DATA | C12: 45428
B13: FIRMA | C13: x | D13: (INSERIRE UNA X)

Sheet Dati_Demografici
A2: Risponda per cortesia alle seguenti domande. In caso di cella di risposta di colore grigio, la selezioni e poi scelga la risposta per lei adatta dal menù a discesa.
A5: Dati demografici
A7: Età | B7: 24 | C7: Inserire un numero intero (es. 24)
A9: In quale genere si identifica? | B9: Donna
A11: Sesso Biologico | B11: Femminile
A13: Anno di enrollment/inizio studi universitari | C13: Inserire solo l'anno (es. 2021)
A14: 2023
A15: Ha già conseguito una laurea? | B15: No
A17: Livello di istruzione più alto di almeno uno dei suoi due genitori | B17: Laurea Magistrale o vecchio ordinamento completa

Sheet Questionari
A4: Come quantificherebbe il suo livello accademico in:
A5: Selezioni la risposta dalla freccetta accanto ciascuna cella di risposta grigia
A7: Materie scientifiche, come chimica, biologia e scienze della vita | B7: 2 - Abilità e competenze limitate
A9: Scienze umanistiche e sociali | B9: 4 - Abilità e competenze superiori alla media
A11: Matematica e fisica | B11: 3 - Abilità e competenze moderate
A13: Coding, programmazione e simulazioni al computer | B13: 2 - Abilità e competenze limitate
A18: In questa parte, vedrà una serie di domande rispetto alla sua esperienza con materie STEM (Scienza, Tecnologia, Ingegneria e Matematica).
A19: Selezioni la risposta dalla freccetta accanto ciascuna cella di risposta grigia
A20: Self-regulated learning
A22: Mi assicuro che nessuno mi disturbi quando studio. | B22: 4 - Qualche volta
A24: Cerco di studiare in un posto tranquillo. | B24: 4 - Qualche volta
A26: Penso ai tipi di domande che potrebbero esserci in un test/esame. | B26: 6 - Molto spesso
A28: Chiedo al/alla mio/a insegnante di materie STEM gli argomenti che saranno nei prossimi esami. | B28: 2 - Quasi mai
A30: Mi affido ai miei appunti di classe per studiare. | B30: 4 - Qualche volta
A32: Studio molto anche quando ci sono cose più divertenti da fare a casa. | B32: 6 - Molto spesso
A34: Mi interrogo per vedere quanto sto imparando durante lo studio. | B34: 4 - Qualche volta
A36: Faccio un programma per aiutarmi a organizzare il mio tempo di studio. | B36: 2 - Quasi mai
A38: Uso raccoglitori o cartelle per organizzare i miei materiali di studio della scienza. | B38: 4 - Qualche volta
A40: Tendo a smarrire gli appunti delle lezioni di scienze. | B40: 2 - Quasi mai
A42: Evito di andare a sessioni extra di aiuto nella classe STEM. | B42: 1 - Mai
A44: Aspetto fino all'ultimo minuto per studiare per i test di scienze. | B44: 3 - Raramente
... A76: Finisco tutto il mio studio prima di giocare ai videogiochi o uscire con i miei amici. | B76: 6 - Molto spesso
A81: Consideri adesso i tuoi corsi STEM... quanto questi elementi riflettono il suo comportamento?
A82: Motivational Learning | E82: questo corso... cioè??
A83: Nb. per "corso", si intende l'intero corso di laurea a cui si è iscritti
A85: Rispetto agli altri studenti del corso, di solito mi aspetto di fare bene. | B85: 3 - Mi riconosco poco
A87: Sono certo di poter comprendere le idee insegnate in questo corso. | B87: 4 - Neutrale
A89: Mi aspetto di fare molto bene in questo corso. | B89: 5 - Mi riconosco in parte
A91: Rispetto ad altri in questo corso, penso di essere un/a bravo/a studente/essa. | B91: 5 - Mi riconosco in parte
A93: Sono sicuro/a di poter svolgere un ottimo lavoro sui problemi e sui compiti assegnati per questo corso. | B93: 5 - Mi riconosco in parte
A95: Penso che riceverò un buon voto in questo corso. | B95: 4 - Neutrale
A97: Le mie capacità di studio sono eccellenti rispetto ad altre in questo corso. | B97: 5 - Mi riconosco in parte
A99: Rispetto ad altri/e studenti/esse di questo corso, penso di sapere molto sull'argomento. | B99: 5 - Mi riconosco in parte
A101: So che sarò in grado di apprendere il materiale per questo corso. | B101: 5 - Mi riconosco in parte
A103: Preferisco il lavoro di un corso impegnativo per imparare cose nuove. | B103: 4 - Neutrale
A105: È importante per me imparare ciò che viene insegnato in questo corso. | B105: 7 - Mi riconosco completamente
A107: Mi piace quello che sto imparando in questo corso. | B107: 6 - Mi riconosco molto
... A119: Comprendere l'argomento è importante per me. | B119: 7 - Mi riconosco completamente
A124: Consideriamo ora la seguente serie di situazioni. Quanto si sentirebbe ansiosa/o in questi scenari?
A125: Math anxiety UK
...

Sheet Task_1parte_Associazioni
A1: cue word | C1: association_1 | E1: association_2 | G1: association_3
A2: Consideriamo ora questo gioco di associazione:
J3: ESEMPIO DI COMPILAZIONE - ASSOCIAZIONI
A4: Legga la parola in grassetto e scriva negli spazi grigi le prime 3 parole che le vengono in mente dopo averla letta
A5: Per favore, provi a utilizzare una sola parola come associazione
A6: Non ci sono risposte giuste o sbagliate, cerchi solo di farlo il più velocemente possibile.
A7: Se non ha associazioni, lasci gli spazi vuoti.
A8: Pronto/a?
A10: Quali parole le vengono in mente quando legge:
A11: parola_cue | C11: associazione_1 | E11: associazione_2 | G11: associazione_3
A13: ansia | C13: paura | E13: sudore | G13: stress
A15: valutazione | C15: compito | E15: numero | G15: giudizio
A17: personalità | C17: creativa | E17: tratto | G17: valore
A19: neuroscienze | C19: cervello | E19: difficile | G19: confuso
A21: scienza | C21: biologia | E21: chimica | G21: natura
A23: terapeuta | C23: aiuto | E23: sicurezza | G23: supporto
A25: creatività | C25: spazio | E25: libertà | G25: gioia
A27: media | C27: algebrica | E27: valutazione | G27: soldi
A29: comportamento | C29: contesto | E29: soxiale | G29: amici
A31: sfida | C31: ecfitazione | E31: stress | G31: vittoria
A33: esame | C33: paura | E33: ansia | G33: stress
... A63: curiosità | C63: csrburante | E63: passione | G63: vita
A65: mente | C65: cervello | E65: emozioni
A67: prova | C67: esame | E67: prestazione
A69: test | C69: valutazione | E69: errore | G69: voto
A71: lavoro | C71: fururo | E71: paura | G71: emozione
A73: divertimento | C73: svago | E73: sfogo | G73: spensieratezza
A75: innovazione | C75: tecnologia | E75: scoperta
A77: statistica | C77: affascinante | E77: grafici | G77: numeri
A79: attaccamento | C79: evitante | E79: emotivo | G79: paura
A81: cognizione | C81: animale | E81: cervello | G81: comprensione
A83: equazione | C83: numerica | E83: algebrica | G83: matematica
A85: psicologia | C85: passione | E85: scoperta | G85: conoscenza
A87: informatica | C87: software | E87: programmazione
A89: benessere | C89: mentale | E89: fisico
A91: psicopatologia | C91: disturbo | E91: intervento | G91: studio

Sheet Task_2parte_Valenza
A2: Consideriamo ora la valenza emotiva ispirata dai concetti. | J2: ESEMPIO DI COMPILAZIONE - VALENZA
A3: Esprima quanto positivamente o negativamente percepisce ogni concetto, isolatamente, in una scala da 1 a 5
A4: dove 1 sta per "Molto negativo", 3 sta per "Neutrale" e 5 sta per "Molto Positivo".
A5: Scriva il numero negli spazi bianchi successivi alla parola/associazione.
A6: Ricordi di valutare i concetti in base alla sua personale percezione.
A7: ATTENZIONE! NON MODIFICHI LE PAROLE "ASSOCIAZIONE" IN QUESTO FOGLIO!
A9: parola_cue | B9: valenza_cue | C9: associazione_1 | D9: valenza_1 | E9: associazione_2 | F9: valenza_2 | G9: associazione_3 | H9: valenza_3
A11: =Task_1parte_Associazioni!A13 -> ansia | B11: 2 | C11: =Task_1parte_Associazioni!C13 -> paura | D11: 2 | E11: =Task_1parte_Associazioni!E13 -> sudore | F11: 1 | G11: =Task_1parte_Associazioni!G13 -> stress | H11: 3
A13: =Task_1parte_Associazioni!A15 -> valutazione | B13: 2 | C13: =Task_1parte_Associazioni!C15 -> compito | D13: 3 | E13: =Task_1parte_Associazioni!E15 -> numero | F13: 3 | G13: =Task_1parte_Associazioni!G15 -> giudizio | H13: 1
A15: =Task_1parte_Associazioni!A17 -> personalità | B15: 5 | C15: =Task_1parte_Associazioni!C17 -> creativa | D15: 5 | E15: =Task_1parte_Associazioni!E17 -> tratto | F15: 5 | G15: =Task_1parte_Associazioni!G17 -> valore | H15: 5
A17: =Task_1parte_Associazioni!A19 -> neuroscienze | B17: 3 | C17: =Task_1parte_Associazioni!C19 -> cervello | D17: 5 | E17: =Task_1parte_Associazioni!E19 -> difficile | F17: 3 | G17: =Task_1parte_Associazioni!G19 -> confuso | H17: 1
A19: =Task_1parte_Associazioni!A21 -> scienza | B19: 3 | C19: =Task_1parte_Associazioni!C21 -> biologia | D19: 2 | E19: =Task_1parte_Associazioni!E21 -> chimica | F19: 1 | G19: =Task_1parte_Associazioni!G21 -> natura | H19: 5
A21: =Task_1parte_Associazioni!A23 -> terapeuta | B21: 5 | C21: =Task_1parte_Associazioni!C23 -> aiuto | D21: 5 | E21: =Task_1parte_Associazioni!E23 -> sicurezza | F21: 5 | G21: =Task_1parte_Associazioni!G23 -> supporto | H21: 5
A23: =Task_1parte_Associazioni!A25 -> creatività | B23: 5 | C23: =Task_1parte_Associazioni!C25 -> spazio | D23: 5 | E23: =Task_1parte_Associazioni!E25 -> libertà | F23: 5 | G23: =Task_1parte_Associazioni!G25 -> gioia | H23: 5
A25: =Task_1parte_Associazioni!A27 -> media | B25: 2 | C25: =Task_1parte_Associazioni!C27 -> algebrica | D25: 3 | E25: =Task_1parte_Associazioni!E27 -> valutazione | F25: 2 | G25: =Task_1parte_Associazioni!G27 -> soldi | H25: 3
A27: =Task_1parte_Associazioni!A29 -> comportamento | B27: 3 | C27: =Task_1parte_Associazioni!C29 -> contesto | D27: 3 | E27: =Task_1parte_Associazioni!E29 -> soxiale | F27: 5 | G27: =Task_1parte_Associazioni!G29 -> amici | H27: 5
A29: =Task_1parte_Associazioni!A31 -> sfida | B29: 4 | C29: =Task_1parte_Associazioni!C31 -> ecfitazione | D29: 5 | E29: =Task_1parte_Associazioni!E31 -> stress | F29: 2 | G29: =Task_1parte_Associazioni!G31 -> vittoria | H29: 5
A31: =Task_1parte_Associazioni!A33 -> esame | B31: 3 | C31: =Task_1parte_Associazioni!C33 -> paura | D31: 2 | E31: =Task_1parte_Associazioni!E33 -> ansia | F31: 1 | G31: =Task_1parte_Associazioni!G33 -> stress | H31: 1
A33: =Task_1parte_Associazioni!A35 -> passione | B33: 5 | C33: =Task_1parte_Associazioni!C35 -> cuore | D33: 5 | E33: =Task_1parte_Associazioni!E35 -> pura | F33: 2 | G33: =Task_1parte_Associazioni!G35 -> conoscenza | H33: 5
... A61: =Task_1parte_Associazioni!A63 -> curiosità | B61: 5 | C61: =Task_1parte_Associazioni!C63 -> csrburante | D61: 3 | E61: =Task_1parte_Associazioni!E63 -> passione | F61: 5 | G61: =Task_1parte_Associazioni!G63 -> vita | H61: 5
A63: =Task_1parte_Associazioni!A65 -> mente | B63: 5 | C63: =Task_1parte_Associazioni!C65 -> cervello | D63: 5 | E63: =Task_1parte_Associazioni!E65 -> emozioni | F63: 5 | G63: =Task_1parte_Associazioni!G65 -> 0 | H63: =Task_1parte_Associazioni!H65 -> 0
A65: =Task_1parte_Associazioni!A67 -> prova | B65: 3 | C65: =Task_1parte_Associazioni!C67 -> esame | D65: 2 | E65: =Task_1parte_Associazioni!E67 -> prestazione | F65: 3 | G65: =Task_1parte_Associazioni!G67 -> 0 | H65: =Task_1parte_Associazioni!H67 -> 0
A67: =Task_1parte_Associazioni!A69 -> test | B67: 3 | C67: =Task_1parte_Associazioni!C69 -> valutazione | D67: 2 | E67: =Task_1parte_Associazioni!E69 -> errore | F67: 1 | G67: =Task_1parte_Associazioni!G69 -> voto | H67: 2
A69: =Task_1parte_Associazioni!A71 -> lavoro | B69: 5 | C69: =Task_1parte_Associazioni!C71 -> fururo | D69: 4 | E69: =Task_1parte_Associazioni!E71 -> paura | F69: 2 | G69: =Task_1parte_Associazioni!G71 -> emozione | H69: 5
A71: =Task_1parte_Associazioni!A73 -> divertimento | B71: 5 | C71: =Task_1parte_Associazioni!C73 -> svago | D71: 5 | E71: =Task_1parte_Associazioni!E73 -> sfogo | F71: 5 | G71: =Task_1parte_Associazioni!G73 -> spensieratezza | H71: 4
A73: =Task_1parte_Associazioni!A75 -> innovazione | B73: 5 | C73: =Task_1parte_Associazioni!C75 -> tecnologia | D73: 5 | E73: =Task_1parte_Associazioni!E75 -> scoperta | F73: 5 | G73: =Task_1parte_Associazioni!G75 -> 0 | H73: =Task_1parte_Associazioni!H75 -> 0
A75: =Task_1parte_Associazioni!A77 -> statistica | B75: 3 | C75: =Task_1parte_Associazioni!C77 -> affascinante | D75: 5 | E75: =Task_1parte_Associazioni!E77 -> grafici | F75: 5 | G75: =Task_1parte_Associazioni!G77 -> numeri | H75: 3
A77: =Task_1parte_Associazioni!A79 -> attaccamento | B77: 2 | C77: =Task_1parte_Associazioni!C79 -> evitante | D77: 3 | E77: =Task_1parte_Associazioni!E79 -> emotivo | F77: 5 | G77: =Task_1parte_Associazioni!G79 -> paura | H77: 2
A79: =Task_1parte_Associazioni!A81 -> cognizione | B79: 3 | C79: =Task_1parte_Associazioni!C81 -> animale | D79: 3 | E79: =Task_1parte_Associazioni!E81 -> cervello | F79: 5 | G79: =Task_1parte_Associazioni!G81 -> comprensione | H79: 5
A81: =Task_1parte_Associazioni!A83 -> equazione | B81: 3 | C81: =Task_1parte_Associazioni!C83 -> numerica | D81: 3 | E81: =Task_1parte_Associazioni!E83 -> algebrica | F81: 3 | G81: =Task_1parte_Associazioni!G83 -> matematica | H81: 3
A83: =Task_1parte_Associazioni!A85 -> psicologia | B83: 5 | C83: =Task_1parte_Associazioni!C85 -> passione | D83: 5 | E83: =Task_1parte_Associazioni!E85 -> scoperta | F83: 5 | G83: =Task_1parte_Associazioni!G85 -> conoscenza | H83: 5
A85: =Task_1parte_Associazioni!A87 -> informatica | B85: 4 | C85: =Task_1parte_Associazioni!C87 -> software | D85: 4 | E85: =Task_1parte_Associazioni!E87 -> programmazione | F85: 3 | G85: =Task_1parte_Associazioni!G87 -> 0 | H85: =Task_1parte_Associazioni!H87 -> 0
A87: =Task_1parte_Associazioni!A89 -> benessere | B87: 5 | C87: =Task_1parte_Associazioni!C89 -> mentale | D87: 5 | E87: =Task_1parte_Associazioni!E89 -> fisico | F87: 3 | G87: =Task_1parte_Associazioni!G89 -> 0 | H87: =Task_1parte_Associazioni!H89 -> 0
A89: =Task_1parte_Associazioni!A91 -> psicopatologia | B89: 2 | C89: =Task_1parte_Associazioni!C91 -> disturbo | D89: 1 | E89: =Task_1parte_Associazioni!E91 -> intervento | F89: 5 | G89: =Task_1parte_Associazioni!G91 -> studio | H89: 4
