Workbook

Sheet Consenso_Informato
A1: CONSENSO INFORMATO alla RICERCA
A3: Progetto: “Using Forma Mentis Networks to Map Students’ Attitudes Toward Data Science”
A5: Nel partecipare alla ricerca, riconosco, comprendo e accetto i seguenti punti:
A7: 1. La ricerca del progetto include la raccolta di dati cognitivi che sono: (i) associazioni libere tra le parole e (ii) punteggi di valenza, entrambi raccolti in modo anonimo;
A8: 2. Partecipo come volontaria/o nella raccolta dei dati, con la possibilità di interrompere l'attività in qualsiasi momento senza penalizzazioni. Comprendo che posso chiedere informazioni e ulteriori spiegazioni in qualsiasi momento durante l'esperimento.
A9: 3. I dati saranno raccolti in forma aggregata, in modo completamente anonimo e utilizzati per scopi di ricerca.
A10: 4. La ricerca viene condotta in conformità con le Indicazioni Etiche e l’approvazione del Comitato Etico dell'Università di Melbourne
B12: DATA | C12: 16.05.2024
B13: FIRMA | C13: X | D13: (INSERIRE UNA X)

Sheet Dati_Demografici
A2: Risponda per cortesia alle seguenti domande. In caso di cella di risposta di colore grigio, la selezioni e poi scelga la risposta per lei adatta dal menù a discesa.
A5: Dati demografici
A7: Età | B7: 19 | C7: Inserire un numero intero (es. 24)
A9: In quale genere si identifica? | B9: Donna
A11: Sesso Biologico | B11: Femminile
A13: Anno di enrollment/inizio studi universitari | B13: 2023 | C13: Inserire solo l'anno (es. 2021)
A15: Ha già conseguito una laurea? | B15: No
A17: Livello di istruzione più alto di almeno uno dei suoi due genitori | B17: Laurea Triennale completata

Sheet Questionari
A4: Come quantificherebbe il suo livello accademico in:
A5: Selezioni la risposta dalla freccetta accanto ciascuna cella di risposta grigia
A7: Materie scientifiche, come chimica, biologia e scienze della vita | B7: 2 - Abilità e competenze limitate
A9: Scienze umanistiche e sociali | B9: 2 - Abilità e competenze limitate
A11: Matematica e fisica | B11: 3 - Abilità e competenze moderate
A13: Coding, programmazione e simulazioni al computer | B13: 1 - Abilità scarse o inesistenti
A18: In questa parte, vedrà una serie di domande rispetto alla sua esperienza con materie STEM (Scienza, Tecnologia, Ingegneria e Matematica).
A19: Selezioni la risposta dalla freccetta accanto ciascuna cella di risposta grigia
A20: Self-regulated learning
A22: Mi assicuro che nessuno mi disturbi quando studio. | B22: 5 - Spesso
A24: Cerco di studiare in un posto tranquillo. | B24: 5 - Spesso
A26: Penso ai tipi di domande che potrebbero esserci in un test/esame. | B26: 4 - Qualche volta
A28: Chiedo al/alla mio/a insegnante di materie STEM gli argomenti che saranno nei prossimi esami. | B28: 4 - Qualche volta
A30: Mi affido ai miei appunti di classe per studiare. | B30: 6 - Molto spesso
A32: Studio molto anche quando ci sono cose più divertenti da fare a casa. | B32: 3 - Raramente
A34: Mi interrogo per vedere quanto sto imparando durante lo studio. | B34: 3 - Raramente
A36: Faccio un programma per aiutarmi a organizzare il mio tempo di studio. | B36: 4 - Qualche volta
A38: Uso raccoglitori o cartelle per organizzare i miei materiali di studio della scienza. | B38: 6 - Molto spesso
A40: Tendo a smarrire gli appunti delle lezioni di scienze. | B40: 2 - Quasi mai
A42: Evito di andare a sessioni extra di aiuto nella classe STEM. | B42: 4 - Qualche volta
A44: Aspetto fino all'ultimo minuto per studiare per i test di scienze. | B44: 4 - Qualche volta
... A76: Finisco tutto il mio studio prima di giocare ai videogiochi o uscire con i miei amici. | B76: 5 - Spesso
A81: Consideri adesso i tuoi corsi STEM... quanto questi elementi riflettono il suo comportamento?
A82: Motivational Learning | E82: questo corso... cioè??
A83: Nb. per "corso", si intende l'intero corso di laurea a cui si è iscritti
A85: Rispetto agli altri studenti del corso, di solito mi aspetto di fare bene. | B85: 4 - Neutrale
A87: Sono certo di poter comprendere le idee insegnate in questo corso. | B87: 5 - Mi riconosco in parte
A89: Mi aspetto di fare molto bene in questo corso. | B89: 5 - Mi riconosco in parte
A91: Rispetto ad altri in questo corso, penso di essere un/a bravo/a studente/essa. | B91: 5 - Mi riconosco in parte
A93: Sono sicuro/a di poter svolgere un ottimo lavoro sui problemi e sui compiti assegnati per questo corso. | B93: 4 - Neutrale
A95: Penso che riceverò un buon voto in questo corso. | B95: 4 - Neutrale
A97: Le mie capacità di studio sono eccellenti rispetto ad altre in questo corso. | B97: 4 - Neutrale
A99: Rispetto ad altri/e studenti/esse di questo corso, penso di sapere molto sull'argomento. | B99: 4 - Neutrale
A101: So che sarò in grado di apprendere il materiale per questo corso. | B101: 5 - Mi riconosco in parte
A103: Preferisco il lavoro di un corso impegnativo per imparare cose nuove. | B103: 2 - Non mi riconosco molto
A105: È importante per me imparare ciò che viene insegnato in questo corso. | B105: 6 - Mi riconosco molto
A107: Mi piace quello che sto imparando in questo corso. | B107: 6 - Mi riconosco molto
... A119: Comprendere l'argomento è importante per me. | B119: 6 - Mi riconosco molto
A124: Consideriamo ora la seguente serie di situazioni. Quanto si sentirebbe ansiosa/o in questi scenari?
A125: Math anxiety UK
...

Sheet Task_1parte_Associazioni
A1: cue word | C1: association_1 | E1: association_2 | G1: association_3
A2: Consideriamo ora questo gioco di associazione:
J3: ESEMPIO DI COMPILAZIONE - ASSOCIAZIONI
A4: Legga la parola in grassetto e scriva negli spazi grigi le prime 3 parole che le vengono in mente dopo averla letta
A5: Per favore, provi a utilizzare una sola parola come associazione
A6: Non ci sono risposte giuste o sbagliate, cerchi solo di farlo il più velocemente possibile.
A7: Se non ha associazioni, lasci gli spazi vuoti.
A8: Pronto/a?
A10: Quali parole le vengono in mente quando legge:
A11: parola_cue | C11: associazione_1 | E11: associazione_2 | G11: associazione_3
A13: terapeuta | C13: terapia | E13: aiuto
A15: innovazione | C15: tecnologia
A17: informatica | C17: computer | E17: programmi
A19: prova | C19: esame
A21: laurea | C21: università | E21: corso
A23: psicologia | C23: università | E23: mente | G23: cervello
A25: creatività | C25: bambini
A27: sviluppo | C27: adolescenza
A29: psicoterapia | C29: cura | E29: terapia
A31: psicopatologia | C31: patologie
A33: lavoro | C33: soldi | E33: colleghi
A35: neuroscienze | C35: cervello | E35: scienza
A37: media | C37: numeri | E37: matematica
A39: equazione | C39: algebra | E39: lineare
A41: personalità | C41: doppia
A43: mente | C43: cervello | E43: psicologia
A45: università | C45: corso | E45: voti | G45: esami
A47: scienziato | C47: scienza | E47: esperimenti
A49: emozione | C49: felicità | E49: amore
A51: test | C51: ammissione | E51: voto
A53: attaccamento
A55: matematica | C55: numeri | E55: calcoli
A57: passione | C57: sport
A59: ansia | C59: esame
A61: scienza | C61: progresso | E61: studio
A63: modello
A65: esame | C65: voti | E65: ansia
A67: insegnante | C67: scuola
A69: valutazione | C69: esito | E69: voto
A71: statistica | C71: matematica | E71: grafici
...

Sheet Task_2parte_Valenza
A2: Consideriamo ora la valenza emotiva ispirata dai concetti. | J2: ESEMPIO DI COMPILAZIONE - VALENZA
A3: Esprima quanto positivamente o negativamente percepisce ogni concetto, isolatamente, in una scala da 1 a 5
A4: dove 1 sta per "Molto negativo", 3 sta per "Neutrale" e 5 sta per "Molto Positivo".
A5: Scriva il numero negli spazi bianchi successivi alla parola/associazione.
A6: Ricordi di valutare i concetti in base alla sua personale percezione.
A7: ATTENZIONE! NON MODIFICHI LE PAROLE "ASSOCIAZIONE" IN QUESTO FOGLIO!
A9: parola_cue | B9: valenza_cue | C9: associazione_1 | D9: valenza_1 | E9: associazione_2 | F9: valenza_2 | G9: associazione_3 | H9: valenza_3
A11: =Task_1parte_Associazioni!A13 -> terapeuta | B11: 2 | C11: =Task_1parte_Associazioni!C13 -> terapia | D11: 2 | E11: =Task_1parte_Associazioni!E13 -> aiuto | F11: 3 | G11: =Task_1parte_Associazioni!G13 -> 0 | H11: =Task_1parte_Associazioni!H13 -> 0
A13: =Task_1parte_Associazioni!A15 -> innovazione | B13: 4 | C13: =Task_1parte_Associazioni!C15 -> tecnologia | D13: 4 | E13: =Task_1parte_Associazioni!E15 -> 0 | F13: =Task_1parte_Associazioni!F15 -> 0 | G13: =Task_1parte_Associazioni!G15 -> 0 | H13: =Task_1parte_Associazioni!H15 -> 0
A15: =Task_1parte_Associazioni!A17 -> informatica | B15: 4 | C15: =Task_1parte_Associazioni!C17 -> computer | D15: 4 | E15: =Task_1parte_Associazioni!E17 -> programmi | F15: 3 | G15: =Task_1parte_Associazioni!G17 -> 0 | H15: =Task_1parte_Associazioni!H17 -> 0
A17: =Task_1parte_Associazioni!A19 -> prova | B17: 3 | C17: =Task_1parte_Associazioni!C19 -> esame | D17: 2 | E17: =Task_1parte_Associazioni!E19 -> 0 | F17: =Task_1parte_Associazioni!F19 -> 0 | G17: =Task_1parte_Associazioni!G19 -> 0 | H17: =Task_1parte_Associazioni!H19 -> 0
A19: =Task_1parte_Associazioni!A21 -> laurea | B19: 4 | C19: =Task_1parte_Associazioni!C21 -> università | D19: 4 | E19: =Task_1parte_Associazioni!E21 -> corso | F19: 4 | G19: =Task_1parte_Associazioni!G21 -> 0 | H19: =Task_1parte_Associazioni!H21 -> 0
A21: =Task_1parte_Associazioni!A23 -> psicologia | B21: 4 | C21: =Task_1parte_Associazioni!C23 -> università | D21: 4 | E21: =Task_1parte_Associazioni!E23 -> mente | F21: 4 | G21: =Task_1parte_Associazioni!G23 -> cervello | H21: 4
A23: =Task_1parte_Associazioni!A25 -> creatività | B23: 5 | C23: =Task_1parte_Associazioni!C25 -> bambini | D23: 5 | E23: =Task_1parte_Associazioni!E25 -> 0 | F23: =Task_1parte_Associazioni!F25 -> 0 | G23: =Task_1parte_Associazioni!G25 -> 0 | H23: =Task_1parte_Associazioni!H25 -> 0
A25: =Task_1parte_Associazioni!A27 -> sviluppo | B25: 4 | C25: =Task_1parte_Associazioni!C27 -> adolescenza | D25: 4 | E25: =Task_1parte_Associazioni!E27 -> 0 | F25: =Task_1parte_Associazioni!F27 -> 0 | G25: =Task_1parte_Associazioni!G27 -> 0 | H25: =Task_1parte_Associazioni!H27 -> 0
A27: =Task_1parte_Associazioni!A29 -> psicoterapia | B27: 2 | C27: =Task_1parte_Associazioni!C29 -> cura | D27: 2 | E27: =Task_1parte_Associazioni!E29 -> terapia | F27: 2 | G27: =Task_1parte_Associazioni!G29 -> 0 | H27: =Task_1parte_Associazioni!H29 -> 0
A29: =Task_1parte_Associazioni!A31 -> psicopatologia | B29: 2 | C29: =Task_1parte_Associazioni!C31 -> patologie | D29: 2 | E29: =Task_1parte_Associazioni!E31 -> 0 | F29: =Task_1parte_Associazioni!F31 -> 0 | G29: =Task_1parte_Associazioni!G31 -> 0 | H29: =Task_1parte_Associazioni!H31 -> 0
A31: =Task_1parte_Associazioni!A33 -> lavoro | B31: 3 | C31: =Task_1parte_Associazioni!C33 -> soldi | D31: 4 | E31: =Task_1parte_Associazioni!E33 -> colleghi | F31: 4 | G31: =Task_1parte_Associazioni!G33 -> 0 | H31: =Task_1parte_Associazioni!H33 -> 0
A33: =Task_1parte_Associazioni!A35 -> neuroscienze | B33: 3 | C33: =Task_1parte_Associazioni!C35 -> cervello | D33: 4 | E33: =Task_1parte_Associazioni!E35 -> scienza | F33: 4 | G33: =Task_1parte_Associazioni!G35 -> 0 | H33: =Task_1parte_Associazioni!H35 -> 0
A35: =Task_1parte_Associazioni!A37 -> media | B35: 3 | C35: =Task_1parte_Associazioni!C37 -> numeri | D35: 3 | E35: =Task_1parte_Associazioni!E37 -> matematica | F35: 3 | G35: =Task_1parte_Associazioni!G37 -> 0 | H35: =Task_1parte_Associazioni!H37 -> 0
A37: =Task_1parte_Associazioni!A39 -> equazione | B37: 3 | C37: =Task_1parte_Associazioni!C39 -> algebra | D37: 3 | E37: =Task_1parte_Associazioni!E39 -> lineare | F37: 3 | G37: =Task_1parte_Associazioni!G39 -> 0 | H37: =Task_1parte_Associazioni!H39 -> 0
A39: =Task_1parte_Associazioni!A41 -> personalità | B39: 4 | C39: =Task_1parte_Associazioni!C41 -> doppia | D39: 3 | E39: =Task_1parte_Associazioni!E41 -> 0 | F39: =Task_1parte_Associazioni!F41 -> 0 | G39: =Task_1parte_Associazioni!G41 -> 0 | H39: =Task_1parte_Associazioni!H41 -> 0
A41: =Task_1parte_Associazioni!A43 -> mente | B41: 4 | C41: =Task_1parte_Associazioni!C43 -> cervello | D41: 4 | E41: =Task_1parte_Associazioni!E43 -> psicologia | F41: 4 | G41: =Task_1parte_Associazioni!G43 -> 0 | H41: =Task_1parte_Associazioni!H43 -> 0
A43: =Task_1parte_Associazioni!A45 -> università | B43: 4 | C43: =Task_1parte_Associazioni!C45 -> corso | D43: 4 | E43: =Task_1parte_Associazioni!E45 -> voti | F43: 3 | G43: =Task_1parte_Associazioni!G45 -> esami | H43: 2
A45: =Task_1parte_Associazioni!A47 -> scienziato | B45: 3 | C45: =Task_1parte_Associazioni!C47 -> scienza | D45: 3 | E45: =Task_1parte_Associazioni!E47 -> esperimenti | F45: 4 | G45: =Task_1parte_Associazioni!G47 -> 0 | H45: =Task_1parte_Associazioni!H47 -> 0
A47: =Task_1parte_Associazioni!A49 -> emozione | B47: 4 | C47: =Task_1parte_Associazioni!C49 -> felicità | D47: 5 | E47: =Task_1parte_Associazioni!E49 -> amore | F47: 5 | G47: =Task_1parte_Associazioni!G49 -> 0 | H47: =Task_1parte_Associazioni!H49 -> 0
A49: =Task_1parte_Associazioni!A51 -> test | B49: 3 | C49: =Task_1parte_Associazioni!C51 -> ammissione | D49: 2 | E49: =Task_1parte_Associazioni!E51 -> voto | F49: 2 | G49: =Task_1parte_Associazioni!G51 -> 0 | H49: =Task_1parte_Associazioni!H51 -> 0
A51: =Task_1parte_Associazioni!A53 -> attaccamento | B51: 3 | C51: =Task_1parte_Associazioni!C53 -> 0 | D51: =Task_1parte_Associazioni!D53 -> 0 | E51: =Task_1parte_Associazioni!E53 -> 0 | F51: =Task_1parte_Associazioni!F53 -> 0 | G51: =Task_1parte_Associazioni!G53 -> 0 | H51: =Task_1parte_Associazioni!H53 -> 0
A53: =Task_1parte_Associazioni!A55 -> matematica | B53: 3 | C53: =Task_1parte_Associazioni!C55 -> numeri | D53: 3 | E53: =Task_1parte_Associazioni!E55 -> calcoli | F53: 3 | G53: =Task_1parte_Associazioni!G55 -> 0 | H53: =Task_1parte_Associazioni!H55 -> 0
A55: =Task_1parte_Associazioni!A57 -> passione | B55: 4 | C55: =Task_1parte_Associazioni!C57 -> sport | D55: 4 | E55: =Task_1parte_Associazioni!E57 -> 0 | F55: =Task_1parte_Associazioni!F57 -> 0 | G55: =Task_1parte_Associazioni!G57 -> 0 | H55: =Task_1parte_Associazioni!H57 -> 0
A57: =Task_1parte_Associazioni!A59 -> ansia | B57: 1 | C57: =Task_1parte_Associazioni!C59 -> esame | D57: 3 | E57: =Task_1parte_Associazioni!E59 -> 0 | F57: =Task_1parte_Associazioni!F59 -> 0 | G57: =Task_1parte_Associazioni!G59 -> 0 | H57: =Task_1parte_Associazioni!H59 -> 0
A59: =Task_1parte_Associazioni!A61 -> scienza | B59: 3 | C59: =Task_1parte_Associazioni!C61 -> progresso | D59: 4 | E59: =Task_1parte_Associazioni!E61 -> studio | F59: 3 | G59: =Task_1parte_Associazioni!G61 -> 0 | H59: =Task_1parte_Associazioni!H61 -> 0
A61: =Task_1parte_Associazioni!A63 -> modello | B61: 3 | C61: =Task_1parte_Associazioni!C63 -> 0 | D61: =Task_1parte_Associazioni!D63 -> 0 | E61: =Task_1parte_Associazioni!E63 -> 0 | F61: =Task_1parte_Associazioni!F63 -> 0 | G61: =Task_1parte_Associazioni!G63 -> 0 | H61: =Task_1parte_Associazioni!H63 -> 0
A63: =Task_1parte_Associazioni!A65 -> esame | B63: 2 | C63: =Task_1parte_Associazioni!C65 -> voti | D63: 2 | E63: =Task_1parte_Associazioni!E65 -> ansia | F63: 1 | G63: =Task_1parte_Associazioni!G65 -> 0 | H63: =Task_1parte_Associazioni!H65 -> 0
A65: =Task_1parte_Associazioni!A67 -> insegnante | B65: 3 | C65: =Task_1parte_Associazioni!C67 -> scuola | D65: 3 | E65: =Task_1parte_Associazioni!E67 -> 0 | F65: =Task_1parte_Associazioni!F67 -> 0 | G65: =Task_1parte_Associazioni!G67 -> 0 | H65: =Task_1parte_Associazioni!H67 -> 0
A67: =Task_1parte_Associazioni!A69 -> valutazione | B67: 2 | C67: =Task_1parte_Associazioni!C69 -> esito | D67: 2 | E67: =Task_1parte_Associazioni!E69 -> voto | F67: 2 | G67: =Task_1parte_Associazioni!G69 -> 0 | H67: =Task_1parte_Associazioni!H69 -> 0
A69: =Task_1parte_Associazioni!A71 -> statistica | B69: 3 | C69: =Task_1parte_Associazioni!C71 -> matematica | D69: 3 | E69: =Task_1parte_Associazioni!E71 -> grafici | F69: 3 | G69: =Task_1parte_Associazioni!G71 -> 0 | H69: =Task_1parte_Associazioni!H71 -> 0
A71: =Task_1parte_Associazioni!A73 -> sfida | B71: 2 | C71: =Task_1parte_Associazioni!C73 -> giochi | D71: 5 | E71: =Task_1parte_Associazioni!E73 -> competizione | F71: 2 | G71: =Task_1parte_Associazioni!G73 -> 0 | H71: =Task_1parte_Associazioni!H73 -> 0
A73: =Task_1parte_Associazioni!A75 -> sapere | B73: 5 | C73: =Task_1parte_Associazioni!C75 -> intelligenza | D73: 5 | E73: =Task_1parte_Associazioni!E75 -> 0 | F73: =Task_1parte_Associazioni!F75 -> 0 | G73: =Task_1parte_Associazioni!G75 -> 0 | H73: =Task_1parte_Associazioni!H75 -> 0
A75: =Task_1parte_Associazioni!A77 -> fisica | B75: 1 | C75: =Task_1parte_Associazioni!C77 -> formule | D75: 3 | E75: =Task_1parte_Associazioni!E77 -> numeri | F75: 3 | G75: =Task_1parte_Associazioni!G77 -> 0 | H75: =Task_1parte_Associazioni!H77 -> 0
...
