Workbook

Sheet Consenso_Informato
A1: CONSENSO INFORMATO alla RICERCA
A3: Progetto: “Using Forma Mentis Networks to Map Students’ Attitudes Toward Data Science”
A5: Nel partecipare alla ricerca, riconosco, comprendo e accetto i seguenti punti:
A7: 1. La ricerca del progetto include la raccolta di dati cognitivi che sono: (i) associazioni libere tra le parole e (ii) punteggi di valenza, entrambi raccolti in modo anonimo;
A8: 2. Partecipo come volontaria/o nella raccolta dei dati, con la possibilità di interrompere l'attività in qualsiasi momento senza penalizzazioni. Comprendo che posso chiedere informazioni e ulteriori spiegazioni in qualsiasi momento durante l'esperimento.
A9: 3. I dati saranno raccolti in forma aggregata, in modo completamente anonimo e utilizzati per scopi di ricerca.
A10: 4. La ricerca viene condotta in conformità con le Indicazioni Etiche e l’approvazione del Comitato Etico dell'Università di Melbourne
B12: DATA | C12: 45397
B13: FIRMA | C13: _____x___ | D13: (INSERIRE UNA X)

Sheet Dati_Demografici
A2: Risponda per cortesia alle seguenti domande. In caso di cella di risposta di colore grigio, la selezioni e poi scelga la risposta per lei adatta dal menù a discesa.
A5: Dati demografici
A7: Età | B7: 21 | C7: Inserire un numero intero (es. 24)
A9: In quale genere si identifica? | B9: Uomo
A11: Sesso Biologico | B11: Maschile
A13: Anno di enrollment/inizio studi universitari | B13: 2021 | C13: Inserire solo l'anno (es. 2021)
A15: Ha già conseguito una laurea? | B15: No
A17: Livello di istruzione più alto di almeno uno dei suoi due genitori | B17: Diploma di scuola superiore secondaria

Sheet Questionari
A4: Come quantificherebbe il suo livello accademico in:
A5: Selezioni la risposta dalla freccetta accanto ciascuna cella di risposta grigia
A7: Materie scientifiche, come chimica, biologia e scienze della vita | B7: 3 - Abilità e competenze moderate
A9: Scienze umanistiche e sociali | B9: 3 - Abilità e competenze moderate
A11: Matematica e fisica | B11: 4 - Abilità e competenze superiori alla media
A13: Coding, programmazione e simulazioni al computer | B13: 4 - Abilità e competenze superiori alla media
A18: In questa parte, vedrà una serie di domande rispetto alla sua esperienza con materie STEM (Scienza, Tecnologia, Ingegneria e Matematica).
A19: Selezioni la risposta dalla freccetta accanto ciascuna cella di risposta grigia
A20: Self-regulated learning
A22: Mi assicuro che nessuno mi disturbi quando studio. | B22: 6 - Molto spesso
A24: Cerco di studiare in un posto tranquillo. | B24: 6 - Molto spesso
A26: Penso ai tipi di domande che potrebbero esserci in un test/esame. | B26: 7 - Sempre
A28: Chiedo al/alla mio/a insegnante di materie STEM gli argomenti che saranno nei prossimi esami. | B28: 4 - Qualche volta
A30: Mi affido ai miei appunti di classe per studiare. | B30: 6 - Molto spesso
A32: Studio molto anche quando ci sono cose più divertenti da fare a casa. | B32: 2 - Quasi mai
A34: Mi interrogo per vedere quanto sto imparando durante lo studio. | B34: 2 - Quasi mai
A36: Faccio un programma per aiutarmi a organizzare il mio tempo di studio. | B36: 2 - Quasi mai
A38: Uso raccoglitori o cartelle per organizzare i miei materiali di studio della scienza. | B38: 4 - Qualche volta
A40: Tendo a smarrire gli appunti delle lezioni di scienze. | B40: 3 - Raramente
A42: Evito di andare a sessioni extra di aiuto nella classe STEM. | B42: 5 - Spesso
A44: Aspetto fino all'ultimo minuto per studiare per i test di scienze. | B44: 5 - Spesso
... A76: Finisco tutto il mio studio prima di giocare ai videogiochi o uscire con i miei amici. | B76: 2 - Quasi mai
A81: Consideri adesso i tuoi corsi STEM... quanto questi elementi riflettono il suo comportamento?
A82: Motivational Learning | E82: questo corso... cioè??
A83: Nb. per "corso", si intende l'intero corso di laurea a cui si è iscritti
A85: Rispetto agli altri studenti del corso, di solito mi aspetto di fare bene. | B85: 2 - Non mi riconosco molto
A87: Sono certo di poter comprendere le idee insegnate in questo corso. | B87: 5 - Mi riconosco in parte
A89: Mi aspetto di fare molto bene in questo corso. | B89: 5 - Mi riconosco in parte
A91: Rispetto ad altri in questo corso, penso di essere un/a bravo/a studente/essa. | B91: 3 - Mi riconosco poco
A93: Sono sicuro/a di poter svolgere un ottimo lavoro sui problemi e sui compiti assegnati per questo corso. | B93: 5 - Mi riconosco in parte
A95: Penso che riceverò un buon voto in questo corso. | B95: 5 - Mi riconosco in parte
A97: Le mie capacità di studio sono eccellenti rispetto ad altre in questo corso. | B97: 3 - Mi riconosco poco
A99: Rispetto ad altri/e studenti/esse di questo corso, penso di sapere molto sull'argomento. | B99: 4 - Neutrale
A101: So che sarò in grado di apprendere il materiale per questo corso. | B101: 6 - Mi riconosco molto
A103: Preferisco il lavoro di un corso impegnativo per imparare cose nuove. | B103: 6 - Mi riconosco molto
A105: È importante per me imparare ciò che viene insegnato in questo corso. | B105: 6 - Mi riconosco molto
A107: Mi piace quello che sto imparando in questo corso. | B107: 6 - Mi riconosco molto
... A119: Comprendere l'argomento è importante per me. | B119: 6 - Mi riconosco molto
A124: Consideriamo ora la seguente serie di situazioni. Quanto si sentirebbe ansiosa/o in questi scenari?
A125: Math anxiety UK
...

Sheet Task_1parte_Associazioni
A1: cue word | C1: association_1 | E1: association_2 | G1: association_3
A2: Consideriamo ora questo gioco di associazione:
J3: ESEMPIO DI COMPILAZIONE - ASSOCIAZIONI
A4: Legga la parola in grassetto e scriva negli spazi grigi le prime 3 parole che le vengono in mente dopo averla letta
A5: Per favore, provi a utilizzare una sola parola come associazione
A6: Non ci sono risposte giuste o sbagliate, cerchi solo di farlo il più velocemente possibile.
A7: Se non ha associazioni, lasci gli spazi vuoti.
A8: Pronto/a?
A10: Quali parole le vengono in mente quando legge:
A11: parola_cue | C11: associazione_1 | E11: associazione_2 | G11: associazione_3
A13: equazione | C13: Matematica | E13: Uguale | G13: Superiori
A15: creatività | C15: Pittore | E15: Colori
A17: ansia | C17: Verifica | E17: Superiori | G17: Peso
A19: psicoterapia | C19: Disciplina | E19: Scienza | G19: Psicologo
A21: scienza | C21: Scienziato | E21: Verde | G21: Materia
A23: passione | C23: Calcio | E23: Sudore | G23: Felicità
A25: sapere | C25: Conoscenza | E25: Cervello | G25: Libri
A27: scienziato | C27: Scienza | E27: Camice | G27: Ricerca
A29: attaccamento | C29: Maglia | E29: Lacrime | G29: Sacrificio
A31: innovazione | C31: Tecnologia | E31: Ai
A33: neuroscienze | C33: Cervello | E33: Studio
A35: media | C35: Social | E35: Matematica | G35: Voti
A37: sviluppo | C37: Tecnologia | E37: Anni | G37: Sacrificio
A39: modello | C39: Studio | E39: Allenato | G39: Ricerca
A41: emozione | C41: Felicita | E41: Tristezza | G41: Rabbia
A43: esame | C43: Ansia | E43: Università | G43: Superiori
A45: terapeuta | C45: Aiuto | E45: Studio | G45: Tristezza
A47: insegnante | C47: Maestra | E47: Elementari | G47: Medie
A49: psicologia | C49: Lettino | E49: Ricordi
A51: psicopatologia | C51: Patologia | E51: Psicologia
A53: informatica | C53: Codice | E53: Computer | G53: Superiori
A55: divertimento | C55: Amici | E55: Bar | G55: Risate
A57: valutazione | C57: Negativa | E57: Voto | G57: Superiori
A59: mente | C59: Cervello | E59: Neuroni
A61: professore | C61: Superiori | E61: Severo | G61: Verifiche
A63: statistica | C63: Probabilità | E63: Esame | G63: Interessante
A65: benessere | C65: Fisico | E65: Mentale | G65: Umano
A67: curiosità | C67: Scoprire | E67: Ricerca | G67: Stimolo
A69: università | C69: Studio | E69: Caffe | G69: Amicizie
A71: matematica | C71: Voti | E71: Superiori | G71: Ansia
...

Sheet Task_2parte_Valenza
A2: Consideriamo ora la valenza emotiva ispirata dai concetti. | J2: ESEMPIO DI COMPILAZIONE - VALENZA
A3: Esprima quanto positivamente o negativamente percepisce ogni concetto, isolatamente, in una scala da 1 a 5
A4: dove 1 sta per "Molto negativo", 3 sta per "Neutrale" e 5 sta per "Molto Positivo".
A5: Scriva il numero negli spazi bianchi successivi alla parola/associazione.
A6: Ricordi di valutare i concetti in base alla sua personale percezione.
A7: ATTENZIONE! NON MODIFICHI LE PAROLE "ASSOCIAZIONE" IN QUESTO FOGLIO!
A9: parola_cue | B9: valenza_cue | C9: associazione_1 | D9: valenza_1 | E9: associazione_2 | F9: valenza_2 | G9: associazione_3 | H9: valenza_3
A11: =Task_1parte_Associazioni!A13 -> equazione | B11: 3 | C11: =Task_1parte_Associazioni!C13 -> Matematica | D11: 1 | E11: =Task_1parte_Associazioni!E13 -> Uguale | F11: 3 | G11: =Task_1parte_Associazioni!G13 -> Superiori | H11: 2
A13: =Task_1parte_Associazioni!A15 -> creatività | B13: 4 | C13: =Task_1parte_Associazioni!C15 -> Pittore | D13: 2 | E13: =Task_1parte_Associazioni!E15 -> Colori | F13: 3 | G13: =Task_1parte_Associazioni!G15 -> 0 | H13: =Task_1parte_Associazioni!H15 -> 0
A15: =Task_1parte_Associazioni!A17 -> ansia | B15: 1 | C15: =Task_1parte_Associazioni!C17 -> Verifica | D15: 1 | E15: =Task_1parte_Associazioni!E17 -> Superiori | F15: 2 | G15: =Task_1parte_Associazioni!G17 -> Peso | H15: 2
A17: =Task_1parte_Associazioni!A19 -> psicoterapia | B17: 3 | C17: =Task_1parte_Associazioni!C19 -> Disciplina | D17: 3 | E17: =Task_1parte_Associazioni!E19 -> Scienza | F17: 4 | G17: =Task_1parte_Associazioni!G19 -> Psicologo | H17: 4
A19: =Task_1parte_Associazioni!A21 -> scienza | B19: 3 | C19: =Task_1parte_Associazioni!C21 -> Scienziato | D19: 3 | E19: =Task_1parte_Associazioni!E21 -> Verde | F19: 3 | G19: =Task_1parte_Associazioni!G21 -> Materia | H19: 3
A21: =Task_1parte_Associazioni!A23 -> passione | B21: 4 | C21: =Task_1parte_Associazioni!C23 -> Calcio | D21: 5 | E21: =Task_1parte_Associazioni!E23 -> Sudore | F21: 4 | G21: =Task_1parte_Associazioni!G23 -> Felicità | H21: 5
A23: =Task_1parte_Associazioni!A25 -> sapere | B23: 3 | C23: =Task_1parte_Associazioni!C25 -> Conoscenza | D23: 3 | E23: =Task_1parte_Associazioni!E25 -> Cervello | F23: 3 | G23: =Task_1parte_Associazioni!G25 -> Libri | H23: 2
A25: =Task_1parte_Associazioni!A27 -> scienziato | B25: 3 | C25: =Task_1parte_Associazioni!C27 -> Scienza | D25: 3 | E25: =Task_1parte_Associazioni!E27 -> Camice | F25: 3 | G25: =Task_1parte_Associazioni!G27 -> Ricerca | H25: 3
A27: =Task_1parte_Associazioni!A29 -> attaccamento | B27: 4 | C27: =Task_1parte_Associazioni!C29 -> Maglia | D27: 5 | E27: =Task_1parte_Associazioni!E29 -> Lacrime | F27: 4 | G27: =Task_1parte_Associazioni!G29 -> Sacrificio | H27: 5
A29: =Task_1parte_Associazioni!A31 -> innovazione | B29: 3 | C29: =Task_1parte_Associazioni!C31 -> Tecnologia | D29: 3 | E29: =Task_1parte_Associazioni!E31 -> Ai | F29: 5 | G29: =Task_1parte_Associazioni!G31 -> 0 | H29: =Task_1parte_Associazioni!H31 -> 0
A31: =Task_1parte_Associazioni!A33 -> neuroscienze | B31: 3 | C31: =Task_1parte_Associazioni!C33 -> Cervello | D31: 3 | E31: =Task_1parte_Associazioni!E33 -> Studio | F31: 2 | G31: =Task_1parte_Associazioni!G33 -> 0 | H31: =Task_1parte_Associazioni!H33 -> 0
A33: =Task_1parte_Associazioni!A35 -> media | B33: 3 | C33: =Task_1parte_Associazioni!C35 -> Social | D33: 4 | E33: =Task_1parte_Associazioni!E35 -> Matematica | F33: 2 | G33: =Task_1parte_Associazioni!G35 -> Voti | H33: 1
A35: =Task_1parte_Associazioni!A37 -> sviluppo | B35: 3 | C35: =Task_1parte_Associazioni!C37 -> Tecnologia | D35: 3 | E35: =Task_1parte_Associazioni!E37 -> Anni | F35: 3 | G35: =Task_1parte_Associazioni!G37 -> Sacrificio | H35: 4
A37: =Task_1parte_Associazioni!A39 -> modello | B37: 3 | C37: =Task_1parte_Associazioni!C39 -> Studio | D37: 2 | E37: =Task_1parte_Associazioni!E39 -> Allenato | F37: 3 | G37: =Task_1parte_Associazioni!G39 -> Ricerca | H37: 3
A39: =Task_1parte_Associazioni!A41 -> emozione | B39: 4 | C39: =Task_1parte_Associazioni!C41 -> Felicita | D39: 5 | E39: =Task_1parte_Associazioni!E41 -> Tristezza | F39: 2 | G39: =Task_1parte_Associazioni!G41 -> Rabbia | H39: 3
A41: =Task_1parte_Associazioni!A43 -> esame | B41: 2 | C41: =Task_1parte_Associazioni!C43 -> Ansia | D41: 3 | E41: =Task_1parte_Associazioni!E43 -> Università | F41: 2 | G41: =Task_1parte_Associazioni!G43 -> Superiori | H41: 1
A43: =Task_1parte_Associazioni!A45 -> terapeuta | B43: 3 | C43: =Task_1parte_Associazioni!C45 -> Aiuto | D43: 3 | E43: =Task_1parte_Associazioni!E45 -> Studio | F43: 3 | G43: =Task_1parte_Associazioni!G45 -> Tristezza | H43: 3
A45: =Task_1parte_Associazioni!A47 -> insegnante | B45: 3 | C45: =Task_1parte_Associazioni!C47 -> Maestra | D45: 4 | E45: =Task_1parte_Associazioni!E47 -> Elementari | F45: 4 | G45: =Task_1parte_Associazioni!G47 -> Medie | H45: 5
A47: =Task_1parte_Associazioni!A49 -> psicologia | B47: 3 | C47: =Task_1parte_Associazioni!C49 -> Lettino | D47: 3 | E47: =Task_1parte_Associazioni!E49 -> Ricordi | F47: 3 | G47: =Task_1parte_Associazioni!G49 -> 0 | H47: =Task_1parte_Associazioni!H49 -> 0
A49: =Task_1parte_Associazioni!A51 -> psicopatologia | B49: 3 | C49: =Task_1parte_Associazioni!C51 -> Patologia | D49: 3 | E49: =Task_1parte_Associazioni!E51 -> Psicologia | F49: 3 | G49: =Task_1parte_Associazioni!G51 -> 0 | H49: =Task_1parte_Associazioni!H51 -> 0
A51: =Task_1parte_Associazioni!A53 -> informatica | B51: 4 | C51: =Task_1parte_Associazioni!C53 -> Codice | D51: 3 | E51: =Task_1parte_Associazioni!E53 -> Computer | F51: 4 | G51: =Task_1parte_Associazioni!G53 -> Superiori | H51: 2
A53: =Task_1parte_Associazioni!A55 -> divertimento | B53: 5 | C53: =Task_1parte_Associazioni!C55 -> Amici | D53: 5 | E53: =Task_1parte_Associazioni!E55 -> Bar | F53: 5 | G53: =Task_1parte_Associazioni!G55 -> Risate | H53: 5
A55: =Task_1parte_Associazioni!A57 -> valutazione | B55: 2 | C55: =Task_1parte_Associazioni!C57 -> Negativa | D55: 1 | E55: =Task_1parte_Associazioni!E57 -> Voto | F55: 1 | G55: =Task_1parte_Associazioni!G57 -> Superiori | H55: 2
A57: =Task_1parte_Associazioni!A59 -> mente | B57: 3 | C57: =Task_1parte_Associazioni!C59 -> Cervello | D57: 3 | E57: =Task_1parte_Associazioni!E59 -> Neuroni | F57: 3 | G57: =Task_1parte_Associazioni!G59 -> 0 | H57: =Task_1parte_Associazioni!H59 -> 0
A59: =Task_1parte_Associazioni!A61 -> professore | B59: 2 | C59: =Task_1parte_Associazioni!C61 -> Superiori | D59: 2 | E59: =Task_1parte_Associazioni!E61 -> Severo | F59: 1 | G59: =Task_1parte_Associazioni!G61 -> Verifiche | H59: 1
A61: =Task_1parte_Associazioni!A63 -> statistica | B61: 2 | C61: =Task_1parte_Associazioni!C63 -> Probabilità | D61: 3 | E61: =Task_1parte_Associazioni!E63 -> Esame | F61: 3 | G61: =Task_1parte_Associazioni!G63 -> Interessante | H61: 2
A63: =Task_1parte_Associazioni!A65 -> benessere | B63: 3 | C63: =Task_1parte_Associazioni!C65 -> Fisico | D63: 3 | E63: =Task_1parte_Associazioni!E65 -> Mentale | F63: 4 | G63: =Task_1parte_Associazioni!G65 -> Umano | H63: 4
A65: =Task_1parte_Associazioni!A67 -> curiosità | B65: 3 | C65: =Task_1parte_Associazioni!C67 -> Scoprire | D65: 4 | E65: =Task_1parte_Associazioni!E67 -> Ricerca | F65: 4 | G65: =Task_1parte_Associazioni!G67 -> Stimolo | H65: 3
A67: =Task_1parte_Associazioni!A69 -> università | B67: 3 | C67: =Task_1parte_Associazioni!C69 -> Studio | D67: 3 | E67: =Task_1parte_Associazioni!E69 -> Caffe | F67: 4 | G67: =Task_1parte_Associazioni!G69 -> Amicizie | H67: 4
A69: =Task_1parte_Associazioni!A71 -> matematica | B69: 2 | C69: =Task_1parte_Associazioni!C71 -> Voti | D69: 2 | E69: =Task_1parte_Associazioni!E71 -> Superiori | F69: 2 | G69: =Task_1parte_Associazioni!G71 -> Ansia | H69: 1
A71: =Task_1parte_Associazioni!A73 -> personalità | B71: 2 | C71: =Task_1parte_Associazioni!C73 -> Positiva | D71: 3 | E71: =Task_1parte_Associazioni!E73 -> Esempio | F71: 3 | G71: =Task_1parte_Associazioni!G73 -> 0 | H71: =Task_1parte_Associazioni!H73 -> 0
A73: =Task_1parte_Associazioni!A75 -> cognizione | B73: 3 | C73: =Task_1parte_Associazioni!C75 -> Causa | D73: 3 | E73: =Task_1parte_Associazioni!E75 -> 0 | F73: =Task_1parte_Associazioni!F75 -> 0 | G73: =Task_1parte_Associazioni!G75 -> 0 | H73: =Task_1parte_Associazioni!H75 -> 0
A75: =Task_1parte_Associazioni!A77 -> sfida | B75: 4 | C75: =Task_1parte_Associazioni!C77 -> Gioco | D75: 4 | E75: =Task_1parte_Associazioni!E77 -> Affrontare | F75: 4 | G75: =Task_1parte_Associazioni!G77 -> Calcio | H75: 5
...
