Workbook

Sheet Info_studio
A1: MATERIALE INFORMATIVO SULLO STUDIO
A3: Scheda informativa dello studio:
A4: "Usare le Forma Mentis Networks per mappare le attitudini nei confronti delle discipline STEM"
A6: Gentile partecipante,
A7: La invitiamo a partecipare al nostro studio che mira ad esplorare l’esperienza da Lei vissuta in quanto
A8: studente o studentessa di discipline STEM.
A10: Scopo dello studio: Lo scopo di questo studio è quello di comprendere le sue esperienze e i suoi processi
A11: cognitivi come studenti e studentesse di discipline STEM.
A13: Sponsorizzazione: Questo studio non è sponsorizzato da enti esterni.
A15: Durata e frequenza: La sua partecipazione comporterà la compilazione di alcuni questionari e l’esecuzione
A16: di tre task. Il tutto non durerà più di 60 minuti.
A18: Descrizione del processo e del compito: Le verrà chiesto di effettuare alcuni compiti, tra cui la
... A44: Assegnista di ricerca dell'Università di Trento

Sheet Consenso_Informato
B1: CONSENSO INFORMATO alla RICERCA
B3: Progetto: “Usare le Forma Mentis Networks per mappare le attitudini nei confronti delle discipline STEM”
A5: Con la presente dichiaro
A6: • di aver letto il foglio informativo sullo studio dal titolo: "Usare le Forma Mentis Networks per mappare le attitudini nei confronti delle discipline STEM";
A7: • che gli obiettivi, i metodi e i rischi dello studio mi sono stati spiegati chiaramente e dettagliatamente dalla dr. Ciringione
A8: • di aver avuto l'opportunità di esprimere le mie considerazioni e chiedere ulteriori chiarimenti, e che ho avuto il tempo di prendere una decisione ponderata e non richiesta;
A9: • di aver compreso che i dati raccolti qui non hanno alcuna rilevanza clinica, ma saranno raccolti ed analizzati puramente a scopo di ricerca;
A10: • di sapere che posso ritirarmi dallo studio in qualsiasi momento senza dover fornire alcuna spiegazione;
A11: • che il mio consenso a partecipare allo studio sopra menzionato è una decisione libera che non è influenzata da promesse di vantaggi finanziari o di altro tipo o da eventuali obblighi verso il ricercatore responsabile dello studio.
A12: Pertanto, sono informato/a sulle attività pianificate e so come posso partecipare allo studio.
A14: Poiché questo è il caso:
A15: x | B15: DO IL MIO CONSENSO A PARTECIPARE ALLO STUDIO
A16: FALSE | B16: RIFIUTO DI DARE IL MIO CONSENSO A PARTECIPARE ALLO STUDIO
C18: DATA
C19: FIRMA | D19: x | E19: (INSERIRE UNA X)

Sheet Dati_Demografici
A2: Risponda per cortesia alle seguenti domande. In caso di cella di risposta di colore grigio, la selezioni e poi scelga la risposta per lei adatta dal menù a discesa.
A5: Dati demografici
A7: Età | B7: 19 | C7: Inserire un numero intero (es. 24)
A9: In quale genere si identifica? | B9: Donna
A11: Sesso Biologico | B11: Femminile
A13: Anno di enrollment/inizio studi universitari | B13: 2023 | C13: Inserire solo l'anno (es. 2021)
A15: Ha già conseguito una laurea? | B15: No
A17: Livello di istruzione più alto di almeno uno dei suoi due genitori | B17: Diploma di scuola superiore secondaria

Sheet Questionari
A4: Come quantificherebbe il suo livello accademico in:
A5: Selezioni la risposta dalla freccetta accanto ciascuna cella di risposta grigia
A7: Materie scientifiche, come chimica, biologia e scienze della vita | B7: 3 - Abilità e competenze moderate
A9: Scienze umanistiche e sociali | B9: 4 - Abilità e competenze superiori alla media
A11: Matematica e fisica | B11: 2 - Abilità e competenze limitate
A13: Coding, programmazione e simulazioni al computer | B13: 1 - Abilità scarse o inesistenti
A18: Descriva in che misura ciascuna di queste affermazioni la descrive
A19: Selezioni la risposta dalla freccetta accanto ciascuna cella di risposta grigia
A20: Self-regulated learning
A22: 1. Preferisco problemi complessi a problemi semplici | B22: 2
A24: 2. Preferisco essere responsabile della gestione di situazioni che richiedono sforzo di pensiero | B24: 3
A26: 3. "Pensare" non è la mia idea di divertimento | B26: 2
A28: 4. Preferirei fare qualcosa che richiede scarsa attività cognitiva piuttosto che qualcosa che sfida la mia capacità di pensiero | B28: 2
A30: 5. Io cerco di anticipare o evitare situazioni in cui probabilmente dovrò pensare a fondo riguardo a qualcosa | B30: 2
A32: 6. Provo soddisfazione nel riflettere molto e a lungo | B32: 2
A34: 7. Io penso solo se sono costretto a farlo | B34: 1 - Non mi descrive per nulla
A36: 8. Preferisco pensare a piccoli progetti quotidiani, piuttosto che a progetti a lungo termine | B36: 2
A38: 9. Preferisco compiti che richiedono piccoli sforzi cognitivi dopo essere stati appresi | B38: 1 - Non mi descrive per nulla
A40: 10. L'idea di contare sul pensiero per trovare la mia strada mi intriga | B40: 2
A42: 11. Mi piace un compito che prevede l'arrivo a nuove soluzioni per risolvere problemi | B42: 3
A44: 12. Imparare nuovi modi di pensare non mi eccita molto | B44: 3
A46: 13. Preferisco riempire la mia vita con puzzles da risolvere | B46: 3
A48: 14. La nozione di pensiero astrattamente mi affascina | B48: 4
A50: 15. Preferirei un compito intellettuale, difficile e importante rispetto ad uno piuttosto importante ma che non richiede pensiero | B50: 3
A52: 16. Provo sollievo piuttosto che soddisfazione dopo aver completato un compito che ha richiesto una gran quantità di sforzo mentale | B52: 2
A54: 17. E' sufficiente per me ottenere un risultato dal lavoro fatto; non mi curo del come o perchè esso funziona | B54: 3
A56: 18. Io normalmente finisco per riflettere riguardo a un tema anche se esso non mi riguarda personalmente | B56: 4
A62: Mi vedo come una persona che ...
A63: Motivational Learning | E63: questo corso... cioè??
A64: Selezioni la risposta dalla freccetta accanto ciascuna cella di risposta grigia
A66: 1) ...è riservata | B66: 1 - Per niente d'accordo
A68: 2) ...generalmente si fida | B68: 3
A70: 3) ...tende a essere pigra | B70: 2
A72: 4) ...è rilassata, sopporta bene lo stress | B72: 5 - Completamente d'accordo
A74: 5) ...ha pochi interessi artistici | B74: 2
A76: 6) ...è spigliata, socievole | B76: 5 - Completamente d'accordo
A78: 7) ...tende a trovare i difetti negli altri | B78: 2
A80: 8) ...è coscienziosa nel lavoro | B80: 3
A82: 9) ...si agita facilmente | B82: 1 - Per niente d'accordo
A84: 10) ...ha una fervida immaginazione | B84: 4
...

Sheet Task_1parte_Associazioni
A1: cue word | C1: association_1 | E1: association_2 | G1: association_3
A2: Consideriamo ora questo gioco di associazione:
J3: ESEMPIO DI COMPILAZIONE - ASSOCIAZIONI
A4: Legga la parola in grassetto e scriva negli spazi grigi le prime 3 parole che le vengono in mente dopo averla letta
A5: Per favore, provi a utilizzare una sola parola come associazione
A6: Non ci sono risposte giuste o sbagliate, cerchi solo di farlo il più velocemente possibile.
A7: Se non ha associazioni, lasci gli spazi vuoti.
A8: Pronto/a?
A10: Quali parole le vengono in mente quando legge:
A11: parola_cue | C11: associazione_1 | E11: associazione_2 | G11: associazione_3
A13: tecnologia | C13: pc | E13: presente | G13: internet
A15: benessere | C15: salute | E15: casa | G15: lavoro
A17: futuro | C17: serenità | E17: amore | G17: viaggi
A19: personalità | C19: conoscenza | E19: introspezione | G19: esperienze
A21: laurea | C21: fatica | E21: studio | G21: sogno
A23: numeri | C23: matematica | E23: conti | G23: insegnamento
A25: frustrazione | C25: tristezza | E25: confusione | G25: emozione
A27: scuola | C27: amicizia | E27: docenti | G27: bambini
A29: statistica | C29: università | E29: economia | G29: calcoli
A31: fisica | C31: incomprensione | E31: natura | G31: lezione
A33: compito | C33: test | E33: scadenza | G33: impegno
... A93: studente | C93: ansia | E93: organizzato | G93: studioso

Sheet Task_2parte_Valenza
A2: Consideriamo ora la valenza emotiva ispirata dai concetti. | J2: ESEMPIO DI COMPILAZIONE - VALENZA
A3: Esprima quanto positivamente o negativamente percepisce ogni concetto, isolatamente, in una scala da 1 a 5
A4: dove 1 sta per "Molto negativo", 3 sta per "Neutrale" e 5 sta per "Molto Positivo".
A5: Scriva il numero negli spazi bianchi successivi alla parola/associazione.
A6: Ricordi di valutare i concetti in base alla sua personale percezione.
A7: ATTENZIONE! NON MODIFICHI LE PAROLE "ASSOCIAZIONE" IN QUESTO FOGLIO!
A9: parola_cue | B9: valenza_cue | C9: associazione_1 | D9: valenza_1 | E9: associazione_2 | F9: valenza_2 | G9: associazione_3 | H9: valenza_3
A11: =Task_1parte_Associazioni!A13 -> tecnologia | B11: 5 | C11: =Task_1parte_Associazioni!C13 -> pc | D11: 4 | E11: =Task_1parte_Associazioni!E13 -> presente | F11: 4 | G11: =Task_1parte_Associazioni!G13 -> internet | H11: 3
A13: =Task_1parte_Associazioni!A15 -> benessere | B13: 5 | C13: =Task_1parte_Associazioni!C15 -> salute | D13: 5 | E13: =Task_1parte_Associazioni!E15 -> casa | F13: 5 | G13: =Task_1parte_Associazioni!G15 -> lavoro | H13: 4
A15: =Task_1parte_Associazioni!A17 -> futuro | B15: 5 | C15: =Task_1parte_Associazioni!C17 -> serenità | D15: 5 | E15: =Task_1parte_Associazioni!E17 -> amore | F15: 5 | G15: =Task_1parte_Associazioni!G17 -> viaggi | H15: 5
A17: =Task_1parte_Associazioni!A19 -> personalità | B17: 5 | C17: =Task_1parte_Associazioni!C19 -> conoscenza | D17: 5 | E17: =Task_1parte_Associazioni!E19 -> introspezione | F17: 5 | G17: =Task_1parte_Associazioni!G19 -> esperienze | H17: 5
A19: =Task_1parte_Associazioni!A21 -> laurea | B19: 4 | C19: =Task_1parte_Associazioni!C21 -> fatica | D19: 3 | E19: =Task_1parte_Associazioni!E21 -> studio | F19: 3 | G19: =Task_1parte_Associazioni!G21 -> sogno | H19: 4
A21: =Task_1parte_Associazioni!A23 -> numeri | B21: 1 | C21: =Task_1parte_Associazioni!C23 -> matematica | D21: 2 | E21: =Task_1parte_Associazioni!E23 -> conti | F21: 2 | G21: =Task_1parte_Associazioni!G23 -> insegnamento | H21: 4
A23: =Task_1parte_Associazioni!A25 -> frustrazione | B23: 3 | C23: =Task_1parte_Associazioni!C25 -> tristezza | D23: 3 | E23: =Task_1parte_Associazioni!E25 -> confusione | F23: 3 | G23: =Task_1parte_Associazioni!G25 -> emozione | H23: 4
A25: =Task_1parte_Associazioni!A27 -> scuola | B25: 4 | C25: =Task_1parte_Associazioni!C27 -> amicizia | D25: 5 | E25: =Task_1parte_Associazioni!E27 -> docenti | F25: 4 | G25: =Task_1parte_Associazioni!G27 -> bambini | H25: 4
A27: =Task_1parte_Associazioni!A29 -> statistica | B27: 1 | C27: =Task_1parte_Associazioni!C29 -> università | D27: 3 | E27: =Task_1parte_Associazioni!E29 -> economia | F27: 2 | G27: =Task_1parte_Associazioni!G29 -> calcoli | H27: 2
A29: =Task_1parte_Associazioni!A31 -> fisica | B29: 1 | C29: =Task_1parte_Associazioni!C31 -> incomprensione | D29: 2 | E29: =Task_1parte_Associazioni!E31 -> natura | F29: 3 | G29: =Task_1parte_Associazioni!G31 -> lezione | H29: 2
A31: =Task_1parte_Associazioni!A33 -> compito | B31: 2 | C31: =Task_1parte_Associazioni!C33 -> test | D31: 2 | E31: =Task_1parte_Associazioni!E33 -> scadenza | F31: 2 | G31: =Task_1parte_Associazioni!G33 -> impegno | H31: 3
A33: =Task_1parte_Associazioni!A35 -> neuroscienze | B33: 4 | C33: =Task_1parte_Associazioni!C35 -> cervello | D33: 5 | E33: =Task_1parte_Associazioni!E35 -> esperimenti | F33: 3 | G33: =Task_1parte_Associazioni!G35 -> ricerca | H33: 2
... A75: =Task_1parte_Associazioni!A77 -> voto | B75: 3 | C75: =Task_1parte_Associazioni!C77 -> scuola | D75: 2 | E75: =Task_1parte_Associazioni!E77 -> ansia | F75: 2 | G75: =Task_1parte_Associazioni!G77 -> risultato | H75: 2
A77: =Task_1parte_Associazioni!A79 -> noia | B77: 2 | C77: =Task_1parte_Associazioni!C79 -> tempo | D77: 3 | E77: =Task_1parte_Associazioni!E79 -> documentari | F77: 3 | G77: =Task_1parte_Associazioni!G79 -> matematica | H77: =Task_1parte_Associazioni!H79 -> 0
A79: =Task_1parte_Associazioni!A81 -> scoperta | B79: 4 | C79: =Task_1parte_Associazioni!C81 -> sicentifica | D79: 3 | E79: =Task_1parte_Associazioni!E81 -> curiosità | F79: 4 | G79: =Task_1parte_Associazioni!G81 -> impegno | H79: 3
A81: =Task_1parte_Associazioni!A83 -> esame | B81: 2 | C81: =Task_1parte_Associazioni!C83 -> preparazione | D81: 3 | E81: =Task_1parte_Associazioni!E83 -> fine | F81: 4 | G81: =Task_1parte_Associazioni!G83 -> studio | H81: 3
A83: =Task_1parte_Associazioni!A85 -> cognizione | B83: 3 | C83: =Task_1parte_Associazioni!C85 -> mente | D83: 4 | E83: =Task_1parte_Associazioni!E85 -> psicologia | F83: 5 | G83: =Task_1parte_Associazioni!G85 -> animali | H83: 3
A85: =Task_1parte_Associazioni!A87 -> lavoro | B85: 3 | C85: =Task_1parte_Associazioni!C87 -> adulti | D85: 2 | E85: =Task_1parte_Associazioni!E87 -> guadagno | F85: 5 | G85: =Task_1parte_Associazioni!G87 -> passione | H85: 5
A87: =Task_1parte_Associazioni!A89 -> grafico | B87: 3 | C87: =Task_1parte_Associazioni!C89 -> statistica | D87: 2 | E87: =Task_1parte_Associazioni!E89 -> osservazione | F87: 2 | G87: =Task_1parte_Associazioni!G89 -> chiarimenti | H87: 3
A89: =Task_1parte_Associazioni!A91 -> esercitazione | B89: 3 | C89: =Task_1parte_Associazioni!C91 -> prepaazione | D89: 2 | E89: =Task_1parte_Associazioni!E91 -> praticità | F89: 2 | G89: =Task_1parte_Associazioni!G91 -> meccanismi | H89: 2
A91: =Task_1parte_Associazioni!A93 -> studente | B91: 4 | C91: =Task_1parte_Associazioni!C93 -> ansia | D91: 2 | E91: =Task_1parte_Associazioni!E93 -> organizzato | F91: 5 | G91: =Task_1parte_Associazioni!G93 -> studioso | H91: 4

Sheet breve_testo
A1: Scriva adesso un breve testo di circa 250 parole relativamente a come si sente quando si trova ad affrontare le discipline STEM.
A2: "Quando affronto le discipline STEM…"
A3: Quando affronto le discipline STEM, nonostante non sia una mia passione o di mio grande interesse, provo a immergermi.
A4: Ho molta difficoltà ad approcciarmi a molte di queste materie però ci provo con impegno e dedizione, costante negli esercizi e chiedendo
A5: qualche aiuto in più nel caso.
A6: Non nego che certe volte mi irrito o mi infastidisco nel non riuscire a svolgere determinati compiti e mi faccio prendere dall'ansia di fallire.
