Workbook

Sheet Info_studio
A1: MATERIALE INFORMATIVO SULLO STUDIO
A3: Scheda informativa dello studio:
A4: "Usare le Forma Mentis Networks per mappare le attitudini nei confronti delle discipline STEM"
A6: Gentile partecipante,
A7: La invitiamo a partecipare al nostro studio che mira ad esplorare l’esperienza da Lei vissuta in quanto
A8: studente o studentessa di discipline STEM.
A10: Scopo dello studio: Lo scopo di questo studio è quello di comprendere le sue esperienze e i suoi processi
A11: cognitivi come studenti e studentesse di discipline STEM.
A13: Sponsorizzazione: Questo studio non è sponsorizzato da enti esterni.
A15: Durata e frequenza: La sua partecipazione comporterà la compilazione di alcuni questionari e l’esecuzione
A16: di tre task. Il tutto non durerà più di 60 minuti.
A18: Descrizione del processo e del compito: Le verrà chiesto di effettuare alcuni compiti, tra cui la
... A44: Assegnista di ricerca dell'Università di Trento

Sheet Consenso_Informato
B1: CONSENSO INFORMATO alla RICERCA
B3: Progetto: “Usare le Forma Mentis Networks per mappare le attitudini nei confronti delle discipline STEM”
A5: Con la presente dichiaro
A6: • di aver letto il foglio informativo sullo studio dal titolo: "Usare le Forma Mentis Networks per mappare le attitudini nei confronti delle discipline STEM";
A7: • che gli obiettivi, i metodi e i rischi dello studio mi sono stati spiegati chiaramente e dettagliatamente dalla dr. Ciringione
A8: • di aver avuto l'opportunità di esprimere le mie considerazioni e chiedere ulteriori chiarimenti, e che ho avuto il tempo di prendere una decisione ponderata e non richiesta;
A9: • di aver compreso che i dati raccolti qui non hanno alcuna rilevanza clinica, ma saranno raccolti ed analizzati puramente a scopo di ricerca;
A10: • di sapere che posso ritirarmi dallo studio in qualsiasi momento senza dover fornire alcuna spiegazione;
A11: • che il mio consenso a partecipare allo studio sopra menzionato è una decisione libera che non è influenzata da promesse di vantaggi finanziari o di altro tipo o da eventuali obblighi verso il ricercatore responsabile dello studio.
A12: Pertanto, sono informato/a sulle attività pianificate e so come posso partecipare allo studio.
A14: Poiché questo è il caso:
A15: x | B15: DO IL MIO CONSENSO A PARTECIPARE ALLO STUDIO
A16: FALSE | B16: RIFIUTO DI DARE IL MIO CONSENSO A PARTECIPARE ALLO STUDIO
C18: DATA | D18: 09.10.2024
C19: FIRMA | D19: x | E19: (INSERIRE UNA X)

Sheet Dati_Demografici
A2: Risponda per cortesia alle seguenti domande. In caso di cella di risposta di colore grigio, la selezioni e poi scelga la risposta per lei adatta dal menù a discesa.
A5: Dati demografici
A7: Età | B7: 20 | C7: Inserire un numero intero (es. 24)
A9: In quale genere si identifica? | B9: Donna
A11: Sesso Biologico | B11: Femminile
A13: Anno di enrollment/inizio studi universitari | B13: 2022/23 | C13: Inserire solo l'anno (es. 2021)
A15: Ha già conseguito una laurea? | B15: No
A17: Livello di istruzione più alto di almeno uno dei suoi due genitori | B17: Diploma di scuola superiore secondaria

Sheet Questionari
A4: Come quantificherebbe il suo livello accademico in:
A5: Selezioni la risposta dalla freccetta accanto ciascuna cella di risposta grigia
A7: Materie scientifiche, come chimica, biologia e scienze della vita | B7: 3 - Abilità e competenze moderate
A9: Scienze umanistiche e sociali | B9: 3 - Abilità e competenze moderate
A11: Matematica e fisica | B11: 3 - Abilità e competenze moderate
A13: Coding, programmazione e simulazioni al computer | B13: 1 - Abilità scarse o inesistenti
A18: Descriva in che misura ciascuna di queste affermazioni la descrive
A19: Selezioni la risposta dalla freccetta accanto ciascuna cella di risposta grigia
A20: Self-regulated learning
A22: 1. Preferisco problemi complessi a problemi semplici | B22: 3
A24: 2. Preferisco essere responsabile della gestione di situazioni che richiedono sforzo di pensiero | B24: 3
A26: 3. "Pensare" non è la mia idea di divertimento | B26: 1 - Non mi descrive per nulla
A28: 4. Preferirei fare qualcosa che richiede scarsa attività cognitiva piuttosto che qualcosa che sfida la mia capacità di pensiero | B28: 3
A30: 5. Io cerco di anticipare o evitare situazioni in cui probabilmente dovrò pensare a fondo riguardo a qualcosa | B30: 2
A32: 6. Provo soddisfazione nel riflettere molto e a lungo | B32: 4
A34: 7. Io penso solo se sono costretto a farlo | B34: 2
A36: 8. Preferisco pensare a piccoli progetti quotidiani, piuttosto che a progetti a lungo termine | B36: 2
A38: 9. Preferisco compiti che richiedono piccoli sforzi cognitivi dopo essere stati appresi | B38: 2
A40: 10. L'idea di contare sul pensiero per trovare la mia strada mi intriga | B40: 4
A42: 11. Mi piace un compito che prevede l'arrivo a nuove soluzioni per risolvere problemi | B42: 3
A44: 12. Imparare nuovi modi di pensare non mi eccita molto | B44: 2
A46: 13. Preferisco riempire la mia vita con puzzles da risolvere | B46: 3
A48: 14. La nozione di pensiero astrattamente mi affascina | B48: 5 - Mi descrive molto bene
A50: 15. Preferirei un compito intellettuale, difficile e importante rispetto ad uno piuttosto importante ma che non richiede pensiero | B50: 3
A52: 16. Provo sollievo piuttosto che soddisfazione dopo aver completato un compito che ha richiesto una gran quantità di sforzo mentale | B52: 2
A54: 17. E' sufficiente per me ottenere un risultato dal lavoro fatto; non mi curo del come o perchè esso funziona | B54: 3
A56: 18. Io normalmente finisco per riflettere riguardo a un tema anche se esso non mi riguarda personalmente | B56: 3
A62: Mi vedo come una persona che ...
A63: Motivational Learning | E63: questo corso... cioè??
A64: Selezioni la risposta dalla freccetta accanto ciascuna cella di risposta grigia
A66: 1) ...è riservata | B66: 3
A68: 2) ...generalmente si fida | B68: 4
A70: 3) ...tende a essere pigra | B70: 2
A72: 4) ...è rilassata, sopporta bene lo stress | B72: 3
A74: 5) ...ha pochi interessi artistici | B74: 4
A76: 6) ...è spigliata, socievole | B76: 4
A78: 7) ...tende a trovare i difetti negli altri | B78: 3
A80: 8) ...è coscienziosa nel lavoro | B80: 4
A82: 9) ...si agita facilmente | B82: 3
A84: 10) ...ha una fervida immaginazione | B84: 4
...

Sheet Task_1parte_Associazioni
A1: cue word | C1: association_1 | E1: association_2 | G1: association_3
A2: Consideriamo ora questo gioco di associazione:
J3: ESEMPIO DI COMPILAZIONE - ASSOCIAZIONI
A4: Legga la parola in grassetto e scriva negli spazi grigi le prime 3 parole che le vengono in mente dopo averla letta
A5: Per favore, provi a utilizzare una sola parola come associazione
A6: Non ci sono risposte giuste o sbagliate, cerchi solo di farlo il più velocemente possibile.
A7: Se non ha associazioni, lasci gli spazi vuoti.
A8: Pronto/a?
A10: Quali parole le vengono in mente quando legge:
A11: parola_cue | C11: associazione_1 | E11: associazione_2 | G11: associazione_3
A13: tecnologia | C13: ansia | E13: difficoltà | G13: schifo
A15: benessere | C15: obbiettivo | E15: serenità | G15: equilibrio
A17: futuro | C17: ansia | E17: confronto | G17: impazienza
A19: personalità | C19: energica | E19: accogliente | G19: diversa
A21: laurea | C21: traguardo | E21: impazienza | G21: ansia
A23: numeri | C23: ansia | E23: curiosità | G23: sfida
A25: frustrazione | C25: vuoto | E25: logorante | G25: esame
A27: scuola | C27: sfida | E27: ansia | G27: impotenza
A29: statistica | C29: interessante | E29: avvicente | G29: sfida
A31: fisica | C31: mnemomnica | E31: noiosa | G31: difficile
A33: compito | C33: sfida | E33: confronto | G33: aiuto
... A83: esame | C83: ansia | E83: sfida | G83: confronto
A85: cognizione
A87: lavoro | C87: monotono | E87: vita | G87: troppo
A89: grafico | C89: ansia | E89: lettura | G89: linee
A91: esercitazione | C91: aiuto | E91: mettersi alla prova | G91: tranquillità
A93: studente | C93: problemi | E93: confronto | G93: ansia

Sheet Task_2parte_Valenza
A2: Consideriamo ora la valenza emotiva ispirata dai concetti. | J2: ESEMPIO DI COMPILAZIONE - VALENZA
A3: Esprima quanto positivamente o negativamente percepisce ogni concetto, isolatamente, in una scala da 1 a 5
A4: dove 1 sta per "Molto negativo", 3 sta per "Neutrale" e 5 sta per "Molto Positivo".
A5: Scriva il numero negli spazi bianchi successivi alla parola/associazione.
A6: Ricordi di valutare i concetti in base alla sua personale percezione.
A7: ATTENZIONE! NON MODIFICHI LE PAROLE "ASSOCIAZIONE" IN QUESTO FOGLIO!
A9: parola_cue | B9: valenza_cue | C9: associazione_1 | D9: valenza_1 | E9: associazione_2 | F9: valenza_2 | G9: associazione_3 | H9: valenza_3
A11: =Task_1parte_Associazioni!A13 -> tecnologia | B11: 2 | C11: =Task_1parte_Associazioni!C13 -> ansia | D11: 2 | E11: =Task_1parte_Associazioni!E13 -> difficoltà | F11: 3 | G11: =Task_1parte_Associazioni!G13 -> schifo | H11: 2
A13: =Task_1parte_Associazioni!A15 -> benessere | B13: 5 | C13: =Task_1parte_Associazioni!C15 -> obbiettivo | D13: 4 | E13: =Task_1parte_Associazioni!E15 -> serenità | F13: 5 | G13: =Task_1parte_Associazioni!G15 -> equilibrio | H13: 5
A15: =Task_1parte_Associazioni!A17 -> futuro | B15: 4 | C15: =Task_1parte_Associazioni!C17 -> ansia | D15: 2 | E15: =Task_1parte_Associazioni!E17 -> confronto | F15: 3 | G15: =Task_1parte_Associazioni!G17 -> impazienza | H15: 3
A17: =Task_1parte_Associazioni!A19 -> personalità | B17: 4 | C17: =Task_1parte_Associazioni!C19 -> energica | D17: 5 | E17: =Task_1parte_Associazioni!E19 -> accogliente | F17: 4 | G17: =Task_1parte_Associazioni!G19 -> diversa | H17: 3
A19: =Task_1parte_Associazioni!A21 -> laurea | B19: 4 | C19: =Task_1parte_Associazioni!C21 -> traguardo | D19: 5 | E19: =Task_1parte_Associazioni!E21 -> impazienza | F19: 3 | G19: =Task_1parte_Associazioni!G21 -> ansia | H19: 2
A21: =Task_1parte_Associazioni!A23 -> numeri | B21: 3 | C21: =Task_1parte_Associazioni!C23 -> ansia | D21: 2 | E21: =Task_1parte_Associazioni!E23 -> curiosità | F21: 5 | G21: =Task_1parte_Associazioni!G23 -> sfida | H21: 4
A23: =Task_1parte_Associazioni!A25 -> frustrazione | B23: 2 | C23: =Task_1parte_Associazioni!C25 -> vuoto | D23: 1 | E23: =Task_1parte_Associazioni!E25 -> logorante | F23: 1 | G23: =Task_1parte_Associazioni!G25 -> esame | H23: 3
A25: =Task_1parte_Associazioni!A27 -> scuola | B25: 4 | C25: =Task_1parte_Associazioni!C27 -> sfida | D25: 4 | E25: =Task_1parte_Associazioni!E27 -> ansia | F25: 2 | G25: =Task_1parte_Associazioni!G27 -> impotenza | H25: 1
A27: =Task_1parte_Associazioni!A29 -> statistica | B27: 3 | C27: =Task_1parte_Associazioni!C29 -> interessante | D27: 5 | E27: =Task_1parte_Associazioni!E29 -> avvicente | F27: 5 | G27: =Task_1parte_Associazioni!G29 -> sfida | H27: 4
A29: =Task_1parte_Associazioni!A31 -> fisica | B29: 2 | C29: =Task_1parte_Associazioni!C31 -> mnemomnica | D29: 2 | E29: =Task_1parte_Associazioni!E31 -> noiosa | F29: 3 | G29: =Task_1parte_Associazioni!G31 -> difficile | H29: 3
A31: =Task_1parte_Associazioni!A33 -> compito | B31: 4 | C31: =Task_1parte_Associazioni!C33 -> sfida | D31: 4 | E31: =Task_1parte_Associazioni!E33 -> confronto | F31: 3 | G31: =Task_1parte_Associazioni!G33 -> aiuto | H31: 4
A33: =Task_1parte_Associazioni!A35 -> neuroscienze | B33: 3 | C33: =Task_1parte_Associazioni!C35 -> curiosità | D33: 4 | E33: =Task_1parte_Associazioni!E35 -> serenità | F33: 5 | G33: =Task_1parte_Associazioni!G35 -> difficile | H33: 3
... A81: =Task_1parte_Associazioni!A83 -> esame | B81: 3 | C81: =Task_1parte_Associazioni!C83 -> ansia | D81: 2 | E81: =Task_1parte_Associazioni!E83 -> sfida | F81: 4 | G81: =Task_1parte_Associazioni!G83 -> confronto | H81: 3
A83: =Task_1parte_Associazioni!A85 -> cognizione | C83: =Task_1parte_Associazioni!C85 -> 0 | D83: =Task_1parte_Associazioni!D85 -> 0 | E83: =Task_1parte_Associazioni!E85 -> 0 | F83: =Task_1parte_Associazioni!F85 -> 0 | G83: =Task_1parte_Associazioni!G85 -> 0
A85: =Task_1parte_Associazioni!A87 -> lavoro | B85: 3 | C85: =Task_1parte_Associazioni!C87 -> monotono | D85: 2 | E85: =Task_1parte_Associazioni!E87 -> vita | F85: 4 | G85: =Task_1parte_Associazioni!G87 -> troppo | H85: 3
A87: =Task_1parte_Associazioni!A89 -> grafico | B87: 2 | C87: =Task_1parte_Associazioni!C89 -> ansia | D87: 2 | E87: =Task_1parte_Associazioni!E89 -> lettura | F87: 4 | G87: =Task_1parte_Associazioni!G89 -> linee | H87: 3
A89: =Task_1parte_Associazioni!A91 -> esercitazione | B89: 5 | C89: =Task_1parte_Associazioni!C91 -> aiuto | D89: 4 | E89: =Task_1parte_Associazioni!E91 -> mettersi alla prova | F89: 5 | G89: =Task_1parte_Associazioni!G91 -> tranquillità | H89: 5
A91: =Task_1parte_Associazioni!A93 -> studente | B91: 4 | C91: =Task_1parte_Associazioni!C93 -> problemi | D91: 3 | E91: =Task_1parte_Associazioni!E93 -> confronto | F91: 3 | G91: =Task_1parte_Associazioni!G93 -> ansia | H91: 2

Sheet breve_testo
A1: Scriva adesso un breve testo di circa 250 parole relativamente a come si sente quando si trova ad affrontare le discipline STEM.
A2: "Quando affronto le discipline STEM…"
A4: Le discipline STEM mi sono sempre piaciute, le ho sempre trovate delle interessanti sfide, ma nel corso dei miei anni scolastici non
A5: sono state affrontate come secondo me sarebbe stato opportuno, ci venivano insegnati dei procedimenti che dovevano essere
A6: imparati e svolti, non bisognava mettersi in gioco, ragionare, ma semplicemente cercare di ricordare, affievolendo l'entusiasmo.
A7: Per la preparazione al Tolc per entrare mi sono trovata di fronte a logica matematica, che per me era nuovo e mi sono sentita avvilita
A8: di non averla studiata prima. All'inizio del primo anno ero molto agitata nei confronti di qualunche materia STEM, ma poi ho visto
A9: come ho affrontato la situazione, come mi prendeva lo studio e quanto mi appasionava cercare di capire. Quindi quest'anno ho
A10: cominciato l'anno molto propositiva, serena, curiosa e sicura delle mie abilità, con l'idea che se mi impegno oltre a raggiugere il mio
A11: obbiettivo, lo farò con il sorriso. Un po' di ansia persiste lo stesso, ma non come l'anno scorso che mi sembrava che mi stesse
A12: prosciugando, è solo una lieve ansia legata al futuro che non so cosa aspettarmi, ma insieme ad entusiasmo di mettermi in gioco
A13: Sono molto fiera di me dei miei cambiamenti, ci metto tutto quello che riesco a fare
