Workbook

Sheet Info_studio
A1: MATERIALE INFORMATIVO SULLO STUDIO
A3: Scheda informativa dello studio:
A4: "Usare le Forma Mentis Networks per mappare le attitudini nei confronti delle discipline STEM"
A6: Gentile partecipante,
A7: La invitiamo a partecipare al nostro studio che mira ad esplorare l’esperienza da Lei vissuta in quanto
A8: studente o studentessa di discipline STEM.
A10: Scopo dello studio: Lo scopo di questo studio è quello di comprendere le sue esperienze e i suoi processi
A11: cognitivi come studenti e studentesse di discipline STEM.
A13: Sponsorizzazione: Questo studio non è sponsorizzato da enti esterni.
A15: Durata e frequenza: La sua partecipazione comporterà la compilazione di alcuni questionari e l’esecuzione
A16: di tre task. Il tutto non durerà più di 60 minuti.
A18: Descrizione del processo e del compito: Le verrà chiesto di effettuare alcuni compiti, tra cui la
... A44: Assegnista di ricerca dell'Università di Trento

Sheet Consenso_Informato
B1: CONSENSO INFORMATO alla RICERCA
B3: Progetto: “Usare le Forma Mentis Networks per mappare le attitudini nei confronti delle discipline STEM”
A5: Con la presente dichiaro
A6: • di aver letto il foglio informativo sullo studio dal titolo: "Usare le Forma Mentis Networks per mappare le attitudini nei confronti delle discipline STEM";
A7: • che gli obiettivi, i metodi e i rischi dello studio mi sono stati spiegati chiaramente e dettagliatamente dalla dr. Ciringione
A8: • di aver avuto l'opportunità di esprimere le mie considerazioni e chiedere ulteriori chiarimenti, e che ho avuto il tempo di prendere una decisione ponderata e non richiesta;
A9: • di aver compreso che i dati raccolti qui non hanno alcuna rilevanza clinica, ma saranno raccolti ed analizzati puramente a scopo di ricerca;
A10: • di sapere che posso ritirarmi dallo studio in qualsiasi momento senza dover fornire alcuna spiegazione;
A11: • che il mio consenso a partecipare allo studio sopra menzionato è una decisione libera che non è influenzata da promesse di vantaggi finanziari o di altro tipo o da eventuali obblighi verso il ricercatore responsabile dello studio.
A12: Pertanto, sono informato/a sulle attività pianificate e so come posso partecipare allo studio.
A14: Poiché questo è il caso:
A15: FALSE | B15: DO IL MIO CONSENSO A PARTECIPARE ALLO STUDIO
A16: FALSE | B16: RIFIUTO DI DARE IL MIO CONSENSO A PARTECIPARE ALLO STUDIO
C18: DATA | D18: ______
C19: FIRMA | D19: ______ | E19: (INSERIRE UNA X)

Sheet Dati_Demografici
A2: Risponda per cortesia alle seguenti domande. In caso di cella di risposta di colore grigio, la selezioni e poi scelga la risposta per lei adatta dal menù a discesa.
A5: Dati demografici
A7: Età | B7: 20 | C7: Inserire un numero intero (es. 24)
A9: In quale genere si identifica? | B9: Uomo
A11: Sesso Biologico | B11: Maschile
A13: Anno di enrollment/inizio studi universitari | B13: 2023 | C13: Inserire solo l'anno (es. 2021)
A15: Ha già conseguito una laurea? | B15: No
A17: Livello di istruzione più alto di almeno uno dei suoi due genitori | B17: Meno di un diploma di scuola superiore

Sheet Questionari
A4: Come quantificherebbe il suo livello accademico in:
A5: Selezioni la risposta dalla freccetta accanto ciascuna cella di risposta grigia
A7: Materie scientifiche, come chimica, biologia e scienze della vita | B7: 4 - Abilità e competenze superiori alla media
A9: Scienze umanistiche e sociali | B9: 4 - Abilità e competenze superiori alla media
A11: Matematica e fisica | B11: 3 - Abilità e competenze moderate
A13: Coding, programmazione e simulazioni al computer | B13: 3 - Abilità e competenze moderate
A18: Descriva in che misura ciascuna di queste affermazioni la descrive
A19: Selezioni la risposta dalla freccetta accanto ciascuna cella di risposta grigia
A20: Self-regulated learning
A22: 1. Preferisco problemi complessi a problemi semplici | B22: 3
A24: 2. Preferisco essere responsabile della gestione di situazioni che richiedono sforzo di pensiero | B24: 5 - Mi descrive molto bene
A26: 3. "Pensare" non è la mia idea di divertimento | B26: 1 - Non mi descrive per nulla
A28: 4. Preferirei fare qualcosa che richiede scarsa attività cognitiva piuttosto che qualcosa che sfida la mia capacità di pensiero | B28: 1 - Non mi descrive per nulla
A30: 5. Io cerco di anticipare o evitare situazioni in cui probabilmente dovrò pensare a fondo riguardo a qualcosa | B30: 1 - Non mi descrive per nulla
A32: 6. Provo soddisfazione nel riflettere molto e a lungo | B32: 5 - Mi descrive molto bene
A34: 7. Io penso solo se sono costretto a farlo | B34: 1 - Non mi descrive per nulla
A36: 8. Preferisco pensare a piccoli progetti quotidiani, piuttosto che a progetti a lungo termine | B36: 3
A38: 9. Preferisco compiti che richiedono piccoli sforzi cognitivi dopo essere stati appresi | B38: 2
A40: 10. L'idea di contare sul pensiero per trovare la mia strada mi intriga | B40: 4
A42: 11. Mi piace un compito che prevede l'arrivo a nuove soluzioni per risolvere problemi | B42: 5 - Mi descrive molto bene
A44: 12. Imparare nuovi modi di pensare non mi eccita molto | B44: 1 - Non mi descrive per nulla
A46: 13. Preferisco riempire la mia vita con puzzles da risolvere | B46: 2
A48: 14. La nozione di pensiero astrattamente mi affascina | B48: 4
A50: 15. Preferirei un compito intellettuale, difficile e importante rispetto ad uno piuttosto importante ma che non richiede pensiero | B50: 5 - Mi descrive molto bene
A52: 16. Provo sollievo piuttosto che soddisfazione dopo aver completato un compito che ha richiesto una gran quantità di sforzo mentale | B52: 5 - Mi descrive molto bene
A54: 17. E' sufficiente per me ottenere un risultato dal lavoro fatto; non mi curo del come o perchè esso funziona | B54: 1 - Non mi descrive per nulla
A56: 18. Io normalmente finisco per riflettere riguardo a un tema anche se esso non mi riguarda personalmente | B56: 4
A62: Mi vedo come una persona che ...
A63: Motivational Learning | E63: questo corso... cioè??
A64: Selezioni la risposta dalla freccetta accanto ciascuna cella di risposta grigia
A66: 1) ...è riservata | B66: 2
A68: 2) ...generalmente si fida | B68: 3
A70: 3) ...tende a essere pigra | B70: 4
A72: 4) ...è rilassata, sopporta bene lo stress | B72: 4
A74: 5) ...ha pochi interessi artistici | B74: 2
A76: 6) ...è spigliata, socievole | B76: 4
A78: 7) ...tende a trovare i difetti negli altri | B78: 2
A80: 8) ...è coscienziosa nel lavoro | B80: 5 - Completamente d'accordo
A82: 9) ...si agita facilmente | B82: 2
A84: 10) ...ha una fervida immaginazione | B84: 5 - Completamente d'accordo
...

Sheet Task_1parte_Associazioni
A1: cue word | C1: association_1 | E1: association_2 | G1: association_3
A2: Consideriamo ora questo gioco di associazione:
J3: ESEMPIO DI COMPILAZIONE - ASSOCIAZIONI
A4: Legga la parola in grassetto e scriva negli spazi grigi le prime 3 parole che le vengono in mente dopo averla letta
A5: Per favore, provi a utilizzare una sola parola come associazione
A6: Non ci sono risposte giuste o sbagliate, cerchi solo di farlo il più velocemente possibile.
A7: Se non ha associazioni, lasci gli spazi vuoti.
A8: Pronto/a?
A10: Quali parole le vengono in mente quando legge:
A11: parola_cue | C11: associazione_1 | E11: associazione_2 | G11: associazione_3
A13: tecnologia | C13: avanzamento | E13: futuro | G13: benessere
A15: benessere | C15: buono | E15: positivo | G15: indicatore
A17: futuro | C17: lavoro | E17: cambiamento | G17: contributo
A19: personalità | C19: quantificabile | E19: costrutto | G19: idea
A21: laurea | C21: traguardo | E21: obbiettivo | G21: sollievo
A23: numeri | C23: utile | E23: strumento
A25: frustrazione | C25: blocco | E25: malattia
A27: scuola | C27: istruzione | E27: futuro | G27: formazione
A29: statistica | C29: utile | E29: strumento | G29: inferenze
A31: fisica | C31: natura | E31: fondamento | G31: scienza
A33: compito | C33: obbligo | E33: lavoro | G33: traguardo
A35: neuroscienze | C35: scienza | E35: ricerca | G35: futuro
A37: insegnante | C37: mentore | E37: futuro
A39: sfida | C39: obbiettivo | E39: traguardo
A41: comportamento | C41: misurabile | E41: modificabile | G41: psicologia
A43: professore | C43: futuro | E43: mentore | G43: cultura
A45: stress | C45: frustrazione | E45: impedimento
A47: creatività | C47: arte | E47: cultura | G47: immaginazione
A49: relazione | C49: lavoro | E49: coppia | G49: sostegno
A51: ansia | C51: blocco
A53: psicologia | C53: comportamento | E53: neuroscienze | G53: cognizione
A55: scienza | C55: futuro | E55: avanzamento | G55: benessere
A57: terapia | C57: strumento | E57: miglioramento | G57: benessere
A59: matematica | C59: strumento
A61: equazione | C61: matematica
A63: modello | C63: costrutto | E63: matematica | G63: galileo
A65: emozione | C65: psicologia | E65: comportamento
A67: università | C67: istruzione | E67: formazione | G67: educazione
A69: mente | C69: psicologia | E69: identità | G69: cognizione
A71: biologia | C71: scienza | E71: natura | G71: organismo
...

Sheet Task_2parte_Valenza
A2: Consideriamo ora la valenza emotiva ispirata dai concetti. | J2: ESEMPIO DI COMPILAZIONE - VALENZA
A3: Esprima quanto positivamente o negativamente percepisce ogni concetto, isolatamente, in una scala da 1 a 5
A4: dove 1 sta per "Molto negativo", 3 sta per "Neutrale" e 5 sta per "Molto Positivo".
A5: Scriva il numero negli spazi bianchi successivi alla parola/associazione.
A6: Ricordi di valutare i concetti in base alla sua personale percezione.
A7: ATTENZIONE! NON MODIFICHI LE PAROLE "ASSOCIAZIONE" IN QUESTO FOGLIO!
A9: parola_cue | B9: valenza_cue | C9: associazione_1 | D9: valenza_1 | E9: associazione_2 | F9: valenza_2 | G9: associazione_3 | H9: valenza_3
A11: =Task_1parte_Associazioni!A13 -> tecnologia | B11: 5 | C11: =Task_1parte_Associazioni!C13 -> avanzamento | D11: 5 | E11: =Task_1parte_Associazioni!E13 -> futuro | F11: 3 | G11: =Task_1parte_Associazioni!G13 -> benessere | H11: 5
A13: =Task_1parte_Associazioni!A15 -> benessere | B13: 5 | C13: =Task_1parte_Associazioni!C15 -> buono | D13: 4 | E13: =Task_1parte_Associazioni!E15 -> positivo | F13: 4 | G13: =Task_1parte_Associazioni!G15 -> indicatore | H13: 3
A15: =Task_1parte_Associazioni!A17 -> futuro | B15: 3 | C15: =Task_1parte_Associazioni!C17 -> lavoro | D15: 2 | E15: =Task_1parte_Associazioni!E17 -> cambiamento | F15: 3 | G15: =Task_1parte_Associazioni!G17 -> contributo | H15: 5
A17: =Task_1parte_Associazioni!A19 -> personalità | B17: 3 | C17: =Task_1parte_Associazioni!C19 -> quantificabile | D17: 3 | E17: =Task_1parte_Associazioni!E19 -> costrutto | F17: 4 | G17: =Task_1parte_Associazioni!G19 -> idea | H17: 5
A19: =Task_1parte_Associazioni!A21 -> laurea | B19: 5 | C19: =Task_1parte_Associazioni!C21 -> traguardo | D19: 5 | E19: =Task_1parte_Associazioni!E21 -> obbiettivo | F19: 5 | G19: =Task_1parte_Associazioni!G21 -> sollievo | H19: 5
A21: =Task_1parte_Associazioni!A23 -> numeri | B21: 3 | C21: =Task_1parte_Associazioni!C23 -> utile | D21: 4 | E21: =Task_1parte_Associazioni!E23 -> strumento | F21: 4 | G21: =Task_1parte_Associazioni!G23 -> 0 | H21: =Task_1parte_Associazioni!H23 -> 0
A23: =Task_1parte_Associazioni!A25 -> frustrazione | B23: 1 | C23: =Task_1parte_Associazioni!C25 -> blocco | D23: 2 | E23: =Task_1parte_Associazioni!E25 -> malattia | F23: 1 | G23: =Task_1parte_Associazioni!G25 -> 0 | H23: =Task_1parte_Associazioni!H25 -> 0
A25: =Task_1parte_Associazioni!A27 -> scuola | B25: 3 | C25: =Task_1parte_Associazioni!C27 -> istruzione | D25: 5 | E25: =Task_1parte_Associazioni!E27 -> futuro | F25: 5 | G25: =Task_1parte_Associazioni!G27 -> formazione | H25: 5
A27: =Task_1parte_Associazioni!A29 -> statistica | B27: 4 | C27: =Task_1parte_Associazioni!C29 -> utile | D27: 4 | E27: =Task_1parte_Associazioni!E29 -> strumento | F27: 4 | G27: =Task_1parte_Associazioni!G29 -> inferenze | H27: 4
A29: =Task_1parte_Associazioni!A31 -> fisica | B29: 4 | C29: =Task_1parte_Associazioni!C31 -> natura | D29: 4 | E29: =Task_1parte_Associazioni!E31 -> fondamento | F29: 3 | G29: =Task_1parte_Associazioni!G31 -> scienza | H29: 4
A31: =Task_1parte_Associazioni!A33 -> compito | B31: 3 | C31: =Task_1parte_Associazioni!C33 -> obbligo | D31: 2 | E31: =Task_1parte_Associazioni!E33 -> lavoro | F31: 3 | G31: =Task_1parte_Associazioni!G33 -> traguardo | H31: 5
A33: =Task_1parte_Associazioni!A35 -> neuroscienze | B33: 5 | C33: =Task_1parte_Associazioni!C35 -> scienza | D33: 5 | E33: =Task_1parte_Associazioni!E35 -> ricerca | F33: 5 | G33: =Task_1parte_Associazioni!G35 -> futuro | H33: 5
A35: =Task_1parte_Associazioni!A37 -> insegnante | B35: 5 | C35: =Task_1parte_Associazioni!C37 -> mentore | D35: 4 | E35: =Task_1parte_Associazioni!E37 -> futuro | F35: 5 | G35: =Task_1parte_Associazioni!G37 -> 0 | H35: =Task_1parte_Associazioni!H37 -> 0
A37: =Task_1parte_Associazioni!A39 -> sfida | B37: 4 | C37: =Task_1parte_Associazioni!C39 -> obbiettivo | D37: 5 | E37: =Task_1parte_Associazioni!E39 -> traguardo | F37: 5 | G37: =Task_1parte_Associazioni!G39 -> 0 | H37: =Task_1parte_Associazioni!H39 -> 0
A39: =Task_1parte_Associazioni!A41 -> comportamento | B39: 5 | C39: =Task_1parte_Associazioni!C41 -> misurabile | D39: 4 | E39: =Task_1parte_Associazioni!E41 -> modificabile | F39: 5 | G39: =Task_1parte_Associazioni!G41 -> psicologia | H39: 5
A41: =Task_1parte_Associazioni!A43 -> professore | B41: 5 | C41: =Task_1parte_Associazioni!C43 -> futuro | D41: 4 | E41: =Task_1parte_Associazioni!E43 -> mentore | F41: 5 | G41: =Task_1parte_Associazioni!G43 -> cultura | H41: 4
A43: =Task_1parte_Associazioni!A45 -> stress | B43: 1 | C43: =Task_1parte_Associazioni!C45 -> frustrazione | D43: 1 | E43: =Task_1parte_Associazioni!E45 -> impedimento | F43: 1 | G43: =Task_1parte_Associazioni!G45 -> 0 | H43: =Task_1parte_Associazioni!H45 -> 0
A45: =Task_1parte_Associazioni!A47 -> creatività | B45: 4 | C45: =Task_1parte_Associazioni!C47 -> arte | D45: 3 | E45: =Task_1parte_Associazioni!E47 -> cultura | F45: 4 | G45: =Task_1parte_Associazioni!G47 -> immaginazione | H45: 5
A47: =Task_1parte_Associazioni!A49 -> relazione | B47: 4 | C47: =Task_1parte_Associazioni!C49 -> lavoro | D47: 4 | E47: =Task_1parte_Associazioni!E49 -> coppia | F47: 4 | G47: =Task_1parte_Associazioni!G49 -> sostegno | H47: 5
A49: =Task_1parte_Associazioni!A51 -> ansia | B49: 3 | C49: =Task_1parte_Associazioni!C51 -> blocco | D49: 1 | E49: =Task_1parte_Associazioni!E51 -> 0 | F49: =Task_1parte_Associazioni!F51 -> 0 | G49: =Task_1parte_Associazioni!G51 -> 0 | H49: =Task_1parte_Associazioni!H51 -> 0
A51: =Task_1parte_Associazioni!A53 -> psicologia | B51: 5 | C51: =Task_1parte_Associazioni!C53 -> comportamento | D51: 5 | E51: =Task_1parte_Associazioni!E53 -> neuroscienze | F51: 5 | G51: =Task_1parte_Associazioni!G53 -> cognizione | H51: 5
A53: =Task_1parte_Associazioni!A55 -> scienza | B53: 5 | C53: =Task_1parte_Associazioni!C55 -> futuro | D53: 5 | E53: =Task_1parte_Associazioni!E55 -> avanzamento | F53: 5 | G53: =Task_1parte_Associazioni!G55 -> benessere | H53: 5
A55: =Task_1parte_Associazioni!A57 -> terapia | B55: 4 | C55: =Task_1parte_Associazioni!C57 -> strumento | D55: 4 | E55: =Task_1parte_Associazioni!E57 -> miglioramento | F55: 4 | G55: =Task_1parte_Associazioni!G57 -> benessere | H55: 5
A57: =Task_1parte_Associazioni!A59 -> matematica | B57: 3 | C57: =Task_1parte_Associazioni!C59 -> strumento | D57: 4 | E57: =Task_1parte_Associazioni!E59 -> 0 | F57: =Task_1parte_Associazioni!F59 -> 0 | G57: =Task_1parte_Associazioni!G59 -> 0 | H57: =Task_1parte_Associazioni!H59 -> 0
A59: =Task_1parte_Associazioni!A61 -> equazione | B59: 3 | C59: =Task_1parte_Associazioni!C61 -> matematica | D59: 3 | E59: =Task_1parte_Associazioni!E61 -> 0 | F59: =Task_1parte_Associazioni!F61 -> 0 | G59: =Task_1parte_Associazioni!G61 -> 0 | H59: =Task_1parte_Associazioni!H61 -> 0
A61: =Task_1parte_Associazioni!A63 -> modello | B61: 4 | C61: =Task_1parte_Associazioni!C63 -> costrutto | D61: 4 | E61: =Task_1parte_Associazioni!E63 -> matematica | F61: 3 | G61: =Task_1parte_Associazioni!G63 -> galileo | H61: 2
A63: =Task_1parte_Associazioni!A65 -> emozione | B63: 4 | C63: =Task_1parte_Associazioni!C65 -> psicologia | D63: 5 | E63: =Task_1parte_Associazioni!E65 -> comportamento | F63: 5 | G63: =Task_1parte_Associazioni!G65 -> 0 | H63: =Task_1parte_Associazioni!H65 -> 0
A65: =Task_1parte_Associazioni!A67 -> università | B65: 5 | C65: =Task_1parte_Associazioni!C67 -> istruzione | D65: 5 | E65: =Task_1parte_Associazioni!E67 -> formazione | F65: 5 | G65: =Task_1parte_Associazioni!G67 -> educazione | H65: 5
A67: =Task_1parte_Associazioni!A69 -> mente | B67: 5 | C67: =Task_1parte_Associazioni!C69 -> psicologia | D67: 5 | E67: =Task_1parte_Associazioni!E69 -> identità | F67: 3 | G67: =Task_1parte_Associazioni!G69 -> cognizione | H67: 5
A69: =Task_1parte_Associazioni!A71 -> biologia | B69: 4 | C69: =Task_1parte_Associazioni!C71 -> scienza | D69: 5 | E69: =Task_1parte_Associazioni!E71 -> natura | F69: 4 | G69: =Task_1parte_Associazioni!G71 -> organismo | H69: 3
A71: =Task_1parte_Associazioni!A73 -> curiosità | B71: 5 | C71: =Task_1parte_Associazioni!C73 -> creatività | D71: 5 | E71: =Task_1parte_Associazioni!E73 -> scoperta | F71: 5 | G71: =Task_1parte_Associazioni!G73 -> innovazione | H71: 5
A73: =Task_1parte_Associazioni!A75 -> conoscenza | B73: 5 | C73: =Task_1parte_Associazioni!C75 -> epistemologia | D73: 2 | E73: =Task_1parte_Associazioni!E75 -> scienza | F73: 5 | G73: =Task_1parte_Associazioni!G75 -> ricerca | H73: 4
A75: =Task_1parte_Associazioni!A77 -> voto | B75: 3 | C75: =Task_1parte_Associazioni!C77 -> misura | D75: 4 | E75: =Task_1parte_Associazioni!E77 -> variabile | F75: 4 | G75: =Task_1parte_Associazioni!G77 -> 0 | H75: 0
...

Sheet breve_testo
A1: Scriva adesso un breve testo di circa 250 parole relativamente a come si sente quando si trova ad affrontare le discipline STEM.
A2: "Quando affronto le discipline STEM…"
A3: Quando affronto le discipline STEM sono sereno e rilassato, non ho alcuna ansia e non associo alcun stato emotivo negativo alle discipline stem, anzi, trovo possano essere utili al progresso e alla innovazione umana.
