Workbook

Sheet Info_studio
A1: MATERIALE INFORMATIVO SULLO STUDIO
A3: Scheda informativa dello studio:
A4: "Usare le Forma Mentis Networks per mappare le attitudini nei confronti delle discipline STEM"
A6: Gentile partecipante,
A7: La invitiamo a partecipare al nostro studio che mira ad esplorare l’esperienza da Lei vissuta in quanto
A8: studente o studentessa di discipline STEM.
A10: Scopo dello studio: Lo scopo di questo studio è quello di comprendere le sue esperienze e i suoi processi
A11: cognitivi come studenti e studentesse di discipline STEM.
A13: Sponsorizzazione: Questo studio non è sponsorizzato da enti esterni.
A15: Durata e frequenza: La sua partecipazione comporterà la compilazione di alcuni questionari e l’esecuzione
A16: di tre task. Il tutto non durerà più di 60 minuti.
A18: Descrizione del processo e del compito: Le verrà chiesto di effettuare alcuni compiti, tra cui la
... A44: Assegnista di ricerca dell'Università di Trento

Sheet Consenso_Informato
B1: CONSENSO INFORMATO alla RICERCA
B3: Progetto: “Usare le Forma Mentis Networks per mappare le attitudini nei confronti delle discipline STEM”
A5: Con la presente dichiaro
A6: • di aver letto il foglio informativo sullo studio dal titolo: "Usare le Forma Mentis Networks per mappare le attitudini nei confronti delle discipline STEM";
A7: • che gli obiettivi, i metodi e i rischi dello studio mi sono stati spiegati chiaramente e dettagliatamente dalla dr. Ciringione
A8: • di aver avuto l'opportunità di esprimere le mie considerazioni e chiedere ulteriori chiarimenti, e che ho avuto il tempo di prendere una decisione ponderata e non richiesta;
A9: • di aver compreso che i dati raccolti qui non hanno alcuna rilevanza clinica, ma saranno raccolti ed analizzati puramente a scopo di ricerca;
A10: • di sapere che posso ritirarmi dallo studio in qualsiasi momento senza dover fornire alcuna spiegazione;
A11: • che il mio consenso a partecipare allo studio sopra menzionato è una decisione libera che non è influenzata da promesse di vantaggi finanziari o di altro tipo o da eventuali obblighi verso il ricercatore responsabile dello studio.
A12: Pertanto, sono informato/a sulle attività pianificate e so come posso partecipare allo studio.
A14: Poiché questo è il caso:
A15: FALSE | B15: DO IL MIO CONSENSO A PARTECIPARE ALLO STUDIO
A16: FALSE | B16: RIFIUTO DI DARE IL MIO CONSENSO A PARTECIPARE ALLO STUDIO
C18: DATA | D18: ______
C19: FIRMA | D19: X | E19: (INSERIRE UNA X)

Sheet Dati_Demografici
A2: Risponda per cortesia alle seguenti domande. In caso di cella di risposta di colore grigio, la selezioni e poi scelga la risposta per lei adatta dal menù a discesa.
A5: Dati demografici
A7: Età | B7: 21 | C7: Inserire un numero intero (es. 24)
A9: In quale genere si identifica? | B9: Donna
A11: Sesso Biologico | B11: Femminile
A13: Anno di enrollment/inizio studi universitari | B13: 2022 | C13: Inserire solo l'anno (es. 2021)
A15: Ha già conseguito una laurea? | B15: No
A17: Livello di istruzione più alto di almeno uno dei suoi due genitori | B17: Diploma di scuola superiore secondaria

Sheet Questionari
A4: Come quantificherebbe il suo livello accademico in:
A5: Selezioni la risposta dalla freccetta accanto ciascuna cella di risposta grigia
A7: Materie scientifiche, come chimica, biologia e scienze della vita | B7: 3 - Abilità e competenze moderate
A9: Scienze umanistiche e sociali | B9: 4 - Abilità e competenze superiori alla media
A11: Matematica e fisica | B11: 2 - Abilità e competenze limitate
A13: Coding, programmazione e simulazioni al computer | B13: 1 - Abilità scarse o inesistenti
A18: Descriva in che misura ciascuna di queste affermazioni la descrive
A19: Selezioni la risposta dalla freccetta accanto ciascuna cella di risposta grigia
A20: Self-regulated learning
A22: 1. Preferisco problemi complessi a problemi semplici | B22: 3
A24: 2. Preferisco essere responsabile della gestione di situazioni che richiedono sforzo di pensiero | B24: 5 - Mi descrive molto bene
A26: 3. "Pensare" non è la mia idea di divertimento | B26: 2
A28: 4. Preferirei fare qualcosa che richiede scarsa attività cognitiva piuttosto che qualcosa che sfida la mia capacità di pensiero | B28: 3
A30: 5. Io cerco di anticipare o evitare situazioni in cui probabilmente dovrò pensare a fondo riguardo a qualcosa | B30: 1 - Non mi descrive per nulla
A32: 6. Provo soddisfazione nel riflettere molto e a lungo | B32: 5 - Mi descrive molto bene
A34: 7. Io penso solo se sono costretto a farlo | B34: 1 - Non mi descrive per nulla
A36: 8. Preferisco pensare a piccoli progetti quotidiani, piuttosto che a progetti a lungo termine | B36: 3
A38: 9. Preferisco compiti che richiedono piccoli sforzi cognitivi dopo essere stati appresi | B38: 2
A40: 10. L'idea di contare sul pensiero per trovare la mia strada mi intriga | B40: 4
A42: 11. Mi piace un compito che prevede l'arrivo a nuove soluzioni per risolvere problemi | B42: 2
A44: 12. Imparare nuovi modi di pensare non mi eccita molto | B44: 4
A46: 13. Preferisco riempire la mia vita con puzzles da risolvere | B46: 1 - Non mi descrive per nulla
A48: 14. La nozione di pensiero astrattamente mi affascina | B48: 5 - Mi descrive molto bene
A50: 15. Preferirei un compito intellettuale, difficile e importante rispetto ad uno piuttosto importante ma che non richiede pensiero | B50: 4
A52: 16. Provo sollievo piuttosto che soddisfazione dopo aver completato un compito che ha richiesto una gran quantità di sforzo mentale | B52: 2
A54: 17. E' sufficiente per me ottenere un risultato dal lavoro fatto; non mi curo del come o perchè esso funziona | B54: 1 - Non mi descrive per nulla
A56: 18. Io normalmente finisco per riflettere riguardo a un tema anche se esso non mi riguarda personalmente | B56: 5 - Mi descrive molto bene
A62: Mi vedo come una persona che ...
A63: Motivational Learning | E63: questo corso... cioè??
A64: Selezioni la risposta dalla freccetta accanto ciascuna cella di risposta grigia
A66: 1) ...è riservata | B66: 5 - Completamente d'accordo
A68: 2) ...generalmente si fida | B68: 5 - Completamente d'accordo
A70: 3) ...tende a essere pigra | B70: 4
A72: 4) ...è rilassata, sopporta bene lo stress | B72: 1 - Per niente d'accordo
A74: 5) ...ha pochi interessi artistici | B74: 4
A76: 6) ...è spigliata, socievole | B76: 1 - Per niente d'accordo
A78: 7) ...tende a trovare i difetti negli altri | B78: 4
A80: 8) ...è coscienziosa nel lavoro | B80: 4
A82: 9) ...si agita facilmente | B82: 4
A84: 10) ...ha una fervida immaginazione | B84: 3
...

Sheet Task_1parte_Associazioni
A1: cue word | C1: association_1 | E1: association_2 | G1: association_3
A2: Consideriamo ora questo gioco di associazione:
J3: ESEMPIO DI COMPILAZIONE - ASSOCIAZIONI
A4: Legga la parola in grassetto e scriva negli spazi grigi le prime 3 parole che le vengono in mente dopo averla letta
A5: Per favore, provi a utilizzare una sola parola come associazione
A6: Non ci sono risposte giuste o sbagliate, cerchi solo di farlo il più velocemente possibile.
A7: Se non ha associazioni, lasci gli spazi vuoti.
A8: Pronto/a?
A10: Quali parole le vengono in mente quando legge:
A11: parola_cue | C11: associazione_1 | E11: associazione_2 | G11: associazione_3
A13: tecnologia | C13: Computer | E13: Scienze | G13: Disegno
A15: benessere | C15: Mente | E15: Corpo | G15: Psicologia
A17: futuro | C17: Paura | E17: Vecchiaia | G17: Lavoro
A19: personalità | C19: Forte | E19: Importante | G19: Persona
A21: laurea | C21: Triennale | E21: Ansia | G21: Vicina
A23: numeri | C23: Primi | E23: Angoscia | G23: Utilità
A25: frustrazione | C25: Curare | E25: Brutta | G25: Pensieri
A27: scuola | C27: Utile | E27: Difficoltà | G27: Insegnamento
A29: statistica | C29: Ansia | E29: Inferiorità | G29: Problema
A31: fisica | C31: Interessante | E31: Quantistica | G31: Velocità
A33: compito | C33: Verifica | E33: Scadenza | G33: Impegno
... A93: studente | C93: Io | E93: Impegno | G93: Futuro

Sheet Task_2parte_Valenza
A2: Consideriamo ora la valenza emotiva ispirata dai concetti. | J2: ESEMPIO DI COMPILAZIONE - VALENZA
A3: Esprima quanto positivamente o negativamente percepisce ogni concetto, isolatamente, in una scala da 1 a 5
A4: dove 1 sta per "Molto negativo", 3 sta per "Neutrale" e 5 sta per "Molto Positivo".
A5: Scriva il numero negli spazi bianchi successivi alla parola/associazione.
A6: Ricordi di valutare i concetti in base alla sua personale percezione.
A7: ATTENZIONE! NON MODIFICHI LE PAROLE "ASSOCIAZIONE" IN QUESTO FOGLIO!
A9: parola_cue | B9: valenza_cue | C9: associazione_1 | D9: valenza_1 | E9: associazione_2 | F9: valenza_2 | G9: associazione_3 | H9: valenza_3
A11: ='Task_1parte_Associazioni'!A13 -> tecnologia | B11: 3 | C11: ='Task_1parte_Associazioni'!C13 -> Computer | D11: 4 | E11: ='Task_1parte_Associazioni'!E13 -> Scienze | F11: 5 | G11: ='Task_1parte_Associazioni'!G13 -> Disegno | H11: 4
A13: ='Task_1parte_Associazioni'!A15 -> benessere | B13: 5 | C13: ='Task_1parte_Associazioni'!C15 -> Mente | D13: 5 | E13: ='Task_1parte_Associazioni'!E15 -> Corpo | F13: 1 | G13: ='Task_1parte_Associazioni'!G15 -> Psicologia | H13: 5
A15: ='Task_1parte_Associazioni'!A17 -> futuro | B15: 4 | C15: ='Task_1parte_Associazioni'!C17 -> Paura | D15: 2 | E15: ='Task_1parte_Associazioni'!E17 -> Vecchiaia | F15: 1 | G15: ='Task_1parte_Associazioni'!G17 -> Lavoro | H15: 2
A17: ='Task_1parte_Associazioni'!A19 -> personalità | B17: 5 | C17: ='Task_1parte_Associazioni'!C19 -> Forte | D17: 3 | E17: ='Task_1parte_Associazioni'!E19 -> Importante | F17: 3 | G17: ='Task_1parte_Associazioni'!G19 -> Persona | H17: 4
A19: ='Task_1parte_Associazioni'!A21 -> laurea | B19: 4 | C19: ='Task_1parte_Associazioni'!C21 -> Triennale | D19: 4 | E19: ='Task_1parte_Associazioni'!E21 -> Ansia | F19: 2 | G19: ='Task_1parte_Associazioni'!G21 -> Vicina | H19: 3
A21: ='Task_1parte_Associazioni'!A23 -> numeri | B21: 2 | C21: ='Task_1parte_Associazioni'!C23 -> Primi | D21: 3 | E21: ='Task_1parte_Associazioni'!E23 -> Angoscia | F21: 1 | G21: ='Task_1parte_Associazioni'!G23 -> Utilità | H21: 3
A23: ='Task_1parte_Associazioni'!A25 -> frustrazione | B23: 1 | C23: ='Task_1parte_Associazioni'!C25 -> Curare | D23: 5 | E23: ='Task_1parte_Associazioni'!E25 -> Brutta | F23: 3 | G23: ='Task_1parte_Associazioni'!G25 -> Pensieri | H23: 4
A25: ='Task_1parte_Associazioni'!A27 -> scuola | B25: 1 | C25: ='Task_1parte_Associazioni'!C27 -> Utile | D25: 3 | E25: ='Task_1parte_Associazioni'!E27 -> Difficoltà | F25: 3 | G25: ='Task_1parte_Associazioni'!G27 -> Insegnamento | H25: 4
A27: ='Task_1parte_Associazioni'!A29 -> statistica | B27: 1 | C27: ='Task_1parte_Associazioni'!C29 -> Ansia | D27: 2 | E27: ='Task_1parte_Associazioni'!E29 -> Inferiorità | F27: 1 | G27: ='Task_1parte_Associazioni'!G29 -> Problema | H27: 2
A29: ='Task_1parte_Associazioni'!A31 -> fisica | B29: 3 | C29: ='Task_1parte_Associazioni'!C31 -> Interessante | D29: 3 | E29: ='Task_1parte_Associazioni'!E31 -> Quantistica | F29: 3 | G29: ='Task_1parte_Associazioni'!G31 -> Velocità | H29: 2
A31: ='Task_1parte_Associazioni'!A33 -> compito | B31: 2 | C31: ='Task_1parte_Associazioni'!C33 -> Verifica | D31: 2 | E31: ='Task_1parte_Associazioni'!E33 -> Scadenza | F31: 1 | G31: ='Task_1parte_Associazioni'!G33 -> Impegno | H31: 5
A33: ='Task_1parte_Associazioni'!A35 -> neuroscienze | B33: 5 | C33: ='Task_1parte_Associazioni'!C35 -> Affascinante | D33: 3 | E33: ='Task_1parte_Associazioni'!E35 -> Cervello | F33: 5 | G33: ='Task_1parte_Associazioni'!G35 -> Fmri | H33: 2
... A91: ='Task_1parte_Associazioni'!A93 -> studente | B91: 4 | C91: ='Task_1parte_Associazioni'!C93 -> Io | D91: 3 | E91: ='Task_1parte_Associazioni'!E93 -> Impegno | F91: 5 | G91: ='Task_1parte_Associazioni'!G93 -> Futuro | H91: 4

Sheet breve_testo
A1: Scriva adesso un breve testo di circa 250 parole relativamente a come si sente quando si trova ad affrontare le discipline STEM.
A2: "Quando affronto le discipline STEM…"
A3: Quando affronto le discipline STEM mi sento incapace, inferiore agli altri, stupida. Sento che mi sarei dovuta impegnare di più in passato, che mi
A4: Mancano le basi e che non sarò mai brava . Sento che non sono portata e che è un problema per il mio futuro. Mi sento molto affascinata da
A5: Questo mondo ma mi ci sento cosi lontana che è difficile non pensare alle cose negative. Mi sento confusa perché non capisco
A6: Se ho sbagliato qualcosa io o se semplicemente si nasce portati per questo tipo di discipline. Ammiro molto chi è bravo nelle discipline STEM,
A7: Per me sono persone molto intelligenti e a volte non mi capacito di come il loro cervello possa comprendere certe cose. Vorrei che venissero
A8: Insegnate con più calma e dedizione cosi che anche le persone più in difficoltà abbiano il tempo di capire almeno un minimo di più. Mi piacerebbe
A9: Molto seguire dei corsi soprattutto in matematica. Gli esami di statistica che ho dovuto frequentare mi hanno abbassato moltissimo la media
A10: Perché non riesco mai a prendere più della sufficienza. Sono molto preoccupata per l’esame di analisi dei dati perché devo laurearmi a luglio.
