Workbook

Sheet Info_studio
A1: MATERIALE INFORMATIVO SULLO STUDIO
A3: Scheda informativa dello studio:
A4: "Usare le Forma Mentis Networks per mappare le attitudini nei confronti delle discipline STEM"
A6: Gentile partecipante,
A7: La invitiamo a partecipare al nostro studio che mira ad esplorare l’esperienza da Lei vissuta in quanto
A8: studente o studentessa di discipline STEM.
A10: Scopo dello studio: Lo scopo di questo studio è quello di comprendere le sue esperienze e i suoi processi
A11: cognitivi come studenti e studentesse di discipline STEM.
A13: Sponsorizzazione: Questo studio non è sponsorizzato da enti esterni.
A15: Durata e frequenza: La sua partecipazione comporterà la compilazione di alcuni questionari e l’esecuzione
A16: di tre task. Il tutto non durerà più di 60 minuti.
A18: Descrizione del processo e del compito: Le verrà chiesto di effettuare alcuni compiti, tra cui la
... A44: Assegnista di ricerca dell'Università di Trento

Sheet Consenso_Informato
B1: CONSENSO INFORMATO alla RICERCA
B3: Progetto: “Usare le Forma Mentis Networks per mappare le attitudini nei confronti delle discipline STEM”
A5: Con la presente dichiaro
A6: • di aver letto il foglio informativo sullo studio dal titolo: "Usare le Forma Mentis Networks per mappare le attitudini nei confronti delle discipline STEM";
A7: • che gli obiettivi, i metodi e i rischi dello studio mi sono stati spiegati chiaramente e dettagliatamente dalla dr. Ciringione
A8: • di aver avuto l'opportunità di esprimere le mie considerazioni e chiedere ulteriori chiarimenti, e che ho avuto il tempo di prendere una decisione ponderata e non richiesta;
A9: • di aver compreso che i dati raccolti qui non hanno alcuna rilevanza clinica, ma saranno raccolti ed analizzati puramente a scopo di ricerca;
A10: • di sapere che posso ritirarmi dallo studio in qualsiasi momento senza dover fornire alcuna spiegazione;
A11: • che il mio consenso a partecipare allo studio sopra menzionato è una decisione libera che non è influenzata da promesse di vantaggi finanziari o di altro tipo o da eventuali obblighi verso il ricercatore responsabile dello studio.
A12: Pertanto, sono informato/a sulle attività pianificate e so come posso partecipare allo studio.
A14: Poiché questo è il caso:
A15: TRUE | B15: DO IL MIO CONSENSO A PARTECIPARE ALLO STUDIO
A16: FALSE | B16: RIFIUTO DI DARE IL MIO CONSENSO A PARTECIPARE ALLO STUDIO
C18: DATA | D18: 8.11.2024
C19: FIRMA | D19: X | E19: (INSERIRE UNA X)

Sheet Dati_Demografici
A2: Risponda per cortesia alle seguenti domande. In caso di cella di risposta di colore grigio, la selezioni e poi scelga la risposta per lei adatta dal menù a discesa.
A5: Dati demografici
A7: Età | B7: 20 | C7: Inserire un numero intero (es. 24)
A9: In quale genere si identifica? | B9: Donna
A11: Sesso Biologico | B11: Femminile
A13: Anno di enrollment/inizio studi universitari | B13: 2022 | C13: Inserire solo l'anno (es. 2021)
A15: Ha già conseguito una laurea? | B15: No
A17: Livello di istruzione più alto di almeno uno dei suoi due genitori | B17: Diploma di scuola superiore secondaria

Sheet Questionari
A4: Come quantificherebbe il suo livello accademico in:
A5: Selezioni la risposta dalla freccetta accanto ciascuna cella di risposta grigia
A7: Materie scientifiche, come chimica, biologia e scienze della vita | B7: 2 - Abilità e competenze limitate
A9: Scienze umanistiche e sociali | B9: 4 - Abilità e competenze superiori alla media
A11: Matematica e fisica | B11: 2 - Abilità e competenze limitate
A13: Coding, programmazione e simulazioni al computer | B13: 1 - Abilità scarse o inesistenti
A18: Descriva in che misura ciascuna di queste affermazioni la descrive
A19: Selezioni la risposta dalla freccetta accanto ciascuna cella di risposta grigia
A20: Self-regulated learning
A22: 1. Preferisco problemi complessi a problemi semplici | B22: 2
A24: 2. Preferisco essere responsabile della gestione di situazioni che richiedono sforzo di pensiero | B24: 4
A26: 3. "Pensare" non è la mia idea di divertimento | B26: 1 - Non mi descrive per nulla
A28: 4. Preferirei fare qualcosa che richiede scarsa attività cognitiva piuttosto che qualcosa che sfida la mia capacità di pensiero | B28: 1 - Non mi descrive per nulla
A30: 5. Io cerco di anticipare o evitare situazioni in cui probabilmente dovrò pensare a fondo riguardo a qualcosa | B30: 1 - Non mi descrive per nulla
A32: 6. Provo soddisfazione nel riflettere molto e a lungo | B32: 3
A34: 7. Io penso solo se sono costretto a farlo | B34: 1 - Non mi descrive per nulla
A36: 8. Preferisco pensare a piccoli progetti quotidiani, piuttosto che a progetti a lungo termine | B36: 2
A38: 9. Preferisco compiti che richiedono piccoli sforzi cognitivi dopo essere stati appresi | B38: 2
A40: 10. L'idea di contare sul pensiero per trovare la mia strada mi intriga | B40: 4
A42: 11. Mi piace un compito che prevede l'arrivo a nuove soluzioni per risolvere problemi | B42: 3
A44: 12. Imparare nuovi modi di pensare non mi eccita molto | B44: 3
A46: 13. Preferisco riempire la mia vita con puzzles da risolvere | B46: 1 - Non mi descrive per nulla
A48: 14. La nozione di pensiero astrattamente mi affascina | B48: 4
A50: 15. Preferirei un compito intellettuale, difficile e importante rispetto ad uno piuttosto importante ma che non richiede pensiero | B50: 5 - Mi descrive molto bene
A52: 16. Provo sollievo piuttosto che soddisfazione dopo aver completato un compito che ha richiesto una gran quantità di sforzo mentale | B52: 3
A54: 17. E' sufficiente per me ottenere un risultato dal lavoro fatto; non mi curo del come o perchè esso funziona | B54: 2
A56: 18. Io normalmente finisco per riflettere riguardo a un tema anche se esso non mi riguarda personalmente | B56: 4
A62: Mi vedo come una persona che ...
A63: Motivational Learning | E63: questo corso... cioè??
A64: Selezioni la risposta dalla freccetta accanto ciascuna cella di risposta grigia
A66: 1) ...è riservata | B66: 1 - Per niente d'accordo
A68: 2) ...generalmente si fida | B68: 3
A70: 3) ...tende a essere pigra | B70: 1 - Per niente d'accordo
A72: 4) ...è rilassata, sopporta bene lo stress | B72: 3
A74: 5) ...ha pochi interessi artistici | B74: 1 - Per niente d'accordo
A76: 6) ...è spigliata, socievole | B76: 4
A78: 7) ...tende a trovare i difetti negli altri | B78: 3
A80: 8) ...è coscienziosa nel lavoro | B80: 4
A82: 9) ...si agita facilmente | B82: 3
A84: 10) ...ha una fervida immaginazione | B84: 3
...

Sheet Task_1parte_Associazioni
A1: cue word | C1: association_1 | E1: association_2 | G1: association_3
A2: Consideriamo ora questo gioco di associazione:
J3: ESEMPIO DI COMPILAZIONE - ASSOCIAZIONI
A4: Legga la parola in grassetto e scriva negli spazi grigi le prime 3 parole che le vengono in mente dopo averla letta
A5: Per favore, provi a utilizzare una sola parola come associazione
A6: Non ci sono risposte giuste o sbagliate, cerchi solo di farlo il più velocemente possibile.
A7: Se non ha associazioni, lasci gli spazi vuoti.
A8: Pronto/a?
A10: Quali parole le vengono in mente quando legge:
A11: parola_cue | C11: associazione_1 | E11: associazione_2 | G11: associazione_3
A13: tecnologia | C13: computer | E13: telefono | G13: internet
A15: benessere | C15: feclitià | E15: leggerezza | G15: serenità
A17: futuro | C17: paure | E17: dubbi | G17: apsettative
A19: personalità | C19: estroversione | E19: esperienza | G19: costruzione
A21: laurea | C21: timore | E21: orgoglio | G21: percorso
A23: numeri | C23: quantità | E23: soldi | G23: anni
A25: frustrazione | C25: studio | E25: insoddisfazione | G25: impegno
A27: scuola | C27: compagni | E27: impegno | G27: studio
A29: statistica | C29: numeri | E29: formule | G29: probabilità
A31: fisica | C31: leggi | E31: universo | G31: difficoltà
A33: compito | C33: prova | E33: sfida | G33: obbligo
... A93: studente | C93: stress | E93: aspettative | G93: motivazione

Sheet Task_2parte_Valenza
A2: Consideriamo ora la valenza emotiva ispirata dai concetti. | J2: ESEMPIO DI COMPILAZIONE - VALENZA
A3: Esprima quanto positivamente o negativamente percepisce ogni concetto, isolatamente, in una scala da 1 a 5
A4: dove 1 sta per "Molto negativo", 3 sta per "Neutrale" e 5 sta per "Molto Positivo".
A5: Scriva il numero negli spazi bianchi successivi alla parola/associazione.
A6: Ricordi di valutare i concetti in base alla sua personale percezione.
A7: ATTENZIONE! NON MODIFICHI LE PAROLE "ASSOCIAZIONE" IN QUESTO FOGLIO!
A9: parola_cue | B9: valenza_cue | C9: associazione_1 | D9: valenza_1 | E9: associazione_2 | F9: valenza_2 | G9: associazione_3 | H9: valenza_3
A11: =Task_1parte_Associazioni!A13 -> tecnologia | B11: 3 | C11: =Task_1parte_Associazioni!C13 -> computer | D11: 2 | E11: =Task_1parte_Associazioni!E13 -> telefono | F11: 2 | G11: =Task_1parte_Associazioni!G13 -> internet | H11: 2
A13: =Task_1parte_Associazioni!A15 -> benessere | B13: 5 | C13: =Task_1parte_Associazioni!C15 -> feclitià | D13: 5 | E13: =Task_1parte_Associazioni!E15 -> leggerezza | F13: 5 | G13: =Task_1parte_Associazioni!G15 -> serenità | H13: 5
A15: =Task_1parte_Associazioni!A17 -> futuro | B15: 4 | C15: =Task_1parte_Associazioni!C17 -> paure | D15: 2 | E15: =Task_1parte_Associazioni!E17 -> dubbi | F15: 2 | G15: =Task_1parte_Associazioni!G17 -> apsettative | H15: 3
A17: =Task_1parte_Associazioni!A19 -> personalità | B17: 4 | C17: =Task_1parte_Associazioni!C19 -> estroversione | D17: 4 | E17: =Task_1parte_Associazioni!E19 -> esperienza | F17: 4 | G17: =Task_1parte_Associazioni!G19 -> costruzione | H17: 4
A19: =Task_1parte_Associazioni!A21 -> laurea | B19: 4 | C19: =Task_1parte_Associazioni!C21 -> timore | D19: 2 | E19: =Task_1parte_Associazioni!E21 -> orgoglio | F19: 4 | G19: =Task_1parte_Associazioni!G21 -> percorso | H19: 3
A21: =Task_1parte_Associazioni!A23 -> numeri | B21: 3 | C21: =Task_1parte_Associazioni!C23 -> quantità | D21: 3 | E21: =Task_1parte_Associazioni!E23 -> soldi | F21: 2 | G21: =Task_1parte_Associazioni!G23 -> anni | H21: 4
A23: =Task_1parte_Associazioni!A25 -> frustrazione | B23: 1 | C23: =Task_1parte_Associazioni!C25 -> studio | D23: 4 | E23: =Task_1parte_Associazioni!E25 -> insoddisfazione | F23: 1 | G23: =Task_1parte_Associazioni!G25 -> impegno | H23: 4
A25: =Task_1parte_Associazioni!A27 -> scuola | B25: 3 | C25: =Task_1parte_Associazioni!C27 -> compagni | D25: 4 | E25: =Task_1parte_Associazioni!E27 -> impegno | F25: 3 | G25: =Task_1parte_Associazioni!G27 -> studio | H25: 3
A27: =Task_1parte_Associazioni!A29 -> statistica | B27: 2 | C27: =Task_1parte_Associazioni!C29 -> numeri | D27: 2 | E27: =Task_1parte_Associazioni!E29 -> formule | F27: 2 | G27: =Task_1parte_Associazioni!G29 -> probabilità | H27: 3
A29: =Task_1parte_Associazioni!A31 -> fisica | B29: 2 | C29: =Task_1parte_Associazioni!C31 -> leggi | D29: 3 | E29: =Task_1parte_Associazioni!E31 -> universo | F29: 3 | G29: =Task_1parte_Associazioni!G31 -> difficoltà | H29: 3
A31: =Task_1parte_Associazioni!A33 -> compito | B31: 3 | C31: =Task_1parte_Associazioni!C33 -> prova | D31: 3 | E31: =Task_1parte_Associazioni!E33 -> sfida | F31: 4 | G31: =Task_1parte_Associazioni!G33 -> obbligo | H31: 1
A33: =Task_1parte_Associazioni!A35 -> neuroscienze | B33: 2 | C33: =Task_1parte_Associazioni!#REF! -> #REF! | D33: 1 | E33: =Task_1parte_Associazioni!E35 -> razionalità | F33: 3 | G33: =Task_1parte_Associazioni!G35 -> machine | H33: 3
A35: =Task_1parte_Associazioni!A37 -> insegnante | B35: 4 | C35: =Task_1parte_Associazioni!C37 -> rapporto | D35: 4 | E35: =Task_1parte_Associazioni!E37 -> fiduica | F35: 5 | G35: =Task_1parte_Associazioni!G37 -> rispetto | H35: 5
A37: =Task_1parte_Associazioni!A39 -> sfida | B37: 4 | C37: =Task_1parte_Associazioni!C39 -> studio | D37: 4 | E37: =Task_1parte_Associazioni!E39 -> esame | F37: 3 | G37: =Task_1parte_Associazioni!G39 -> difficoltà | H37: 2
A39: =Task_1parte_Associazioni!A41 -> comportamento | B39: 4 | C39: =Task_1parte_Associazioni!C41 -> positività | D39: 4 | E39: =Task_1parte_Associazioni!E41 -> rispetto | F39: 5 | G39: =Task_1parte_Associazioni!G41 -> controllo | H39: 4
A41: =Task_1parte_Associazioni!A43 -> professore | B41: 4 | C41: =Task_1parte_Associazioni!C43 -> rispetto | D41: 4 | E41: =Task_1parte_Associazioni!E43 -> conoscenza | F41: 4 | G41: =Task_1parte_Associazioni!G43 -> riigidità | H41: 2
A43: =Task_1parte_Associazioni!A45 -> stress | B43: 2 | C43: =Task_1parte_Associazioni!C45 -> studio | D43: 3 | E43: =Task_1parte_Associazioni!E45 -> relazioni | F43: 4 | G43: =Task_1parte_Associazioni!G45 -> futuro | H43: 4
A45: =Task_1parte_Associazioni!A47 -> creatività | B45: 4 | C45: =Task_1parte_Associazioni!C47 -> danza | D45: 4 | E45: =Task_1parte_Associazioni!E47 -> scrivere | F45: 4 | G45: =Task_1parte_Associazioni!G47 -> vestiti | H45: 4
A47: =Task_1parte_Associazioni!A49 -> relazione | B47: 4 | C47: =Task_1parte_Associazioni!C49 -> affetto | D47: 5 | E47: =Task_1parte_Associazioni!E49 -> sicurezza | F47: 5 | G47: =Task_1parte_Associazioni!G49 -> serenità | H47: 5
A49: =Task_1parte_Associazioni!A51 -> ansia | B49: 2 | C49: =Task_1parte_Associazioni!C51 -> necessasità | D49: 3 | E49: =Task_1parte_Associazioni!E51 -> nausea | F49: 1 | G49: =Task_1parte_Associazioni!G51 -> timore | H49: 1
A51: =Task_1parte_Associazioni!A53 -> psicologia | B51: 4 | C51: =Task_1parte_Associazioni!C53 -> profondità | D51: 4 | E51: =Task_1parte_Associazioni!E53 -> incoscio | F51: 4 | G51: persone | H51: 4
A53: =Task_1parte_Associazioni!A55 -> scienza | B53: 3 | C53: =Task_1parte_Associazioni!C55 -> razionalità | D53: 3 | E53: =Task_1parte_Associazioni!E55 -> rigidità | F53: 2 | G53: =Task_1parte_Associazioni!G55 -> mondo | H53: 3
A55: =Task_1parte_Associazioni!A57 -> terapia | B55: 4 | C55: =Task_1parte_Associazioni!C57 -> dialogo | D55: 4 | E55: =Task_1parte_Associazioni!E57 -> rapporto | F55: 4 | G55: =Task_1parte_Associazioni!G57 -> fiducia | H55: 5
A57: =Task_1parte_Associazioni!A59 -> matematica | B57: 2 | C57: =Task_1parte_Associazioni!C59 -> numeri | D57: 2 | E57: =Task_1parte_Associazioni!E59 -> memoria | F57: 4 | G57: =Task_1parte_Associazioni!G59 -> genetica | H57: 4
A59: =Task_1parte_Associazioni!A61 -> equazione | B59: 2 | C59: =Task_1parte_Associazioni!C61 -> numeri | D59: 2 | E59: =Task_1parte_Associazioni!E61 -> esercizio | F59: 2 | G59: =Task_1parte_Associazioni!G61 -> noia | H59: 2
A61: =Task_1parte_Associazioni!A63 -> modello | B61: 3 | C61: =Task_1parte_Associazioni!C63 -> mente | D61: 4 | E61: =Task_1parte_Associazioni!E63 -> memoria | F61: 4 | G61: =Task_1parte_Associazioni!G63 -> persona | H61: 4
A63: =Task_1parte_Associazioni!A65 -> emozione | B63: 5 | C63: =Task_1parte_Associazioni!C65 -> intensa | D63: 4 | E63: =Task_1parte_Associazioni!E65 -> unica | F63: 4 | G63: =Task_1parte_Associazioni!G65 -> soggettiva | H63: 4
A65: =Task_1parte_Associazioni!A67 -> università | B65: 4 | C65: =Task_1parte_Associazioni!C67 -> futuro | D65: 4 | E65: =Task_1parte_Associazioni!E67 -> angoscia | F65: 2 | G65: =Task_1parte_Associazioni!G67 -> aspettative | H65: 2
A67: =Task_1parte_Associazioni!A69 -> mente | B67: 4 | C67: =Task_1parte_Associazioni!C69 -> profondità | D67: 4 | E67: =Task_1parte_Associazioni!E69 -> intelligenza | F67: 4 | G67: =Task_1parte_Associazioni!G69 -> salute | H67: 5
A69: =Task_1parte_Associazioni!A71 -> biologia | B69: 4 | C69: =Task_1parte_Associazioni!C71 -> vita | D69: 4 | E69: =Task_1parte_Associazioni!E71 -> apparati | F69: 3 | G69: =Task_1parte_Associazioni!G71 -> salute | H69: 4
A71: =Task_1parte_Associazioni!A73 -> curiosità | B71: 4 | C71: =Task_1parte_Associazioni!C73 -> interesse | D71: 4 | E71: =Task_1parte_Associazioni!E73 -> conoscenza | F71: 4 | G71: =Task_1parte_Associazioni!G73 -> vita | H71: 4
A73: =Task_1parte_Associazioni!A75 -> conoscenza | B73: 4 | C73: =Task_1parte_Associazioni!C75 -> futuro | D73: 4 | E73: =Task_1parte_Associazioni!E75 -> personalità | F73: 4 | G73: =Task_1parte_Associazioni!G75 -> lavoro | H73: 3
A75: =Task_1parte_Associazioni!A77 -> voto | B75: 3 | C75: =Task_1parte_Associazioni!C77 -> definizione | D75: 2 | E75: =Task_1parte_Associazioni!E77 -> emozione | F75: 4 | G75: =Task_1parte_Associazioni!G77 -> paura | H75: 2
...

Sheet breve_testo
A1: Scriva adesso un breve testo di circa 250 parole relativamente a come si sente quando si trova ad affrontare le discipline STEM.
A2: "Quando affronto le discipline STEM…"
A3: Quando affornto le disicpline STEM sento sempre di non essere mai abbastanza preprata, è come se vi fosse sempre un qualcosa che mi impedisce
A4: di avere quellòa sicurezza necessaria per affrontarle, mi sottovaluto e mi sento spesso stupida e poco intelligente. Questo mio modo di sentirmi
A5: non è dobuto al fatto che richiedano come discpline una mole di pensiero e ragionaento eccessiva rispetto alle altre, ma poprio per la difficoltà, per la
A6: quantità di numeri e di formule, ma soprattutto per il tempo che impiego per sentirmi a mio agio nel fare gli esercizi.
A7: Si tartat di discpline che se una volta capite e comprese le regole da appliccare risultano divertenti e soddifsfacienti, ma non riuscire a comprendere
A8: un problema, rednersi conto di non sapere da dove partire crea una frustrazione inspiegabile che scoreggia qualsiasi spinta positiva a voler far bene.
A9: Quando affronto queste discipline mi sento come se geneticamnte non fossi portata per i numeri, per i calcoli, per gli algoritmi, si tratta di discpline che
A10: più che spingermi a pensare ad un certo punto mi spingono a memorizzare una serie di algortimi da appliccare per riuscire a svincolarmi dalla
A11: frustrazione di non essere capace e all'altezza.
